package com.jtrent238.luckyblock.structures;

import com.jtrent238.luckyblock.BlockLoader;
import com.jtrent238.luckyblock.util.LuckyColorPicker;
import net.minecraft.block.Block;
import net.minecraft.entity.player.EntityPlayer;
import net.minecraft.world.World;

import java.util.Random;

public class LuckyCube_10x10_Structure {

    public static void placeStructure(World world, EntityPlayer player) {

        int x = (int) player.posX - 6;
        int y = (int) player.posY - 1;
        int z = (int) player.posZ - 5;

        world.setBlock(x + 0, y + 0, z + 0, new LuckyColorPicker().pickColor(), 0, 3);
        world.setBlock(x + 1, y + 0, z + 0, new LuckyColorPicker().pickColor(), 0, 3);
        world.setBlock(x + 2, y + 0, z + 0, new LuckyColorPicker().pickColor(), 0, 3);
        world.setBlock(x + 3, y + 0, z + 0, new LuckyColorPicker().pickColor(), 0, 3);
        world.setBlock(x + 4, y + 0, z + 0, new LuckyColorPicker().pickColor(), 0, 3);
        world.setBlock(x + 5, y + 0, z + 0, new LuckyColorPicker().pickColor(), 0, 3);
        world.setBlock(x + 6, y + 0, z + 0, new LuckyColorPicker().pickColor(), 0, 3);
        world.setBlock(x + 7, y + 0, z + 0, new LuckyColorPicker().pickColor(), 0, 3);
        world.setBlock(x + 8, y + 0, z + 0, new LuckyColorPicker().pickColor(), 0, 3);
        world.setBlock(x + 9, y + 0, z + 0, new LuckyColorPicker().pickColor(), 0, 3);
        world.setBlock(x + 0, y + 0, z + 1, new LuckyColorPicker().pickColor(), 0, 3);
        world.setBlock(x + 1, y + 0, z + 1, new LuckyColorPicker().pickColor(), 0, 3);
        world.setBlock(x + 2, y + 0, z + 1, new LuckyColorPicker().pickColor(), 0, 3);
        world.setBlock(x + 3, y + 0, z + 1, new LuckyColorPicker().pickColor(), 0, 3);
        world.setBlock(x + 4, y + 0, z + 1, new LuckyColorPicker().pickColor(), 0, 3);
        world.setBlock(x + 5, y + 0, z + 1, new LuckyColorPicker().pickColor(), 0, 3);
        world.setBlock(x + 6, y + 0, z + 1, new LuckyColorPicker().pickColor(), 0, 3);
        world.setBlock(x + 7, y + 0, z + 1, new LuckyColorPicker().pickColor(), 0, 3);
        world.setBlock(x + 8, y + 0, z + 1, new LuckyColorPicker().pickColor(), 0, 3);
        world.setBlock(x + 9, y + 0, z + 1, new LuckyColorPicker().pickColor(), 0, 3);
        world.setBlock(x + 0, y + 0, z + 2, new LuckyColorPicker().pickColor(), 0, 3);
        world.setBlock(x + 1, y + 0, z + 2, new LuckyColorPicker().pickColor(), 0, 3);
        world.setBlock(x + 2, y + 0, z + 2, new LuckyColorPicker().pickColor(), 0, 3);
        world.setBlock(x + 3, y + 0, z + 2, new LuckyColorPicker().pickColor(), 0, 3);
        world.setBlock(x + 4, y + 0, z + 2, new LuckyColorPicker().pickColor(), 0, 3);
        world.setBlock(x + 5, y + 0, z + 2, new LuckyColorPicker().pickColor(), 0, 3);
        world.setBlock(x + 6, y + 0, z + 2, new LuckyColorPicker().pickColor(), 0, 3);
        world.setBlock(x + 7, y + 0, z + 2, new LuckyColorPicker().pickColor(), 0, 3);
        world.setBlock(x + 8, y + 0, z + 2, new LuckyColorPicker().pickColor(), 0, 3);
        world.setBlock(x + 9, y + 0, z + 2, new LuckyColorPicker().pickColor(), 0, 3);
        world.setBlock(x + 0, y + 0, z + 3, new LuckyColorPicker().pickColor(), 0, 3);
        world.setBlock(x + 1, y + 0, z + 3, new LuckyColorPicker().pickColor(), 0, 3);
        world.setBlock(x + 2, y + 0, z + 3, new LuckyColorPicker().pickColor(), 0, 3);
        world.setBlock(x + 3, y + 0, z + 3, new LuckyColorPicker().pickColor(), 0, 3);
        world.setBlock(x + 4, y + 0, z + 3, new LuckyColorPicker().pickColor(), 0, 3);
        world.setBlock(x + 5, y + 0, z + 3, new LuckyColorPicker().pickColor(), 0, 3);
        world.setBlock(x + 6, y + 0, z + 3, new LuckyColorPicker().pickColor(), 0, 3);
        world.setBlock(x + 7, y + 0, z + 3, new LuckyColorPicker().pickColor(), 0, 3);
        world.setBlock(x + 8, y + 0, z + 3, new LuckyColorPicker().pickColor(), 0, 3);
        world.setBlock(x + 9, y + 0, z + 3, new LuckyColorPicker().pickColor(), 0, 3);
        world.setBlock(x + 0, y + 0, z + 4, new LuckyColorPicker().pickColor(), 0, 3);
        world.setBlock(x + 1, y + 0, z + 4, new LuckyColorPicker().pickColor(), 0, 3);
        world.setBlock(x + 2, y + 0, z + 4, new LuckyColorPicker().pickColor(), 0, 3);
        world.setBlock(x + 3, y + 0, z + 4, new LuckyColorPicker().pickColor(), 0, 3);
        world.setBlock(x + 4, y + 0, z + 4, new LuckyColorPicker().pickColor(), 0, 3);
        world.setBlock(x + 5, y + 0, z + 4, new LuckyColorPicker().pickColor(), 0, 3);
        world.setBlock(x + 6, y + 0, z + 4, new LuckyColorPicker().pickColor(), 0, 3);
        world.setBlock(x + 7, y + 0, z + 4, new LuckyColorPicker().pickColor(), 0, 3);
        world.setBlock(x + 8, y + 0, z + 4, new LuckyColorPicker().pickColor(), 0, 3);
        world.setBlock(x + 9, y + 0, z + 4, new LuckyColorPicker().pickColor(), 0, 3);
        world.setBlock(x + 0, y + 0, z + 5, new LuckyColorPicker().pickColor(), 0, 3);
        world.setBlock(x + 1, y + 0, z + 5, new LuckyColorPicker().pickColor(), 0, 3);
        world.setBlock(x + 2, y + 0, z + 5, new LuckyColorPicker().pickColor(), 0, 3);
        world.setBlock(x + 3, y + 0, z + 5, new LuckyColorPicker().pickColor(), 0, 3);
        world.setBlock(x + 4, y + 0, z + 5, new LuckyColorPicker().pickColor(), 0, 3);
        world.setBlock(x + 5, y + 0, z + 5, new LuckyColorPicker().pickColor(), 0, 3);
        world.setBlock(x + 6, y + 0, z + 5, new LuckyColorPicker().pickColor(), 0, 3);
        world.setBlock(x + 7, y + 0, z + 5, new LuckyColorPicker().pickColor(), 0, 3);
        world.setBlock(x + 8, y + 0, z + 5, new LuckyColorPicker().pickColor(), 0, 3);
        world.setBlock(x + 9, y + 0, z + 5, new LuckyColorPicker().pickColor(), 0, 3);
        world.setBlock(x + 0, y + 0, z + 6, new LuckyColorPicker().pickColor(), 0, 3);
        world.setBlock(x + 1, y + 0, z + 6, new LuckyColorPicker().pickColor(), 0, 3);
        world.setBlock(x + 2, y + 0, z + 6, new LuckyColorPicker().pickColor(), 0, 3);
        world.setBlock(x + 3, y + 0, z + 6, new LuckyColorPicker().pickColor(), 0, 3);
        world.setBlock(x + 4, y + 0, z + 6, new LuckyColorPicker().pickColor(), 0, 3);
        world.setBlock(x + 5, y + 0, z + 6, new LuckyColorPicker().pickColor(), 0, 3);
        world.setBlock(x + 6, y + 0, z + 6, new LuckyColorPicker().pickColor(), 0, 3);
        world.setBlock(x + 7, y + 0, z + 6, new LuckyColorPicker().pickColor(), 0, 3);
        world.setBlock(x + 8, y + 0, z + 6, new LuckyColorPicker().pickColor(), 0, 3);
        world.setBlock(x + 9, y + 0, z + 6, new LuckyColorPicker().pickColor(), 0, 3);
        world.setBlock(x + 0, y + 0, z + 7, new LuckyColorPicker().pickColor(), 0, 3);
        world.setBlock(x + 1, y + 0, z + 7, new LuckyColorPicker().pickColor(), 0, 3);
        world.setBlock(x + 2, y + 0, z + 7, new LuckyColorPicker().pickColor(), 0, 3);
        world.setBlock(x + 3, y + 0, z + 7, new LuckyColorPicker().pickColor(), 0, 3);
        world.setBlock(x + 4, y + 0, z + 7, new LuckyColorPicker().pickColor(), 0, 3);
        world.setBlock(x + 5, y + 0, z + 7, new LuckyColorPicker().pickColor(), 0, 3);
        world.setBlock(x + 6, y + 0, z + 7, new LuckyColorPicker().pickColor(), 0, 3);
        world.setBlock(x + 7, y + 0, z + 7, new LuckyColorPicker().pickColor(), 0, 3);
        world.setBlock(x + 8, y + 0, z + 7, new LuckyColorPicker().pickColor(), 0, 3);
        world.setBlock(x + 9, y + 0, z + 7, new LuckyColorPicker().pickColor(), 0, 3);
        world.setBlock(x + 0, y + 0, z + 8, new LuckyColorPicker().pickColor(), 0, 3);
        world.setBlock(x + 1, y + 0, z + 8, new LuckyColorPicker().pickColor(), 0, 3);
        world.setBlock(x + 2, y + 0, z + 8, new LuckyColorPicker().pickColor(), 0, 3);
        world.setBlock(x + 3, y + 0, z + 8, new LuckyColorPicker().pickColor(), 0, 3);
        world.setBlock(x + 4, y + 0, z + 8, new LuckyColorPicker().pickColor(), 0, 3);
        world.setBlock(x + 5, y + 0, z + 8, new LuckyColorPicker().pickColor(), 0, 3);
        world.setBlock(x + 6, y + 0, z + 8, new LuckyColorPicker().pickColor(), 0, 3);
        world.setBlock(x + 7, y + 0, z + 8, new LuckyColorPicker().pickColor(), 0, 3);
        world.setBlock(x + 8, y + 0, z + 8, new LuckyColorPicker().pickColor(), 0, 3);
        world.setBlock(x + 9, y + 0, z + 8, new LuckyColorPicker().pickColor(), 0, 3);
        world.setBlock(x + 0, y + 0, z + 9, new LuckyColorPicker().pickColor(), 0, 3);
        world.setBlock(x + 1, y + 0, z + 9, new LuckyColorPicker().pickColor(), 0, 3);
        world.setBlock(x + 2, y + 0, z + 9, new LuckyColorPicker().pickColor(), 0, 3);
        world.setBlock(x + 3, y + 0, z + 9, new LuckyColorPicker().pickColor(), 0, 3);
        world.setBlock(x + 4, y + 0, z + 9, new LuckyColorPicker().pickColor(), 0, 3);
        world.setBlock(x + 5, y + 0, z + 9, new LuckyColorPicker().pickColor(), 0, 3);
        world.setBlock(x + 6, y + 0, z + 9, new LuckyColorPicker().pickColor(), 0, 3);
        world.setBlock(x + 7, y + 0, z + 9, new LuckyColorPicker().pickColor(), 0, 3);
        world.setBlock(x + 8, y + 0, z + 9, new LuckyColorPicker().pickColor(), 0, 3);
        world.setBlock(x + 9, y + 0, z + 9, new LuckyColorPicker().pickColor(), 0, 3);
        world.setBlock(x + 0, y + 1, z + 0, new LuckyColorPicker().pickColor(), 0, 3);
        world.setBlock(x + 1, y + 1, z + 0, new LuckyColorPicker().pickColor(), 0, 3);
        world.setBlock(x + 2, y + 1, z + 0, new LuckyColorPicker().pickColor(), 0, 3);
        world.setBlock(x + 3, y + 1, z + 0, new LuckyColorPicker().pickColor(), 0, 3);
        world.setBlock(x + 4, y + 1, z + 0, new LuckyColorPicker().pickColor(), 0, 3);
        world.setBlock(x + 5, y + 1, z + 0, new LuckyColorPicker().pickColor(), 0, 3);
        world.setBlock(x + 6, y + 1, z + 0, new LuckyColorPicker().pickColor(), 0, 3);
        world.setBlock(x + 7, y + 1, z + 0, new LuckyColorPicker().pickColor(), 0, 3);
        world.setBlock(x + 8, y + 1, z + 0, new LuckyColorPicker().pickColor(), 0, 3);
        world.setBlock(x + 9, y + 1, z + 0, new LuckyColorPicker().pickColor(), 0, 3);
        world.setBlock(x + 0, y + 1, z + 1, new LuckyColorPicker().pickColor(), 0, 3);
        world.setBlock(x + 1, y + 1, z + 1, new LuckyColorPicker().pickColor(), 0, 3);
        world.setBlock(x + 2, y + 1, z + 1, new LuckyColorPicker().pickColor(), 0, 3);
        world.setBlock(x + 3, y + 1, z + 1, new LuckyColorPicker().pickColor(), 0, 3);
        world.setBlock(x + 4, y + 1, z + 1, new LuckyColorPicker().pickColor(), 0, 3);
        world.setBlock(x + 5, y + 1, z + 1, new LuckyColorPicker().pickColor(), 0, 3);
        world.setBlock(x + 6, y + 1, z + 1, new LuckyColorPicker().pickColor(), 0, 3);
        world.setBlock(x + 7, y + 1, z + 1, new LuckyColorPicker().pickColor(), 0, 3);
        world.setBlock(x + 8, y + 1, z + 1, new LuckyColorPicker().pickColor(), 0, 3);
        world.setBlock(x + 9, y + 1, z + 1, new LuckyColorPicker().pickColor(), 0, 3);
        world.setBlock(x + 0, y + 1, z + 2, new LuckyColorPicker().pickColor(), 0, 3);
        world.setBlock(x + 1, y + 1, z + 2, new LuckyColorPicker().pickColor(), 0, 3);
        world.setBlock(x + 2, y + 1, z + 2, new LuckyColorPicker().pickColor(), 0, 3);
        world.setBlock(x + 3, y + 1, z + 2, new LuckyColorPicker().pickColor(), 0, 3);
        world.setBlock(x + 4, y + 1, z + 2, new LuckyColorPicker().pickColor(), 0, 3);
        world.setBlock(x + 5, y + 1, z + 2, new LuckyColorPicker().pickColor(), 0, 3);
        world.setBlock(x + 6, y + 1, z + 2, new LuckyColorPicker().pickColor(), 0, 3);
        world.setBlock(x + 7, y + 1, z + 2, new LuckyColorPicker().pickColor(), 0, 3);
        world.setBlock(x + 8, y + 1, z + 2, new LuckyColorPicker().pickColor(), 0, 3);
        world.setBlock(x + 9, y + 1, z + 2, new LuckyColorPicker().pickColor(), 0, 3);
        world.setBlock(x + 0, y + 1, z + 3, new LuckyColorPicker().pickColor(), 0, 3);
        world.setBlock(x + 1, y + 1, z + 3, new LuckyColorPicker().pickColor(), 0, 3);
        world.setBlock(x + 2, y + 1, z + 3, new LuckyColorPicker().pickColor(), 0, 3);
        world.setBlock(x + 3, y + 1, z + 3, new LuckyColorPicker().pickColor(), 0, 3);
        world.setBlock(x + 4, y + 1, z + 3, new LuckyColorPicker().pickColor(), 0, 3);
        world.setBlock(x + 5, y + 1, z + 3, new LuckyColorPicker().pickColor(), 0, 3);
        world.setBlock(x + 6, y + 1, z + 3, new LuckyColorPicker().pickColor(), 0, 3);
        world.setBlock(x + 7, y + 1, z + 3, new LuckyColorPicker().pickColor(), 0, 3);
        world.setBlock(x + 8, y + 1, z + 3, new LuckyColorPicker().pickColor(), 0, 3);
        world.setBlock(x + 9, y + 1, z + 3, new LuckyColorPicker().pickColor(), 0, 3);
        world.setBlock(x + 0, y + 1, z + 4, new LuckyColorPicker().pickColor(), 0, 3);
        world.setBlock(x + 1, y + 1, z + 4, new LuckyColorPicker().pickColor(), 0, 3);
        world.setBlock(x + 2, y + 1, z + 4, new LuckyColorPicker().pickColor(), 0, 3);
        world.setBlock(x + 3, y + 1, z + 4, new LuckyColorPicker().pickColor(), 0, 3);
        world.setBlock(x + 4, y + 1, z + 4, new LuckyColorPicker().pickColor(), 0, 3);
        world.setBlock(x + 5, y + 1, z + 4, new LuckyColorPicker().pickColor(), 0, 3);
        world.setBlock(x + 6, y + 1, z + 4, new LuckyColorPicker().pickColor(), 0, 3);
        world.setBlock(x + 7, y + 1, z + 4, new LuckyColorPicker().pickColor(), 0, 3);
        world.setBlock(x + 8, y + 1, z + 4, new LuckyColorPicker().pickColor(), 0, 3);
        world.setBlock(x + 9, y + 1, z + 4, new LuckyColorPicker().pickColor(), 0, 3);
        world.setBlock(x + 0, y + 1, z + 5, new LuckyColorPicker().pickColor(), 0, 3);
        world.setBlock(x + 1, y + 1, z + 5, new LuckyColorPicker().pickColor(), 0, 3);
        world.setBlock(x + 2, y + 1, z + 5, new LuckyColorPicker().pickColor(), 0, 3);
        world.setBlock(x + 3, y + 1, z + 5, new LuckyColorPicker().pickColor(), 0, 3);
        world.setBlock(x + 4, y + 1, z + 5, new LuckyColorPicker().pickColor(), 0, 3);
        world.setBlock(x + 5, y + 1, z + 5, new LuckyColorPicker().pickColor(), 0, 3);
        world.setBlock(x + 6, y + 1, z + 5, new LuckyColorPicker().pickColor(), 0, 3);
        world.setBlock(x + 7, y + 1, z + 5, new LuckyColorPicker().pickColor(), 0, 3);
        world.setBlock(x + 8, y + 1, z + 5, new LuckyColorPicker().pickColor(), 0, 3);
        world.setBlock(x + 9, y + 1, z + 5, new LuckyColorPicker().pickColor(), 0, 3);
        world.setBlock(x + 0, y + 1, z + 6, new LuckyColorPicker().pickColor(), 0, 3);
        world.setBlock(x + 1, y + 1, z + 6, new LuckyColorPicker().pickColor(), 0, 3);
        world.setBlock(x + 2, y + 1, z + 6, new LuckyColorPicker().pickColor(), 0, 3);
        world.setBlock(x + 3, y + 1, z + 6, new LuckyColorPicker().pickColor(), 0, 3);
        world.setBlock(x + 4, y + 1, z + 6, new LuckyColorPicker().pickColor(), 0, 3);
        world.setBlock(x + 5, y + 1, z + 6, new LuckyColorPicker().pickColor(), 0, 3);
        world.setBlock(x + 6, y + 1, z + 6, new LuckyColorPicker().pickColor(), 0, 3);
        world.setBlock(x + 7, y + 1, z + 6, new LuckyColorPicker().pickColor(), 0, 3);
        world.setBlock(x + 8, y + 1, z + 6, new LuckyColorPicker().pickColor(), 0, 3);
        world.setBlock(x + 9, y + 1, z + 6, new LuckyColorPicker().pickColor(), 0, 3);
        world.setBlock(x + 0, y + 1, z + 7, new LuckyColorPicker().pickColor(), 0, 3);
        world.setBlock(x + 1, y + 1, z + 7, new LuckyColorPicker().pickColor(), 0, 3);
        world.setBlock(x + 2, y + 1, z + 7, new LuckyColorPicker().pickColor(), 0, 3);
        world.setBlock(x + 3, y + 1, z + 7, new LuckyColorPicker().pickColor(), 0, 3);
        world.setBlock(x + 4, y + 1, z + 7, new LuckyColorPicker().pickColor(), 0, 3);
        world.setBlock(x + 5, y + 1, z + 7, new LuckyColorPicker().pickColor(), 0, 3);
        world.setBlock(x + 6, y + 1, z + 7, new LuckyColorPicker().pickColor(), 0, 3);
        world.setBlock(x + 7, y + 1, z + 7, new LuckyColorPicker().pickColor(), 0, 3);
        world.setBlock(x + 8, y + 1, z + 7, new LuckyColorPicker().pickColor(), 0, 3);
        world.setBlock(x + 9, y + 1, z + 7, new LuckyColorPicker().pickColor(), 0, 3);
        world.setBlock(x + 0, y + 1, z + 8, new LuckyColorPicker().pickColor(), 0, 3);
        world.setBlock(x + 1, y + 1, z + 8, new LuckyColorPicker().pickColor(), 0, 3);
        world.setBlock(x + 2, y + 1, z + 8, new LuckyColorPicker().pickColor(), 0, 3);
        world.setBlock(x + 3, y + 1, z + 8, new LuckyColorPicker().pickColor(), 0, 3);
        world.setBlock(x + 4, y + 1, z + 8, new LuckyColorPicker().pickColor(), 0, 3);
        world.setBlock(x + 5, y + 1, z + 8, new LuckyColorPicker().pickColor(), 0, 3);
        world.setBlock(x + 6, y + 1, z + 8, new LuckyColorPicker().pickColor(), 0, 3);
        world.setBlock(x + 7, y + 1, z + 8, new LuckyColorPicker().pickColor(), 0, 3);
        world.setBlock(x + 8, y + 1, z + 8, new LuckyColorPicker().pickColor(), 0, 3);
        world.setBlock(x + 9, y + 1, z + 8, new LuckyColorPicker().pickColor(), 0, 3);
        world.setBlock(x + 0, y + 1, z + 9, new LuckyColorPicker().pickColor(), 0, 3);
        world.setBlock(x + 1, y + 1, z + 9, new LuckyColorPicker().pickColor(), 0, 3);
        world.setBlock(x + 2, y + 1, z + 9, new LuckyColorPicker().pickColor(), 0, 3);
        world.setBlock(x + 3, y + 1, z + 9, new LuckyColorPicker().pickColor(), 0, 3);
        world.setBlock(x + 4, y + 1, z + 9, new LuckyColorPicker().pickColor(), 0, 3);
        world.setBlock(x + 5, y + 1, z + 9, new LuckyColorPicker().pickColor(), 0, 3);
        world.setBlock(x + 6, y + 1, z + 9, new LuckyColorPicker().pickColor(), 0, 3);
        world.setBlock(x + 7, y + 1, z + 9, new LuckyColorPicker().pickColor(), 0, 3);
        world.setBlock(x + 8, y + 1, z + 9, new LuckyColorPicker().pickColor(), 0, 3);
        world.setBlock(x + 9, y + 1, z + 9, new LuckyColorPicker().pickColor(), 0, 3);
        world.setBlock(x + 0, y + 2, z + 0, new LuckyColorPicker().pickColor(), 0, 3);
        world.setBlock(x + 1, y + 2, z + 0, new LuckyColorPicker().pickColor(), 0, 3);
        world.setBlock(x + 2, y + 2, z + 0, new LuckyColorPicker().pickColor(), 0, 3);
        world.setBlock(x + 3, y + 2, z + 0, new LuckyColorPicker().pickColor(), 0, 3);
        world.setBlock(x + 4, y + 2, z + 0, new LuckyColorPicker().pickColor(), 0, 3);
        world.setBlock(x + 5, y + 2, z + 0, new LuckyColorPicker().pickColor(), 0, 3);
        world.setBlock(x + 6, y + 2, z + 0, new LuckyColorPicker().pickColor(), 0, 3);
        world.setBlock(x + 7, y + 2, z + 0, new LuckyColorPicker().pickColor(), 0, 3);
        world.setBlock(x + 8, y + 2, z + 0, new LuckyColorPicker().pickColor(), 0, 3);
        world.setBlock(x + 9, y + 2, z + 0, new LuckyColorPicker().pickColor(), 0, 3);
        world.setBlock(x + 0, y + 2, z + 1, new LuckyColorPicker().pickColor(), 0, 3);
        world.setBlock(x + 1, y + 2, z + 1, new LuckyColorPicker().pickColor(), 0, 3);
        world.setBlock(x + 2, y + 2, z + 1, new LuckyColorPicker().pickColor(), 0, 3);
        world.setBlock(x + 3, y + 2, z + 1, new LuckyColorPicker().pickColor(), 0, 3);
        world.setBlock(x + 4, y + 2, z + 1, new LuckyColorPicker().pickColor(), 0, 3);
        world.setBlock(x + 5, y + 2, z + 1, new LuckyColorPicker().pickColor(), 0, 3);
        world.setBlock(x + 6, y + 2, z + 1, new LuckyColorPicker().pickColor(), 0, 3);
        world.setBlock(x + 7, y + 2, z + 1, new LuckyColorPicker().pickColor(), 0, 3);
        world.setBlock(x + 8, y + 2, z + 1, new LuckyColorPicker().pickColor(), 0, 3);
        world.setBlock(x + 9, y + 2, z + 1, new LuckyColorPicker().pickColor(), 0, 3);
        world.setBlock(x + 0, y + 2, z + 2, new LuckyColorPicker().pickColor(), 0, 3);
        world.setBlock(x + 1, y + 2, z + 2, new LuckyColorPicker().pickColor(), 0, 3);
        world.setBlock(x + 2, y + 2, z + 2, new LuckyColorPicker().pickColor(), 0, 3);
        world.setBlock(x + 3, y + 2, z + 2, new LuckyColorPicker().pickColor(), 0, 3);
        world.setBlock(x + 4, y + 2, z + 2, new LuckyColorPicker().pickColor(), 0, 3);
        world.setBlock(x + 5, y + 2, z + 2, new LuckyColorPicker().pickColor(), 0, 3);
        world.setBlock(x + 6, y + 2, z + 2, new LuckyColorPicker().pickColor(), 0, 3);
        world.setBlock(x + 7, y + 2, z + 2, new LuckyColorPicker().pickColor(), 0, 3);
        world.setBlock(x + 8, y + 2, z + 2, new LuckyColorPicker().pickColor(), 0, 3);
        world.setBlock(x + 9, y + 2, z + 2, new LuckyColorPicker().pickColor(), 0, 3);
        world.setBlock(x + 0, y + 2, z + 3, new LuckyColorPicker().pickColor(), 0, 3);
        world.setBlock(x + 1, y + 2, z + 3, new LuckyColorPicker().pickColor(), 0, 3);
        world.setBlock(x + 2, y + 2, z + 3, new LuckyColorPicker().pickColor(), 0, 3);
        world.setBlock(x + 3, y + 2, z + 3, new LuckyColorPicker().pickColor(), 0, 3);
        world.setBlock(x + 4, y + 2, z + 3, new LuckyColorPicker().pickColor(), 0, 3);
        world.setBlock(x + 5, y + 2, z + 3, new LuckyColorPicker().pickColor(), 0, 3);
        world.setBlock(x + 6, y + 2, z + 3, new LuckyColorPicker().pickColor(), 0, 3);
        world.setBlock(x + 7, y + 2, z + 3, new LuckyColorPicker().pickColor(), 0, 3);
        world.setBlock(x + 8, y + 2, z + 3, new LuckyColorPicker().pickColor(), 0, 3);
        world.setBlock(x + 9, y + 2, z + 3, new LuckyColorPicker().pickColor(), 0, 3);
        world.setBlock(x + 0, y + 2, z + 4, new LuckyColorPicker().pickColor(), 0, 3);
        world.setBlock(x + 1, y + 2, z + 4, new LuckyColorPicker().pickColor(), 0, 3);
        world.setBlock(x + 2, y + 2, z + 4, new LuckyColorPicker().pickColor(), 0, 3);
        world.setBlock(x + 3, y + 2, z + 4, new LuckyColorPicker().pickColor(), 0, 3);
        world.setBlock(x + 4, y + 2, z + 4, new LuckyColorPicker().pickColor(), 0, 3);
        world.setBlock(x + 5, y + 2, z + 4, new LuckyColorPicker().pickColor(), 0, 3);
        world.setBlock(x + 6, y + 2, z + 4, new LuckyColorPicker().pickColor(), 0, 3);
        world.setBlock(x + 7, y + 2, z + 4, new LuckyColorPicker().pickColor(), 0, 3);
        world.setBlock(x + 8, y + 2, z + 4, new LuckyColorPicker().pickColor(), 0, 3);
        world.setBlock(x + 9, y + 2, z + 4, new LuckyColorPicker().pickColor(), 0, 3);
        world.setBlock(x + 0, y + 2, z + 5, new LuckyColorPicker().pickColor(), 0, 3);
        world.setBlock(x + 1, y + 2, z + 5, new LuckyColorPicker().pickColor(), 0, 3);
        world.setBlock(x + 2, y + 2, z + 5, new LuckyColorPicker().pickColor(), 0, 3);
        world.setBlock(x + 3, y + 2, z + 5, new LuckyColorPicker().pickColor(), 0, 3);
        world.setBlock(x + 4, y + 2, z + 5, new LuckyColorPicker().pickColor(), 0, 3);
        world.setBlock(x + 5, y + 2, z + 5, new LuckyColorPicker().pickColor(), 0, 3);
        world.setBlock(x + 6, y + 2, z + 5, new LuckyColorPicker().pickColor(), 0, 3);
        world.setBlock(x + 7, y + 2, z + 5, new LuckyColorPicker().pickColor(), 0, 3);
        world.setBlock(x + 8, y + 2, z + 5, new LuckyColorPicker().pickColor(), 0, 3);
        world.setBlock(x + 9, y + 2, z + 5, new LuckyColorPicker().pickColor(), 0, 3);
        world.setBlock(x + 0, y + 2, z + 6, new LuckyColorPicker().pickColor(), 0, 3);
        world.setBlock(x + 1, y + 2, z + 6, new LuckyColorPicker().pickColor(), 0, 3);
        world.setBlock(x + 2, y + 2, z + 6, new LuckyColorPicker().pickColor(), 0, 3);
        world.setBlock(x + 3, y + 2, z + 6, new LuckyColorPicker().pickColor(), 0, 3);
        world.setBlock(x + 4, y + 2, z + 6, new LuckyColorPicker().pickColor(), 0, 3);
        world.setBlock(x + 5, y + 2, z + 6, new LuckyColorPicker().pickColor(), 0, 3);
        world.setBlock(x + 6, y + 2, z + 6, new LuckyColorPicker().pickColor(), 0, 3);
        world.setBlock(x + 7, y + 2, z + 6, new LuckyColorPicker().pickColor(), 0, 3);
        world.setBlock(x + 8, y + 2, z + 6, new LuckyColorPicker().pickColor(), 0, 3);
        world.setBlock(x + 9, y + 2, z + 6, new LuckyColorPicker().pickColor(), 0, 3);
        world.setBlock(x + 0, y + 2, z + 7, new LuckyColorPicker().pickColor(), 0, 3);
        world.setBlock(x + 1, y + 2, z + 7, new LuckyColorPicker().pickColor(), 0, 3);
        world.setBlock(x + 2, y + 2, z + 7, new LuckyColorPicker().pickColor(), 0, 3);
        world.setBlock(x + 3, y + 2, z + 7, new LuckyColorPicker().pickColor(), 0, 3);
        world.setBlock(x + 4, y + 2, z + 7, new LuckyColorPicker().pickColor(), 0, 3);
        world.setBlock(x + 5, y + 2, z + 7, new LuckyColorPicker().pickColor(), 0, 3);
        world.setBlock(x + 6, y + 2, z + 7, new LuckyColorPicker().pickColor(), 0, 3);
        world.setBlock(x + 7, y + 2, z + 7, new LuckyColorPicker().pickColor(), 0, 3);
        world.setBlock(x + 8, y + 2, z + 7, new LuckyColorPicker().pickColor(), 0, 3);
        world.setBlock(x + 9, y + 2, z + 7, new LuckyColorPicker().pickColor(), 0, 3);
        world.setBlock(x + 0, y + 2, z + 8, new LuckyColorPicker().pickColor(), 0, 3);
        world.setBlock(x + 1, y + 2, z + 8, new LuckyColorPicker().pickColor(), 0, 3);
        world.setBlock(x + 2, y + 2, z + 8, new LuckyColorPicker().pickColor(), 0, 3);
        world.setBlock(x + 3, y + 2, z + 8, new LuckyColorPicker().pickColor(), 0, 3);
        world.setBlock(x + 4, y + 2, z + 8, new LuckyColorPicker().pickColor(), 0, 3);
        world.setBlock(x + 5, y + 2, z + 8, new LuckyColorPicker().pickColor(), 0, 3);
        world.setBlock(x + 6, y + 2, z + 8, new LuckyColorPicker().pickColor(), 0, 3);
        world.setBlock(x + 7, y + 2, z + 8, new LuckyColorPicker().pickColor(), 0, 3);
        world.setBlock(x + 8, y + 2, z + 8, new LuckyColorPicker().pickColor(), 0, 3);
        world.setBlock(x + 9, y + 2, z + 8, new LuckyColorPicker().pickColor(), 0, 3);
        world.setBlock(x + 0, y + 2, z + 9, new LuckyColorPicker().pickColor(), 0, 3);
        world.setBlock(x + 1, y + 2, z + 9, new LuckyColorPicker().pickColor(), 0, 3);
        world.setBlock(x + 2, y + 2, z + 9, new LuckyColorPicker().pickColor(), 0, 3);
        world.setBlock(x + 3, y + 2, z + 9, new LuckyColorPicker().pickColor(), 0, 3);
        world.setBlock(x + 4, y + 2, z + 9, new LuckyColorPicker().pickColor(), 0, 3);
        world.setBlock(x + 5, y + 2, z + 9, new LuckyColorPicker().pickColor(), 0, 3);
        world.setBlock(x + 6, y + 2, z + 9, new LuckyColorPicker().pickColor(), 0, 3);
        world.setBlock(x + 7, y + 2, z + 9, new LuckyColorPicker().pickColor(), 0, 3);
        world.setBlock(x + 8, y + 2, z + 9, new LuckyColorPicker().pickColor(), 0, 3);
        world.setBlock(x + 9, y + 2, z + 9, new LuckyColorPicker().pickColor(), 0, 3);
        world.setBlock(x + 0, y + 3, z + 0, new LuckyColorPicker().pickColor(), 0, 3);
        world.setBlock(x + 1, y + 3, z + 0, new LuckyColorPicker().pickColor(), 0, 3);
        world.setBlock(x + 2, y + 3, z + 0, new LuckyColorPicker().pickColor(), 0, 3);
        world.setBlock(x + 3, y + 3, z + 0, new LuckyColorPicker().pickColor(), 0, 3);
        world.setBlock(x + 4, y + 3, z + 0, new LuckyColorPicker().pickColor(), 0, 3);
        world.setBlock(x + 5, y + 3, z + 0, new LuckyColorPicker().pickColor(), 0, 3);
        world.setBlock(x + 6, y + 3, z + 0, new LuckyColorPicker().pickColor(), 0, 3);
        world.setBlock(x + 7, y + 3, z + 0, new LuckyColorPicker().pickColor(), 0, 3);
        world.setBlock(x + 8, y + 3, z + 0, new LuckyColorPicker().pickColor(), 0, 3);
        world.setBlock(x + 9, y + 3, z + 0, new LuckyColorPicker().pickColor(), 0, 3);
        world.setBlock(x + 0, y + 3, z + 1, new LuckyColorPicker().pickColor(), 0, 3);
        world.setBlock(x + 1, y + 3, z + 1, new LuckyColorPicker().pickColor(), 0, 3);
        world.setBlock(x + 2, y + 3, z + 1, new LuckyColorPicker().pickColor(), 0, 3);
        world.setBlock(x + 3, y + 3, z + 1, new LuckyColorPicker().pickColor(), 0, 3);
        world.setBlock(x + 4, y + 3, z + 1, new LuckyColorPicker().pickColor(), 0, 3);
        world.setBlock(x + 5, y + 3, z + 1, new LuckyColorPicker().pickColor(), 0, 3);
        world.setBlock(x + 6, y + 3, z + 1, new LuckyColorPicker().pickColor(), 0, 3);
        world.setBlock(x + 7, y + 3, z + 1, new LuckyColorPicker().pickColor(), 0, 3);
        world.setBlock(x + 8, y + 3, z + 1, new LuckyColorPicker().pickColor(), 0, 3);
        world.setBlock(x + 9, y + 3, z + 1, new LuckyColorPicker().pickColor(), 0, 3);
        world.setBlock(x + 0, y + 3, z + 2, new LuckyColorPicker().pickColor(), 0, 3);
        world.setBlock(x + 1, y + 3, z + 2, new LuckyColorPicker().pickColor(), 0, 3);
        world.setBlock(x + 2, y + 3, z + 2, new LuckyColorPicker().pickColor(), 0, 3);
        world.setBlock(x + 3, y + 3, z + 2, new LuckyColorPicker().pickColor(), 0, 3);
        world.setBlock(x + 4, y + 3, z + 2, new LuckyColorPicker().pickColor(), 0, 3);
        world.setBlock(x + 5, y + 3, z + 2, new LuckyColorPicker().pickColor(), 0, 3);
        world.setBlock(x + 6, y + 3, z + 2, new LuckyColorPicker().pickColor(), 0, 3);
        world.setBlock(x + 7, y + 3, z + 2, new LuckyColorPicker().pickColor(), 0, 3);
        world.setBlock(x + 8, y + 3, z + 2, new LuckyColorPicker().pickColor(), 0, 3);
        world.setBlock(x + 9, y + 3, z + 2, new LuckyColorPicker().pickColor(), 0, 3);
        world.setBlock(x + 0, y + 3, z + 3, new LuckyColorPicker().pickColor(), 0, 3);
        world.setBlock(x + 1, y + 3, z + 3, new LuckyColorPicker().pickColor(), 0, 3);
        world.setBlock(x + 2, y + 3, z + 3, new LuckyColorPicker().pickColor(), 0, 3);
        world.setBlock(x + 3, y + 3, z + 3, new LuckyColorPicker().pickColor(), 0, 3);
        world.setBlock(x + 4, y + 3, z + 3, new LuckyColorPicker().pickColor(), 0, 3);
        world.setBlock(x + 5, y + 3, z + 3, new LuckyColorPicker().pickColor(), 0, 3);
        world.setBlock(x + 6, y + 3, z + 3, new LuckyColorPicker().pickColor(), 0, 3);
        world.setBlock(x + 7, y + 3, z + 3, new LuckyColorPicker().pickColor(), 0, 3);
        world.setBlock(x + 8, y + 3, z + 3, new LuckyColorPicker().pickColor(), 0, 3);
        world.setBlock(x + 9, y + 3, z + 3, new LuckyColorPicker().pickColor(), 0, 3);
        world.setBlock(x + 0, y + 3, z + 4, new LuckyColorPicker().pickColor(), 0, 3);
        world.setBlock(x + 1, y + 3, z + 4, new LuckyColorPicker().pickColor(), 0, 3);
        world.setBlock(x + 2, y + 3, z + 4, new LuckyColorPicker().pickColor(), 0, 3);
        world.setBlock(x + 3, y + 3, z + 4, new LuckyColorPicker().pickColor(), 0, 3);
        world.setBlock(x + 4, y + 3, z + 4, new LuckyColorPicker().pickColor(), 0, 3);
        world.setBlock(x + 5, y + 3, z + 4, new LuckyColorPicker().pickColor(), 0, 3);
        world.setBlock(x + 6, y + 3, z + 4, new LuckyColorPicker().pickColor(), 0, 3);
        world.setBlock(x + 7, y + 3, z + 4, new LuckyColorPicker().pickColor(), 0, 3);
        world.setBlock(x + 8, y + 3, z + 4, new LuckyColorPicker().pickColor(), 0, 3);
        world.setBlock(x + 9, y + 3, z + 4, new LuckyColorPicker().pickColor(), 0, 3);
        world.setBlock(x + 0, y + 3, z + 5, new LuckyColorPicker().pickColor(), 0, 3);
        world.setBlock(x + 1, y + 3, z + 5, new LuckyColorPicker().pickColor(), 0, 3);
        world.setBlock(x + 2, y + 3, z + 5, new LuckyColorPicker().pickColor(), 0, 3);
        world.setBlock(x + 3, y + 3, z + 5, new LuckyColorPicker().pickColor(), 0, 3);
        world.setBlock(x + 4, y + 3, z + 5, new LuckyColorPicker().pickColor(), 0, 3);
        world.setBlock(x + 5, y + 3, z + 5, new LuckyColorPicker().pickColor(), 0, 3);
        world.setBlock(x + 6, y + 3, z + 5, new LuckyColorPicker().pickColor(), 0, 3);
        world.setBlock(x + 7, y + 3, z + 5, new LuckyColorPicker().pickColor(), 0, 3);
        world.setBlock(x + 8, y + 3, z + 5, new LuckyColorPicker().pickColor(), 0, 3);
        world.setBlock(x + 9, y + 3, z + 5, new LuckyColorPicker().pickColor(), 0, 3);
        world.setBlock(x + 0, y + 3, z + 6, new LuckyColorPicker().pickColor(), 0, 3);
        world.setBlock(x + 1, y + 3, z + 6, new LuckyColorPicker().pickColor(), 0, 3);
        world.setBlock(x + 2, y + 3, z + 6, new LuckyColorPicker().pickColor(), 0, 3);
        world.setBlock(x + 3, y + 3, z + 6, new LuckyColorPicker().pickColor(), 0, 3);
        world.setBlock(x + 4, y + 3, z + 6, new LuckyColorPicker().pickColor(), 0, 3);
        world.setBlock(x + 5, y + 3, z + 6, new LuckyColorPicker().pickColor(), 0, 3);
        world.setBlock(x + 6, y + 3, z + 6, new LuckyColorPicker().pickColor(), 0, 3);
        world.setBlock(x + 7, y + 3, z + 6, new LuckyColorPicker().pickColor(), 0, 3);
        world.setBlock(x + 8, y + 3, z + 6, new LuckyColorPicker().pickColor(), 0, 3);
        world.setBlock(x + 9, y + 3, z + 6, new LuckyColorPicker().pickColor(), 0, 3);
        world.setBlock(x + 0, y + 3, z + 7, new LuckyColorPicker().pickColor(), 0, 3);
        world.setBlock(x + 1, y + 3, z + 7, new LuckyColorPicker().pickColor(), 0, 3);
        world.setBlock(x + 2, y + 3, z + 7, new LuckyColorPicker().pickColor(), 0, 3);
        world.setBlock(x + 3, y + 3, z + 7, new LuckyColorPicker().pickColor(), 0, 3);
        world.setBlock(x + 4, y + 3, z + 7, new LuckyColorPicker().pickColor(), 0, 3);
        world.setBlock(x + 5, y + 3, z + 7, new LuckyColorPicker().pickColor(), 0, 3);
        world.setBlock(x + 6, y + 3, z + 7, new LuckyColorPicker().pickColor(), 0, 3);
        world.setBlock(x + 7, y + 3, z + 7, new LuckyColorPicker().pickColor(), 0, 3);
        world.setBlock(x + 8, y + 3, z + 7, new LuckyColorPicker().pickColor(), 0, 3);
        world.setBlock(x + 9, y + 3, z + 7, new LuckyColorPicker().pickColor(), 0, 3);
        world.setBlock(x + 0, y + 3, z + 8, new LuckyColorPicker().pickColor(), 0, 3);
        world.setBlock(x + 1, y + 3, z + 8, new LuckyColorPicker().pickColor(), 0, 3);
        world.setBlock(x + 2, y + 3, z + 8, new LuckyColorPicker().pickColor(), 0, 3);
        world.setBlock(x + 3, y + 3, z + 8, new LuckyColorPicker().pickColor(), 0, 3);
        world.setBlock(x + 4, y + 3, z + 8, new LuckyColorPicker().pickColor(), 0, 3);
        world.setBlock(x + 5, y + 3, z + 8, new LuckyColorPicker().pickColor(), 0, 3);
        world.setBlock(x + 6, y + 3, z + 8, new LuckyColorPicker().pickColor(), 0, 3);
        world.setBlock(x + 7, y + 3, z + 8, new LuckyColorPicker().pickColor(), 0, 3);
        world.setBlock(x + 8, y + 3, z + 8, new LuckyColorPicker().pickColor(), 0, 3);
        world.setBlock(x + 9, y + 3, z + 8, new LuckyColorPicker().pickColor(), 0, 3);
        world.setBlock(x + 0, y + 3, z + 9, new LuckyColorPicker().pickColor(), 0, 3);
        world.setBlock(x + 1, y + 3, z + 9, new LuckyColorPicker().pickColor(), 0, 3);
        world.setBlock(x + 2, y + 3, z + 9, new LuckyColorPicker().pickColor(), 0, 3);
        world.setBlock(x + 3, y + 3, z + 9, new LuckyColorPicker().pickColor(), 0, 3);
        world.setBlock(x + 4, y + 3, z + 9, new LuckyColorPicker().pickColor(), 0, 3);
        world.setBlock(x + 5, y + 3, z + 9, new LuckyColorPicker().pickColor(), 0, 3);
        world.setBlock(x + 6, y + 3, z + 9, new LuckyColorPicker().pickColor(), 0, 3);
        world.setBlock(x + 7, y + 3, z + 9, new LuckyColorPicker().pickColor(), 0, 3);
        world.setBlock(x + 8, y + 3, z + 9, new LuckyColorPicker().pickColor(), 0, 3);
        world.setBlock(x + 9, y + 3, z + 9, new LuckyColorPicker().pickColor(), 0, 3);
        world.setBlock(x + 0, y + 4, z + 0, new LuckyColorPicker().pickColor(), 0, 3);
        world.setBlock(x + 1, y + 4, z + 0, new LuckyColorPicker().pickColor(), 0, 3);
        world.setBlock(x + 2, y + 4, z + 0, new LuckyColorPicker().pickColor(), 0, 3);
        world.setBlock(x + 3, y + 4, z + 0, new LuckyColorPicker().pickColor(), 0, 3);
        world.setBlock(x + 4, y + 4, z + 0, new LuckyColorPicker().pickColor(), 0, 3);
        world.setBlock(x + 5, y + 4, z + 0, new LuckyColorPicker().pickColor(), 0, 3);
        world.setBlock(x + 6, y + 4, z + 0, new LuckyColorPicker().pickColor(), 0, 3);
        world.setBlock(x + 7, y + 4, z + 0, new LuckyColorPicker().pickColor(), 0, 3);
        world.setBlock(x + 8, y + 4, z + 0, new LuckyColorPicker().pickColor(), 0, 3);
        world.setBlock(x + 9, y + 4, z + 0, new LuckyColorPicker().pickColor(), 0, 3);
        world.setBlock(x + 0, y + 4, z + 1, new LuckyColorPicker().pickColor(), 0, 3);
        world.setBlock(x + 1, y + 4, z + 1, new LuckyColorPicker().pickColor(), 0, 3);
        world.setBlock(x + 2, y + 4, z + 1, new LuckyColorPicker().pickColor(), 0, 3);
        world.setBlock(x + 3, y + 4, z + 1, new LuckyColorPicker().pickColor(), 0, 3);
        world.setBlock(x + 4, y + 4, z + 1, new LuckyColorPicker().pickColor(), 0, 3);
        world.setBlock(x + 5, y + 4, z + 1, new LuckyColorPicker().pickColor(), 0, 3);
        world.setBlock(x + 6, y + 4, z + 1, new LuckyColorPicker().pickColor(), 0, 3);
        world.setBlock(x + 7, y + 4, z + 1, new LuckyColorPicker().pickColor(), 0, 3);
        world.setBlock(x + 8, y + 4, z + 1, new LuckyColorPicker().pickColor(), 0, 3);
        world.setBlock(x + 9, y + 4, z + 1, new LuckyColorPicker().pickColor(), 0, 3);
        world.setBlock(x + 0, y + 4, z + 2, new LuckyColorPicker().pickColor(), 0, 3);
        world.setBlock(x + 1, y + 4, z + 2, new LuckyColorPicker().pickColor(), 0, 3);
        world.setBlock(x + 2, y + 4, z + 2, new LuckyColorPicker().pickColor(), 0, 3);
        world.setBlock(x + 3, y + 4, z + 2, new LuckyColorPicker().pickColor(), 0, 3);
        world.setBlock(x + 4, y + 4, z + 2, new LuckyColorPicker().pickColor(), 0, 3);
        world.setBlock(x + 5, y + 4, z + 2, new LuckyColorPicker().pickColor(), 0, 3);
        world.setBlock(x + 6, y + 4, z + 2, new LuckyColorPicker().pickColor(), 0, 3);
        world.setBlock(x + 7, y + 4, z + 2, new LuckyColorPicker().pickColor(), 0, 3);
        world.setBlock(x + 8, y + 4, z + 2, new LuckyColorPicker().pickColor(), 0, 3);
        world.setBlock(x + 9, y + 4, z + 2, new LuckyColorPicker().pickColor(), 0, 3);
        world.setBlock(x + 0, y + 4, z + 3, new LuckyColorPicker().pickColor(), 0, 3);
        world.setBlock(x + 1, y + 4, z + 3, new LuckyColorPicker().pickColor(), 0, 3);
        world.setBlock(x + 2, y + 4, z + 3, new LuckyColorPicker().pickColor(), 0, 3);
        world.setBlock(x + 3, y + 4, z + 3, new LuckyColorPicker().pickColor(), 0, 3);
        world.setBlock(x + 4, y + 4, z + 3, new LuckyColorPicker().pickColor(), 0, 3);
        world.setBlock(x + 5, y + 4, z + 3, new LuckyColorPicker().pickColor(), 0, 3);
        world.setBlock(x + 6, y + 4, z + 3, new LuckyColorPicker().pickColor(), 0, 3);
        world.setBlock(x + 7, y + 4, z + 3, new LuckyColorPicker().pickColor(), 0, 3);
        world.setBlock(x + 8, y + 4, z + 3, new LuckyColorPicker().pickColor(), 0, 3);
        world.setBlock(x + 9, y + 4, z + 3, new LuckyColorPicker().pickColor(), 0, 3);
        world.setBlock(x + 0, y + 4, z + 4, new LuckyColorPicker().pickColor(), 0, 3);
        world.setBlock(x + 1, y + 4, z + 4, new LuckyColorPicker().pickColor(), 0, 3);
        world.setBlock(x + 2, y + 4, z + 4, new LuckyColorPicker().pickColor(), 0, 3);
        world.setBlock(x + 3, y + 4, z + 4, new LuckyColorPicker().pickColor(), 0, 3);
        world.setBlock(x + 4, y + 4, z + 4, new LuckyColorPicker().pickColor(), 0, 3);
        world.setBlock(x + 5, y + 4, z + 4, new LuckyColorPicker().pickColor(), 0, 3);
        world.setBlock(x + 6, y + 4, z + 4, new LuckyColorPicker().pickColor(), 0, 3);
        world.setBlock(x + 7, y + 4, z + 4, new LuckyColorPicker().pickColor(), 0, 3);
        world.setBlock(x + 8, y + 4, z + 4, new LuckyColorPicker().pickColor(), 0, 3);
        world.setBlock(x + 9, y + 4, z + 4, new LuckyColorPicker().pickColor(), 0, 3);
        world.setBlock(x + 0, y + 4, z + 5, new LuckyColorPicker().pickColor(), 0, 3);
        world.setBlock(x + 1, y + 4, z + 5, new LuckyColorPicker().pickColor(), 0, 3);
        world.setBlock(x + 2, y + 4, z + 5, new LuckyColorPicker().pickColor(), 0, 3);
        world.setBlock(x + 3, y + 4, z + 5, new LuckyColorPicker().pickColor(), 0, 3);
        world.setBlock(x + 4, y + 4, z + 5, new LuckyColorPicker().pickColor(), 0, 3);
        world.setBlock(x + 5, y + 4, z + 5, new LuckyColorPicker().pickColor(), 0, 3);
        world.setBlock(x + 6, y + 4, z + 5, new LuckyColorPicker().pickColor(), 0, 3);
        world.setBlock(x + 7, y + 4, z + 5, new LuckyColorPicker().pickColor(), 0, 3);
        world.setBlock(x + 8, y + 4, z + 5, new LuckyColorPicker().pickColor(), 0, 3);
        world.setBlock(x + 9, y + 4, z + 5, new LuckyColorPicker().pickColor(), 0, 3);
        world.setBlock(x + 0, y + 4, z + 6, new LuckyColorPicker().pickColor(), 0, 3);
        world.setBlock(x + 1, y + 4, z + 6, new LuckyColorPicker().pickColor(), 0, 3);
        world.setBlock(x + 2, y + 4, z + 6, new LuckyColorPicker().pickColor(), 0, 3);
        world.setBlock(x + 3, y + 4, z + 6, new LuckyColorPicker().pickColor(), 0, 3);
        world.setBlock(x + 4, y + 4, z + 6, new LuckyColorPicker().pickColor(), 0, 3);
        world.setBlock(x + 5, y + 4, z + 6, new LuckyColorPicker().pickColor(), 0, 3);
        world.setBlock(x + 6, y + 4, z + 6, new LuckyColorPicker().pickColor(), 0, 3);
        world.setBlock(x + 7, y + 4, z + 6, new LuckyColorPicker().pickColor(), 0, 3);
        world.setBlock(x + 8, y + 4, z + 6, new LuckyColorPicker().pickColor(), 0, 3);
        world.setBlock(x + 9, y + 4, z + 6, new LuckyColorPicker().pickColor(), 0, 3);
        world.setBlock(x + 0, y + 4, z + 7, new LuckyColorPicker().pickColor(), 0, 3);
        world.setBlock(x + 1, y + 4, z + 7, new LuckyColorPicker().pickColor(), 0, 3);
        world.setBlock(x + 2, y + 4, z + 7, new LuckyColorPicker().pickColor(), 0, 3);
        world.setBlock(x + 3, y + 4, z + 7, new LuckyColorPicker().pickColor(), 0, 3);
        world.setBlock(x + 4, y + 4, z + 7, new LuckyColorPicker().pickColor(), 0, 3);
        world.setBlock(x + 5, y + 4, z + 7, new LuckyColorPicker().pickColor(), 0, 3);
        world.setBlock(x + 6, y + 4, z + 7, new LuckyColorPicker().pickColor(), 0, 3);
        world.setBlock(x + 7, y + 4, z + 7, new LuckyColorPicker().pickColor(), 0, 3);
        world.setBlock(x + 8, y + 4, z + 7, new LuckyColorPicker().pickColor(), 0, 3);
        world.setBlock(x + 9, y + 4, z + 7, new LuckyColorPicker().pickColor(), 0, 3);
        world.setBlock(x + 0, y + 4, z + 8, new LuckyColorPicker().pickColor(), 0, 3);
        world.setBlock(x + 1, y + 4, z + 8, new LuckyColorPicker().pickColor(), 0, 3);
        world.setBlock(x + 2, y + 4, z + 8, new LuckyColorPicker().pickColor(), 0, 3);
        world.setBlock(x + 3, y + 4, z + 8, new LuckyColorPicker().pickColor(), 0, 3);
        world.setBlock(x + 4, y + 4, z + 8, new LuckyColorPicker().pickColor(), 0, 3);
        world.setBlock(x + 5, y + 4, z + 8, new LuckyColorPicker().pickColor(), 0, 3);
        world.setBlock(x + 6, y + 4, z + 8, new LuckyColorPicker().pickColor(), 0, 3);
        world.setBlock(x + 7, y + 4, z + 8, new LuckyColorPicker().pickColor(), 0, 3);
        world.setBlock(x + 8, y + 4, z + 8, new LuckyColorPicker().pickColor(), 0, 3);
        world.setBlock(x + 9, y + 4, z + 8, new LuckyColorPicker().pickColor(), 0, 3);
        world.setBlock(x + 0, y + 4, z + 9, new LuckyColorPicker().pickColor(), 0, 3);
        world.setBlock(x + 1, y + 4, z + 9, new LuckyColorPicker().pickColor(), 0, 3);
        world.setBlock(x + 2, y + 4, z + 9, new LuckyColorPicker().pickColor(), 0, 3);
        world.setBlock(x + 3, y + 4, z + 9, new LuckyColorPicker().pickColor(), 0, 3);
        world.setBlock(x + 4, y + 4, z + 9, new LuckyColorPicker().pickColor(), 0, 3);
        world.setBlock(x + 5, y + 4, z + 9, new LuckyColorPicker().pickColor(), 0, 3);
        world.setBlock(x + 6, y + 4, z + 9, new LuckyColorPicker().pickColor(), 0, 3);
        world.setBlock(x + 7, y + 4, z + 9, new LuckyColorPicker().pickColor(), 0, 3);
        world.setBlock(x + 8, y + 4, z + 9, new LuckyColorPicker().pickColor(), 0, 3);
        world.setBlock(x + 9, y + 4, z + 9, new LuckyColorPicker().pickColor(), 0, 3);
        world.setBlock(x + 0, y + 5, z + 0, new LuckyColorPicker().pickColor(), 0, 3);
        world.setBlock(x + 1, y + 5, z + 0, new LuckyColorPicker().pickColor(), 0, 3);
        world.setBlock(x + 2, y + 5, z + 0, new LuckyColorPicker().pickColor(), 0, 3);
        world.setBlock(x + 3, y + 5, z + 0, new LuckyColorPicker().pickColor(), 0, 3);
        world.setBlock(x + 4, y + 5, z + 0, new LuckyColorPicker().pickColor(), 0, 3);
        world.setBlock(x + 5, y + 5, z + 0, new LuckyColorPicker().pickColor(), 0, 3);
        world.setBlock(x + 6, y + 5, z + 0, new LuckyColorPicker().pickColor(), 0, 3);
        world.setBlock(x + 7, y + 5, z + 0, new LuckyColorPicker().pickColor(), 0, 3);
        world.setBlock(x + 8, y + 5, z + 0, new LuckyColorPicker().pickColor(), 0, 3);
        world.setBlock(x + 9, y + 5, z + 0, new LuckyColorPicker().pickColor(), 0, 3);
        world.setBlock(x + 0, y + 5, z + 1, new LuckyColorPicker().pickColor(), 0, 3);
        world.setBlock(x + 1, y + 5, z + 1, new LuckyColorPicker().pickColor(), 0, 3);
        world.setBlock(x + 2, y + 5, z + 1, new LuckyColorPicker().pickColor(), 0, 3);
        world.setBlock(x + 3, y + 5, z + 1, new LuckyColorPicker().pickColor(), 0, 3);
        world.setBlock(x + 4, y + 5, z + 1, new LuckyColorPicker().pickColor(), 0, 3);
        world.setBlock(x + 5, y + 5, z + 1, new LuckyColorPicker().pickColor(), 0, 3);
        world.setBlock(x + 6, y + 5, z + 1, new LuckyColorPicker().pickColor(), 0, 3);
        world.setBlock(x + 7, y + 5, z + 1, new LuckyColorPicker().pickColor(), 0, 3);
        world.setBlock(x + 8, y + 5, z + 1, new LuckyColorPicker().pickColor(), 0, 3);
        world.setBlock(x + 9, y + 5, z + 1, new LuckyColorPicker().pickColor(), 0, 3);
        world.setBlock(x + 0, y + 5, z + 2, new LuckyColorPicker().pickColor(), 0, 3);
        world.setBlock(x + 1, y + 5, z + 2, new LuckyColorPicker().pickColor(), 0, 3);
        world.setBlock(x + 2, y + 5, z + 2, new LuckyColorPicker().pickColor(), 0, 3);
        world.setBlock(x + 3, y + 5, z + 2, new LuckyColorPicker().pickColor(), 0, 3);
        world.setBlock(x + 4, y + 5, z + 2, new LuckyColorPicker().pickColor(), 0, 3);
        world.setBlock(x + 5, y + 5, z + 2, new LuckyColorPicker().pickColor(), 0, 3);
        world.setBlock(x + 6, y + 5, z + 2, new LuckyColorPicker().pickColor(), 0, 3);
        world.setBlock(x + 7, y + 5, z + 2, new LuckyColorPicker().pickColor(), 0, 3);
        world.setBlock(x + 8, y + 5, z + 2, new LuckyColorPicker().pickColor(), 0, 3);
        world.setBlock(x + 9, y + 5, z + 2, new LuckyColorPicker().pickColor(), 0, 3);
        world.setBlock(x + 0, y + 5, z + 3, new LuckyColorPicker().pickColor(), 0, 3);
        world.setBlock(x + 1, y + 5, z + 3, new LuckyColorPicker().pickColor(), 0, 3);
        world.setBlock(x + 2, y + 5, z + 3, new LuckyColorPicker().pickColor(), 0, 3);
        world.setBlock(x + 3, y + 5, z + 3, new LuckyColorPicker().pickColor(), 0, 3);
        world.setBlock(x + 4, y + 5, z + 3, new LuckyColorPicker().pickColor(), 0, 3);
        world.setBlock(x + 5, y + 5, z + 3, new LuckyColorPicker().pickColor(), 0, 3);
        world.setBlock(x + 6, y + 5, z + 3, new LuckyColorPicker().pickColor(), 0, 3);
        world.setBlock(x + 7, y + 5, z + 3, new LuckyColorPicker().pickColor(), 0, 3);
        world.setBlock(x + 8, y + 5, z + 3, new LuckyColorPicker().pickColor(), 0, 3);
        world.setBlock(x + 9, y + 5, z + 3, new LuckyColorPicker().pickColor(), 0, 3);
        world.setBlock(x + 0, y + 5, z + 4, new LuckyColorPicker().pickColor(), 0, 3);
        world.setBlock(x + 1, y + 5, z + 4, new LuckyColorPicker().pickColor(), 0, 3);
        world.setBlock(x + 2, y + 5, z + 4, new LuckyColorPicker().pickColor(), 0, 3);
        world.setBlock(x + 3, y + 5, z + 4, new LuckyColorPicker().pickColor(), 0, 3);
        world.setBlock(x + 4, y + 5, z + 4, new LuckyColorPicker().pickColor(), 0, 3);
        world.setBlock(x + 5, y + 5, z + 4, new LuckyColorPicker().pickColor(), 0, 3);
        world.setBlock(x + 6, y + 5, z + 4, new LuckyColorPicker().pickColor(), 0, 3);
        world.setBlock(x + 7, y + 5, z + 4, new LuckyColorPicker().pickColor(), 0, 3);
        world.setBlock(x + 8, y + 5, z + 4, new LuckyColorPicker().pickColor(), 0, 3);
        world.setBlock(x + 9, y + 5, z + 4, new LuckyColorPicker().pickColor(), 0, 3);
        world.setBlock(x + 0, y + 5, z + 5, new LuckyColorPicker().pickColor(), 0, 3);
        world.setBlock(x + 1, y + 5, z + 5, new LuckyColorPicker().pickColor(), 0, 3);
        world.setBlock(x + 2, y + 5, z + 5, new LuckyColorPicker().pickColor(), 0, 3);
        world.setBlock(x + 3, y + 5, z + 5, new LuckyColorPicker().pickColor(), 0, 3);
        world.setBlock(x + 4, y + 5, z + 5, new LuckyColorPicker().pickColor(), 0, 3);
        world.setBlock(x + 5, y + 5, z + 5, new LuckyColorPicker().pickColor(), 0, 3);
        world.setBlock(x + 6, y + 5, z + 5, new LuckyColorPicker().pickColor(), 0, 3);
        world.setBlock(x + 7, y + 5, z + 5, new LuckyColorPicker().pickColor(), 0, 3);
        world.setBlock(x + 8, y + 5, z + 5, new LuckyColorPicker().pickColor(), 0, 3);
        world.setBlock(x + 9, y + 5, z + 5, new LuckyColorPicker().pickColor(), 0, 3);
        world.setBlock(x + 0, y + 5, z + 6, new LuckyColorPicker().pickColor(), 0, 3);
        world.setBlock(x + 1, y + 5, z + 6, new LuckyColorPicker().pickColor(), 0, 3);
        world.setBlock(x + 2, y + 5, z + 6, new LuckyColorPicker().pickColor(), 0, 3);
        world.setBlock(x + 3, y + 5, z + 6, new LuckyColorPicker().pickColor(), 0, 3);
        world.setBlock(x + 4, y + 5, z + 6, new LuckyColorPicker().pickColor(), 0, 3);
        world.setBlock(x + 5, y + 5, z + 6, new LuckyColorPicker().pickColor(), 0, 3);
        world.setBlock(x + 6, y + 5, z + 6, new LuckyColorPicker().pickColor(), 0, 3);
        world.setBlock(x + 7, y + 5, z + 6, new LuckyColorPicker().pickColor(), 0, 3);
        world.setBlock(x + 8, y + 5, z + 6, new LuckyColorPicker().pickColor(), 0, 3);
        world.setBlock(x + 9, y + 5, z + 6, new LuckyColorPicker().pickColor(), 0, 3);
        world.setBlock(x + 0, y + 5, z + 7, new LuckyColorPicker().pickColor(), 0, 3);
        world.setBlock(x + 1, y + 5, z + 7, new LuckyColorPicker().pickColor(), 0, 3);
        world.setBlock(x + 2, y + 5, z + 7, new LuckyColorPicker().pickColor(), 0, 3);
        world.setBlock(x + 3, y + 5, z + 7, new LuckyColorPicker().pickColor(), 0, 3);
        world.setBlock(x + 4, y + 5, z + 7, new LuckyColorPicker().pickColor(), 0, 3);
        world.setBlock(x + 5, y + 5, z + 7, new LuckyColorPicker().pickColor(), 0, 3);
        world.setBlock(x + 6, y + 5, z + 7, new LuckyColorPicker().pickColor(), 0, 3);
        world.setBlock(x + 7, y + 5, z + 7, new LuckyColorPicker().pickColor(), 0, 3);
        world.setBlock(x + 8, y + 5, z + 7, new LuckyColorPicker().pickColor(), 0, 3);
        world.setBlock(x + 9, y + 5, z + 7, new LuckyColorPicker().pickColor(), 0, 3);
        world.setBlock(x + 0, y + 5, z + 8, new LuckyColorPicker().pickColor(), 0, 3);
        world.setBlock(x + 1, y + 5, z + 8, new LuckyColorPicker().pickColor(), 0, 3);
        world.setBlock(x + 2, y + 5, z + 8, new LuckyColorPicker().pickColor(), 0, 3);
        world.setBlock(x + 3, y + 5, z + 8, new LuckyColorPicker().pickColor(), 0, 3);
        world.setBlock(x + 4, y + 5, z + 8, new LuckyColorPicker().pickColor(), 0, 3);
        world.setBlock(x + 5, y + 5, z + 8, new LuckyColorPicker().pickColor(), 0, 3);
        world.setBlock(x + 6, y + 5, z + 8, new LuckyColorPicker().pickColor(), 0, 3);
        world.setBlock(x + 7, y + 5, z + 8, new LuckyColorPicker().pickColor(), 0, 3);
        world.setBlock(x + 8, y + 5, z + 8, new LuckyColorPicker().pickColor(), 0, 3);
        world.setBlock(x + 9, y + 5, z + 8, new LuckyColorPicker().pickColor(), 0, 3);
        world.setBlock(x + 0, y + 5, z + 9, new LuckyColorPicker().pickColor(), 0, 3);
        world.setBlock(x + 1, y + 5, z + 9, new LuckyColorPicker().pickColor(), 0, 3);
        world.setBlock(x + 2, y + 5, z + 9, new LuckyColorPicker().pickColor(), 0, 3);
        world.setBlock(x + 3, y + 5, z + 9, new LuckyColorPicker().pickColor(), 0, 3);
        world.setBlock(x + 4, y + 5, z + 9, new LuckyColorPicker().pickColor(), 0, 3);
        world.setBlock(x + 5, y + 5, z + 9, new LuckyColorPicker().pickColor(), 0, 3);
        world.setBlock(x + 6, y + 5, z + 9, new LuckyColorPicker().pickColor(), 0, 3);
        world.setBlock(x + 7, y + 5, z + 9, new LuckyColorPicker().pickColor(), 0, 3);
        world.setBlock(x + 8, y + 5, z + 9, new LuckyColorPicker().pickColor(), 0, 3);
        world.setBlock(x + 9, y + 5, z + 9, new LuckyColorPicker().pickColor(), 0, 3);
        world.setBlock(x + 0, y + 6, z + 0, new LuckyColorPicker().pickColor(), 0, 3);
        world.setBlock(x + 1, y + 6, z + 0, new LuckyColorPicker().pickColor(), 0, 3);
        world.setBlock(x + 2, y + 6, z + 0, new LuckyColorPicker().pickColor(), 0, 3);
        world.setBlock(x + 3, y + 6, z + 0, new LuckyColorPicker().pickColor(), 0, 3);
        world.setBlock(x + 4, y + 6, z + 0, new LuckyColorPicker().pickColor(), 0, 3);
        world.setBlock(x + 5, y + 6, z + 0, new LuckyColorPicker().pickColor(), 0, 3);
        world.setBlock(x + 6, y + 6, z + 0, new LuckyColorPicker().pickColor(), 0, 3);
        world.setBlock(x + 7, y + 6, z + 0, new LuckyColorPicker().pickColor(), 0, 3);
        world.setBlock(x + 8, y + 6, z + 0, new LuckyColorPicker().pickColor(), 0, 3);
        world.setBlock(x + 9, y + 6, z + 0, new LuckyColorPicker().pickColor(), 0, 3);
        world.setBlock(x + 0, y + 6, z + 1, new LuckyColorPicker().pickColor(), 0, 3);
        world.setBlock(x + 1, y + 6, z + 1, new LuckyColorPicker().pickColor(), 0, 3);
        world.setBlock(x + 2, y + 6, z + 1, new LuckyColorPicker().pickColor(), 0, 3);
        world.setBlock(x + 3, y + 6, z + 1, new LuckyColorPicker().pickColor(), 0, 3);
        world.setBlock(x + 4, y + 6, z + 1, new LuckyColorPicker().pickColor(), 0, 3);
        world.setBlock(x + 5, y + 6, z + 1, new LuckyColorPicker().pickColor(), 0, 3);
        world.setBlock(x + 6, y + 6, z + 1, new LuckyColorPicker().pickColor(), 0, 3);
        world.setBlock(x + 7, y + 6, z + 1, new LuckyColorPicker().pickColor(), 0, 3);
        world.setBlock(x + 8, y + 6, z + 1, new LuckyColorPicker().pickColor(), 0, 3);
        world.setBlock(x + 9, y + 6, z + 1, new LuckyColorPicker().pickColor(), 0, 3);
        world.setBlock(x + 0, y + 6, z + 2, new LuckyColorPicker().pickColor(), 0, 3);
        world.setBlock(x + 1, y + 6, z + 2, new LuckyColorPicker().pickColor(), 0, 3);
        world.setBlock(x + 2, y + 6, z + 2, new LuckyColorPicker().pickColor(), 0, 3);
        world.setBlock(x + 3, y + 6, z + 2, new LuckyColorPicker().pickColor(), 0, 3);
        world.setBlock(x + 4, y + 6, z + 2, new LuckyColorPicker().pickColor(), 0, 3);
        world.setBlock(x + 5, y + 6, z + 2, new LuckyColorPicker().pickColor(), 0, 3);
        world.setBlock(x + 6, y + 6, z + 2, new LuckyColorPicker().pickColor(), 0, 3);
        world.setBlock(x + 7, y + 6, z + 2, new LuckyColorPicker().pickColor(), 0, 3);
        world.setBlock(x + 8, y + 6, z + 2, new LuckyColorPicker().pickColor(), 0, 3);
        world.setBlock(x + 9, y + 6, z + 2, new LuckyColorPicker().pickColor(), 0, 3);
        world.setBlock(x + 0, y + 6, z + 3, new LuckyColorPicker().pickColor(), 0, 3);
        world.setBlock(x + 1, y + 6, z + 3, new LuckyColorPicker().pickColor(), 0, 3);
        world.setBlock(x + 2, y + 6, z + 3, new LuckyColorPicker().pickColor(), 0, 3);
        world.setBlock(x + 3, y + 6, z + 3, new LuckyColorPicker().pickColor(), 0, 3);
        world.setBlock(x + 4, y + 6, z + 3, new LuckyColorPicker().pickColor(), 0, 3);
        world.setBlock(x + 5, y + 6, z + 3, new LuckyColorPicker().pickColor(), 0, 3);
        world.setBlock(x + 6, y + 6, z + 3, new LuckyColorPicker().pickColor(), 0, 3);
        world.setBlock(x + 7, y + 6, z + 3, new LuckyColorPicker().pickColor(), 0, 3);
        world.setBlock(x + 8, y + 6, z + 3, new LuckyColorPicker().pickColor(), 0, 3);
        world.setBlock(x + 9, y + 6, z + 3, new LuckyColorPicker().pickColor(), 0, 3);
        world.setBlock(x + 0, y + 6, z + 4, new LuckyColorPicker().pickColor(), 0, 3);
        world.setBlock(x + 1, y + 6, z + 4, new LuckyColorPicker().pickColor(), 0, 3);
        world.setBlock(x + 2, y + 6, z + 4, new LuckyColorPicker().pickColor(), 0, 3);
        world.setBlock(x + 3, y + 6, z + 4, new LuckyColorPicker().pickColor(), 0, 3);
        world.setBlock(x + 4, y + 6, z + 4, new LuckyColorPicker().pickColor(), 0, 3);
        world.setBlock(x + 5, y + 6, z + 4, new LuckyColorPicker().pickColor(), 0, 3);
        world.setBlock(x + 6, y + 6, z + 4, new LuckyColorPicker().pickColor(), 0, 3);
        world.setBlock(x + 7, y + 6, z + 4, new LuckyColorPicker().pickColor(), 0, 3);
        world.setBlock(x + 8, y + 6, z + 4, new LuckyColorPicker().pickColor(), 0, 3);
        world.setBlock(x + 9, y + 6, z + 4, new LuckyColorPicker().pickColor(), 0, 3);
        world.setBlock(x + 0, y + 6, z + 5, new LuckyColorPicker().pickColor(), 0, 3);
        world.setBlock(x + 1, y + 6, z + 5, new LuckyColorPicker().pickColor(), 0, 3);
        world.setBlock(x + 2, y + 6, z + 5, new LuckyColorPicker().pickColor(), 0, 3);
        world.setBlock(x + 3, y + 6, z + 5, new LuckyColorPicker().pickColor(), 0, 3);
        world.setBlock(x + 4, y + 6, z + 5, new LuckyColorPicker().pickColor(), 0, 3);
        world.setBlock(x + 5, y + 6, z + 5, new LuckyColorPicker().pickColor(), 0, 3);
        world.setBlock(x + 6, y + 6, z + 5, new LuckyColorPicker().pickColor(), 0, 3);
        world.setBlock(x + 7, y + 6, z + 5, new LuckyColorPicker().pickColor(), 0, 3);
        world.setBlock(x + 8, y + 6, z + 5, new LuckyColorPicker().pickColor(), 0, 3);
        world.setBlock(x + 9, y + 6, z + 5, new LuckyColorPicker().pickColor(), 0, 3);
        world.setBlock(x + 0, y + 6, z + 6, new LuckyColorPicker().pickColor(), 0, 3);
        world.setBlock(x + 1, y + 6, z + 6, new LuckyColorPicker().pickColor(), 0, 3);
        world.setBlock(x + 2, y + 6, z + 6, new LuckyColorPicker().pickColor(), 0, 3);
        world.setBlock(x + 3, y + 6, z + 6, new LuckyColorPicker().pickColor(), 0, 3);
        world.setBlock(x + 4, y + 6, z + 6, new LuckyColorPicker().pickColor(), 0, 3);
        world.setBlock(x + 5, y + 6, z + 6, new LuckyColorPicker().pickColor(), 0, 3);
        world.setBlock(x + 6, y + 6, z + 6, new LuckyColorPicker().pickColor(), 0, 3);
        world.setBlock(x + 7, y + 6, z + 6, new LuckyColorPicker().pickColor(), 0, 3);
        world.setBlock(x + 8, y + 6, z + 6, new LuckyColorPicker().pickColor(), 0, 3);
        world.setBlock(x + 9, y + 6, z + 6, new LuckyColorPicker().pickColor(), 0, 3);
        world.setBlock(x + 0, y + 6, z + 7, new LuckyColorPicker().pickColor(), 0, 3);
        world.setBlock(x + 1, y + 6, z + 7, new LuckyColorPicker().pickColor(), 0, 3);
        world.setBlock(x + 2, y + 6, z + 7, new LuckyColorPicker().pickColor(), 0, 3);
        world.setBlock(x + 3, y + 6, z + 7, new LuckyColorPicker().pickColor(), 0, 3);
        world.setBlock(x + 4, y + 6, z + 7, new LuckyColorPicker().pickColor(), 0, 3);
        world.setBlock(x + 5, y + 6, z + 7, new LuckyColorPicker().pickColor(), 0, 3);
        world.setBlock(x + 6, y + 6, z + 7, new LuckyColorPicker().pickColor(), 0, 3);
        world.setBlock(x + 7, y + 6, z + 7, new LuckyColorPicker().pickColor(), 0, 3);
        world.setBlock(x + 8, y + 6, z + 7, new LuckyColorPicker().pickColor(), 0, 3);
        world.setBlock(x + 9, y + 6, z + 7, new LuckyColorPicker().pickColor(), 0, 3);
        world.setBlock(x + 0, y + 6, z + 8, new LuckyColorPicker().pickColor(), 0, 3);
        world.setBlock(x + 1, y + 6, z + 8, new LuckyColorPicker().pickColor(), 0, 3);
        world.setBlock(x + 2, y + 6, z + 8, new LuckyColorPicker().pickColor(), 0, 3);
        world.setBlock(x + 3, y + 6, z + 8, new LuckyColorPicker().pickColor(), 0, 3);
        world.setBlock(x + 4, y + 6, z + 8, new LuckyColorPicker().pickColor(), 0, 3);
        world.setBlock(x + 5, y + 6, z + 8, new LuckyColorPicker().pickColor(), 0, 3);
        world.setBlock(x + 6, y + 6, z + 8, new LuckyColorPicker().pickColor(), 0, 3);
        world.setBlock(x + 7, y + 6, z + 8, new LuckyColorPicker().pickColor(), 0, 3);
        world.setBlock(x + 8, y + 6, z + 8, new LuckyColorPicker().pickColor(), 0, 3);
        world.setBlock(x + 9, y + 6, z + 8, new LuckyColorPicker().pickColor(), 0, 3);
        world.setBlock(x + 0, y + 6, z + 9, new LuckyColorPicker().pickColor(), 0, 3);
        world.setBlock(x + 1, y + 6, z + 9, new LuckyColorPicker().pickColor(), 0, 3);
        world.setBlock(x + 2, y + 6, z + 9, new LuckyColorPicker().pickColor(), 0, 3);
        world.setBlock(x + 3, y + 6, z + 9, new LuckyColorPicker().pickColor(), 0, 3);
        world.setBlock(x + 4, y + 6, z + 9, new LuckyColorPicker().pickColor(), 0, 3);
        world.setBlock(x + 5, y + 6, z + 9, new LuckyColorPicker().pickColor(), 0, 3);
        world.setBlock(x + 6, y + 6, z + 9, new LuckyColorPicker().pickColor(), 0, 3);
        world.setBlock(x + 7, y + 6, z + 9, new LuckyColorPicker().pickColor(), 0, 3);
        world.setBlock(x + 8, y + 6, z + 9, new LuckyColorPicker().pickColor(), 0, 3);
        world.setBlock(x + 9, y + 6, z + 9, new LuckyColorPicker().pickColor(), 0, 3);
        world.setBlock(x + 0, y + 7, z + 0, new LuckyColorPicker().pickColor(), 0, 3);
        world.setBlock(x + 1, y + 7, z + 0, new LuckyColorPicker().pickColor(), 0, 3);
        world.setBlock(x + 2, y + 7, z + 0, new LuckyColorPicker().pickColor(), 0, 3);
        world.setBlock(x + 3, y + 7, z + 0, new LuckyColorPicker().pickColor(), 0, 3);
        world.setBlock(x + 4, y + 7, z + 0, new LuckyColorPicker().pickColor(), 0, 3);
        world.setBlock(x + 5, y + 7, z + 0, new LuckyColorPicker().pickColor(), 0, 3);
        world.setBlock(x + 6, y + 7, z + 0, new LuckyColorPicker().pickColor(), 0, 3);
        world.setBlock(x + 7, y + 7, z + 0, new LuckyColorPicker().pickColor(), 0, 3);
        world.setBlock(x + 8, y + 7, z + 0, new LuckyColorPicker().pickColor(), 0, 3);
        world.setBlock(x + 9, y + 7, z + 0, new LuckyColorPicker().pickColor(), 0, 3);
        world.setBlock(x + 0, y + 7, z + 1, new LuckyColorPicker().pickColor(), 0, 3);
        world.setBlock(x + 1, y + 7, z + 1, new LuckyColorPicker().pickColor(), 0, 3);
        world.setBlock(x + 2, y + 7, z + 1, new LuckyColorPicker().pickColor(), 0, 3);
        world.setBlock(x + 3, y + 7, z + 1, new LuckyColorPicker().pickColor(), 0, 3);
        world.setBlock(x + 4, y + 7, z + 1, new LuckyColorPicker().pickColor(), 0, 3);
        world.setBlock(x + 5, y + 7, z + 1, new LuckyColorPicker().pickColor(), 0, 3);
        world.setBlock(x + 6, y + 7, z + 1, new LuckyColorPicker().pickColor(), 0, 3);
        world.setBlock(x + 7, y + 7, z + 1, new LuckyColorPicker().pickColor(), 0, 3);
        world.setBlock(x + 8, y + 7, z + 1, new LuckyColorPicker().pickColor(), 0, 3);
        world.setBlock(x + 9, y + 7, z + 1, new LuckyColorPicker().pickColor(), 0, 3);
        world.setBlock(x + 0, y + 7, z + 2, new LuckyColorPicker().pickColor(), 0, 3);
        world.setBlock(x + 1, y + 7, z + 2, new LuckyColorPicker().pickColor(), 0, 3);
        world.setBlock(x + 2, y + 7, z + 2, new LuckyColorPicker().pickColor(), 0, 3);
        world.setBlock(x + 3, y + 7, z + 2, new LuckyColorPicker().pickColor(), 0, 3);
        world.setBlock(x + 4, y + 7, z + 2, new LuckyColorPicker().pickColor(), 0, 3);
        world.setBlock(x + 5, y + 7, z + 2, new LuckyColorPicker().pickColor(), 0, 3);
        world.setBlock(x + 6, y + 7, z + 2, new LuckyColorPicker().pickColor(), 0, 3);
        world.setBlock(x + 7, y + 7, z + 2, new LuckyColorPicker().pickColor(), 0, 3);
        world.setBlock(x + 8, y + 7, z + 2, new LuckyColorPicker().pickColor(), 0, 3);
        world.setBlock(x + 9, y + 7, z + 2, new LuckyColorPicker().pickColor(), 0, 3);
        world.setBlock(x + 0, y + 7, z + 3, new LuckyColorPicker().pickColor(), 0, 3);
        world.setBlock(x + 1, y + 7, z + 3, new LuckyColorPicker().pickColor(), 0, 3);
        world.setBlock(x + 2, y + 7, z + 3, new LuckyColorPicker().pickColor(), 0, 3);
        world.setBlock(x + 3, y + 7, z + 3, new LuckyColorPicker().pickColor(), 0, 3);
        world.setBlock(x + 4, y + 7, z + 3, new LuckyColorPicker().pickColor(), 0, 3);
        world.setBlock(x + 5, y + 7, z + 3, new LuckyColorPicker().pickColor(), 0, 3);
        world.setBlock(x + 6, y + 7, z + 3, new LuckyColorPicker().pickColor(), 0, 3);
        world.setBlock(x + 7, y + 7, z + 3, new LuckyColorPicker().pickColor(), 0, 3);
        world.setBlock(x + 8, y + 7, z + 3, new LuckyColorPicker().pickColor(), 0, 3);
        world.setBlock(x + 9, y + 7, z + 3, new LuckyColorPicker().pickColor(), 0, 3);
        world.setBlock(x + 0, y + 7, z + 4, new LuckyColorPicker().pickColor(), 0, 3);
        world.setBlock(x + 1, y + 7, z + 4, new LuckyColorPicker().pickColor(), 0, 3);
        world.setBlock(x + 2, y + 7, z + 4, new LuckyColorPicker().pickColor(), 0, 3);
        world.setBlock(x + 3, y + 7, z + 4, new LuckyColorPicker().pickColor(), 0, 3);
        world.setBlock(x + 4, y + 7, z + 4, new LuckyColorPicker().pickColor(), 0, 3);
        world.setBlock(x + 5, y + 7, z + 4, new LuckyColorPicker().pickColor(), 0, 3);
        world.setBlock(x + 6, y + 7, z + 4, new LuckyColorPicker().pickColor(), 0, 3);
        world.setBlock(x + 7, y + 7, z + 4, new LuckyColorPicker().pickColor(), 0, 3);
        world.setBlock(x + 8, y + 7, z + 4, new LuckyColorPicker().pickColor(), 0, 3);
        world.setBlock(x + 9, y + 7, z + 4, new LuckyColorPicker().pickColor(), 0, 3);
        world.setBlock(x + 0, y + 7, z + 5, new LuckyColorPicker().pickColor(), 0, 3);
        world.setBlock(x + 1, y + 7, z + 5, new LuckyColorPicker().pickColor(), 0, 3);
        world.setBlock(x + 2, y + 7, z + 5, new LuckyColorPicker().pickColor(), 0, 3);
        world.setBlock(x + 3, y + 7, z + 5, new LuckyColorPicker().pickColor(), 0, 3);
        world.setBlock(x + 4, y + 7, z + 5, new LuckyColorPicker().pickColor(), 0, 3);
        world.setBlock(x + 5, y + 7, z + 5, new LuckyColorPicker().pickColor(), 0, 3);
        world.setBlock(x + 6, y + 7, z + 5, new LuckyColorPicker().pickColor(), 0, 3);
        world.setBlock(x + 7, y + 7, z + 5, new LuckyColorPicker().pickColor(), 0, 3);
        world.setBlock(x + 8, y + 7, z + 5, new LuckyColorPicker().pickColor(), 0, 3);
        world.setBlock(x + 9, y + 7, z + 5, new LuckyColorPicker().pickColor(), 0, 3);
        world.setBlock(x + 0, y + 7, z + 6, new LuckyColorPicker().pickColor(), 0, 3);
        world.setBlock(x + 1, y + 7, z + 6, new LuckyColorPicker().pickColor(), 0, 3);
        world.setBlock(x + 2, y + 7, z + 6, new LuckyColorPicker().pickColor(), 0, 3);
        world.setBlock(x + 3, y + 7, z + 6, new LuckyColorPicker().pickColor(), 0, 3);
        world.setBlock(x + 4, y + 7, z + 6, new LuckyColorPicker().pickColor(), 0, 3);
        world.setBlock(x + 5, y + 7, z + 6, new LuckyColorPicker().pickColor(), 0, 3);
        world.setBlock(x + 6, y + 7, z + 6, new LuckyColorPicker().pickColor(), 0, 3);
        world.setBlock(x + 7, y + 7, z + 6, new LuckyColorPicker().pickColor(), 0, 3);
        world.setBlock(x + 8, y + 7, z + 6, new LuckyColorPicker().pickColor(), 0, 3);
        world.setBlock(x + 9, y + 7, z + 6, new LuckyColorPicker().pickColor(), 0, 3);
        world.setBlock(x + 0, y + 7, z + 7, new LuckyColorPicker().pickColor(), 0, 3);
        world.setBlock(x + 1, y + 7, z + 7, new LuckyColorPicker().pickColor(), 0, 3);
        world.setBlock(x + 2, y + 7, z + 7, new LuckyColorPicker().pickColor(), 0, 3);
        world.setBlock(x + 3, y + 7, z + 7, new LuckyColorPicker().pickColor(), 0, 3);
        world.setBlock(x + 4, y + 7, z + 7, new LuckyColorPicker().pickColor(), 0, 3);
        world.setBlock(x + 5, y + 7, z + 7, new LuckyColorPicker().pickColor(), 0, 3);
        world.setBlock(x + 6, y + 7, z + 7, new LuckyColorPicker().pickColor(), 0, 3);
        world.setBlock(x + 7, y + 7, z + 7, new LuckyColorPicker().pickColor(), 0, 3);
        world.setBlock(x + 8, y + 7, z + 7, new LuckyColorPicker().pickColor(), 0, 3);
        world.setBlock(x + 9, y + 7, z + 7, new LuckyColorPicker().pickColor(), 0, 3);
        world.setBlock(x + 0, y + 7, z + 8, new LuckyColorPicker().pickColor(), 0, 3);
        world.setBlock(x + 1, y + 7, z + 8, new LuckyColorPicker().pickColor(), 0, 3);
        world.setBlock(x + 2, y + 7, z + 8, new LuckyColorPicker().pickColor(), 0, 3);
        world.setBlock(x + 3, y + 7, z + 8, new LuckyColorPicker().pickColor(), 0, 3);
        world.setBlock(x + 4, y + 7, z + 8, new LuckyColorPicker().pickColor(), 0, 3);
        world.setBlock(x + 5, y + 7, z + 8, new LuckyColorPicker().pickColor(), 0, 3);
        world.setBlock(x + 6, y + 7, z + 8, new LuckyColorPicker().pickColor(), 0, 3);
        world.setBlock(x + 7, y + 7, z + 8, new LuckyColorPicker().pickColor(), 0, 3);
        world.setBlock(x + 8, y + 7, z + 8, new LuckyColorPicker().pickColor(), 0, 3);
        world.setBlock(x + 9, y + 7, z + 8, new LuckyColorPicker().pickColor(), 0, 3);
        world.setBlock(x + 0, y + 7, z + 9, new LuckyColorPicker().pickColor(), 0, 3);
        world.setBlock(x + 1, y + 7, z + 9, new LuckyColorPicker().pickColor(), 0, 3);
        world.setBlock(x + 2, y + 7, z + 9, new LuckyColorPicker().pickColor(), 0, 3);
        world.setBlock(x + 3, y + 7, z + 9, new LuckyColorPicker().pickColor(), 0, 3);
        world.setBlock(x + 4, y + 7, z + 9, new LuckyColorPicker().pickColor(), 0, 3);
        world.setBlock(x + 5, y + 7, z + 9, new LuckyColorPicker().pickColor(), 0, 3);
        world.setBlock(x + 6, y + 7, z + 9, new LuckyColorPicker().pickColor(), 0, 3);
        world.setBlock(x + 7, y + 7, z + 9, new LuckyColorPicker().pickColor(), 0, 3);
        world.setBlock(x + 8, y + 7, z + 9, new LuckyColorPicker().pickColor(), 0, 3);
        world.setBlock(x + 9, y + 7, z + 9, new LuckyColorPicker().pickColor(), 0, 3);
        world.setBlock(x + 0, y + 8, z + 0, new LuckyColorPicker().pickColor(), 0, 3);
        world.setBlock(x + 1, y + 8, z + 0, new LuckyColorPicker().pickColor(), 0, 3);
        world.setBlock(x + 2, y + 8, z + 0, new LuckyColorPicker().pickColor(), 0, 3);
        world.setBlock(x + 3, y + 8, z + 0, new LuckyColorPicker().pickColor(), 0, 3);
        world.setBlock(x + 4, y + 8, z + 0, new LuckyColorPicker().pickColor(), 0, 3);
        world.setBlock(x + 5, y + 8, z + 0, new LuckyColorPicker().pickColor(), 0, 3);
        world.setBlock(x + 6, y + 8, z + 0, new LuckyColorPicker().pickColor(), 0, 3);
        world.setBlock(x + 7, y + 8, z + 0, new LuckyColorPicker().pickColor(), 0, 3);
        world.setBlock(x + 8, y + 8, z + 0, new LuckyColorPicker().pickColor(), 0, 3);
        world.setBlock(x + 9, y + 8, z + 0, new LuckyColorPicker().pickColor(), 0, 3);
        world.setBlock(x + 0, y + 8, z + 1, new LuckyColorPicker().pickColor(), 0, 3);
        world.setBlock(x + 1, y + 8, z + 1, new LuckyColorPicker().pickColor(), 0, 3);
        world.setBlock(x + 2, y + 8, z + 1, new LuckyColorPicker().pickColor(), 0, 3);
        world.setBlock(x + 3, y + 8, z + 1, new LuckyColorPicker().pickColor(), 0, 3);
        world.setBlock(x + 4, y + 8, z + 1, new LuckyColorPicker().pickColor(), 0, 3);
        world.setBlock(x + 5, y + 8, z + 1, new LuckyColorPicker().pickColor(), 0, 3);
        world.setBlock(x + 6, y + 8, z + 1, new LuckyColorPicker().pickColor(), 0, 3);
        world.setBlock(x + 7, y + 8, z + 1, new LuckyColorPicker().pickColor(), 0, 3);
        world.setBlock(x + 8, y + 8, z + 1, new LuckyColorPicker().pickColor(), 0, 3);
        world.setBlock(x + 9, y + 8, z + 1, new LuckyColorPicker().pickColor(), 0, 3);
        world.setBlock(x + 0, y + 8, z + 2, new LuckyColorPicker().pickColor(), 0, 3);
        world.setBlock(x + 1, y + 8, z + 2, new LuckyColorPicker().pickColor(), 0, 3);
        world.setBlock(x + 2, y + 8, z + 2, new LuckyColorPicker().pickColor(), 0, 3);
        world.setBlock(x + 3, y + 8, z + 2, new LuckyColorPicker().pickColor(), 0, 3);
        world.setBlock(x + 4, y + 8, z + 2, new LuckyColorPicker().pickColor(), 0, 3);
        world.setBlock(x + 5, y + 8, z + 2, new LuckyColorPicker().pickColor(), 0, 3);
        world.setBlock(x + 6, y + 8, z + 2, new LuckyColorPicker().pickColor(), 0, 3);
        world.setBlock(x + 7, y + 8, z + 2, new LuckyColorPicker().pickColor(), 0, 3);
        world.setBlock(x + 8, y + 8, z + 2, new LuckyColorPicker().pickColor(), 0, 3);
        world.setBlock(x + 9, y + 8, z + 2, new LuckyColorPicker().pickColor(), 0, 3);
        world.setBlock(x + 0, y + 8, z + 3, new LuckyColorPicker().pickColor(), 0, 3);
        world.setBlock(x + 1, y + 8, z + 3, new LuckyColorPicker().pickColor(), 0, 3);
        world.setBlock(x + 2, y + 8, z + 3, new LuckyColorPicker().pickColor(), 0, 3);
        world.setBlock(x + 3, y + 8, z + 3, new LuckyColorPicker().pickColor(), 0, 3);
        world.setBlock(x + 4, y + 8, z + 3, new LuckyColorPicker().pickColor(), 0, 3);
        world.setBlock(x + 5, y + 8, z + 3, new LuckyColorPicker().pickColor(), 0, 3);
        world.setBlock(x + 6, y + 8, z + 3, new LuckyColorPicker().pickColor(), 0, 3);
        world.setBlock(x + 7, y + 8, z + 3, new LuckyColorPicker().pickColor(), 0, 3);
        world.setBlock(x + 8, y + 8, z + 3, new LuckyColorPicker().pickColor(), 0, 3);
        world.setBlock(x + 9, y + 8, z + 3, new LuckyColorPicker().pickColor(), 0, 3);
        world.setBlock(x + 0, y + 8, z + 4, new LuckyColorPicker().pickColor(), 0, 3);
        world.setBlock(x + 1, y + 8, z + 4, new LuckyColorPicker().pickColor(), 0, 3);
        world.setBlock(x + 2, y + 8, z + 4, new LuckyColorPicker().pickColor(), 0, 3);
        world.setBlock(x + 3, y + 8, z + 4, new LuckyColorPicker().pickColor(), 0, 3);
        world.setBlock(x + 4, y + 8, z + 4, new LuckyColorPicker().pickColor(), 0, 3);
        world.setBlock(x + 5, y + 8, z + 4, new LuckyColorPicker().pickColor(), 0, 3);
        world.setBlock(x + 6, y + 8, z + 4, new LuckyColorPicker().pickColor(), 0, 3);
        world.setBlock(x + 7, y + 8, z + 4, new LuckyColorPicker().pickColor(), 0, 3);
        world.setBlock(x + 8, y + 8, z + 4, new LuckyColorPicker().pickColor(), 0, 3);
        world.setBlock(x + 9, y + 8, z + 4, new LuckyColorPicker().pickColor(), 0, 3);
        world.setBlock(x + 0, y + 8, z + 5, new LuckyColorPicker().pickColor(), 0, 3);
        world.setBlock(x + 1, y + 8, z + 5, new LuckyColorPicker().pickColor(), 0, 3);
        world.setBlock(x + 2, y + 8, z + 5, new LuckyColorPicker().pickColor(), 0, 3);
        world.setBlock(x + 3, y + 8, z + 5, new LuckyColorPicker().pickColor(), 0, 3);
        world.setBlock(x + 4, y + 8, z + 5, new LuckyColorPicker().pickColor(), 0, 3);
        world.setBlock(x + 5, y + 8, z + 5, new LuckyColorPicker().pickColor(), 0, 3);
        world.setBlock(x + 6, y + 8, z + 5, new LuckyColorPicker().pickColor(), 0, 3);
        world.setBlock(x + 7, y + 8, z + 5, new LuckyColorPicker().pickColor(), 0, 3);
        world.setBlock(x + 8, y + 8, z + 5, new LuckyColorPicker().pickColor(), 0, 3);
        world.setBlock(x + 9, y + 8, z + 5, new LuckyColorPicker().pickColor(), 0, 3);
        world.setBlock(x + 0, y + 8, z + 6, new LuckyColorPicker().pickColor(), 0, 3);
        world.setBlock(x + 1, y + 8, z + 6, new LuckyColorPicker().pickColor(), 0, 3);
        world.setBlock(x + 2, y + 8, z + 6, new LuckyColorPicker().pickColor(), 0, 3);
        world.setBlock(x + 3, y + 8, z + 6, new LuckyColorPicker().pickColor(), 0, 3);
        world.setBlock(x + 4, y + 8, z + 6, new LuckyColorPicker().pickColor(), 0, 3);
        world.setBlock(x + 5, y + 8, z + 6, new LuckyColorPicker().pickColor(), 0, 3);
        world.setBlock(x + 6, y + 8, z + 6, new LuckyColorPicker().pickColor(), 0, 3);
        world.setBlock(x + 7, y + 8, z + 6, new LuckyColorPicker().pickColor(), 0, 3);
        world.setBlock(x + 8, y + 8, z + 6, new LuckyColorPicker().pickColor(), 0, 3);
        world.setBlock(x + 9, y + 8, z + 6, new LuckyColorPicker().pickColor(), 0, 3);
        world.setBlock(x + 0, y + 8, z + 7, new LuckyColorPicker().pickColor(), 0, 3);
        world.setBlock(x + 1, y + 8, z + 7, new LuckyColorPicker().pickColor(), 0, 3);
        world.setBlock(x + 2, y + 8, z + 7, new LuckyColorPicker().pickColor(), 0, 3);
        world.setBlock(x + 3, y + 8, z + 7, new LuckyColorPicker().pickColor(), 0, 3);
        world.setBlock(x + 4, y + 8, z + 7, new LuckyColorPicker().pickColor(), 0, 3);
        world.setBlock(x + 5, y + 8, z + 7, new LuckyColorPicker().pickColor(), 0, 3);
        world.setBlock(x + 6, y + 8, z + 7, new LuckyColorPicker().pickColor(), 0, 3);
        world.setBlock(x + 7, y + 8, z + 7, new LuckyColorPicker().pickColor(), 0, 3);
        world.setBlock(x + 8, y + 8, z + 7, new LuckyColorPicker().pickColor(), 0, 3);
        world.setBlock(x + 9, y + 8, z + 7, new LuckyColorPicker().pickColor(), 0, 3);
        world.setBlock(x + 0, y + 8, z + 8, new LuckyColorPicker().pickColor(), 0, 3);
        world.setBlock(x + 1, y + 8, z + 8, new LuckyColorPicker().pickColor(), 0, 3);
        world.setBlock(x + 2, y + 8, z + 8, new LuckyColorPicker().pickColor(), 0, 3);
        world.setBlock(x + 3, y + 8, z + 8, new LuckyColorPicker().pickColor(), 0, 3);
        world.setBlock(x + 4, y + 8, z + 8, new LuckyColorPicker().pickColor(), 0, 3);
        world.setBlock(x + 5, y + 8, z + 8, new LuckyColorPicker().pickColor(), 0, 3);
        world.setBlock(x + 6, y + 8, z + 8, new LuckyColorPicker().pickColor(), 0, 3);
        world.setBlock(x + 7, y + 8, z + 8, new LuckyColorPicker().pickColor(), 0, 3);
        world.setBlock(x + 8, y + 8, z + 8, new LuckyColorPicker().pickColor(), 0, 3);
        world.setBlock(x + 9, y + 8, z + 8, new LuckyColorPicker().pickColor(), 0, 3);
        world.setBlock(x + 0, y + 8, z + 9, new LuckyColorPicker().pickColor(), 0, 3);
        world.setBlock(x + 1, y + 8, z + 9, new LuckyColorPicker().pickColor(), 0, 3);
        world.setBlock(x + 2, y + 8, z + 9, new LuckyColorPicker().pickColor(), 0, 3);
        world.setBlock(x + 3, y + 8, z + 9, new LuckyColorPicker().pickColor(), 0, 3);
        world.setBlock(x + 4, y + 8, z + 9, new LuckyColorPicker().pickColor(), 0, 3);
        world.setBlock(x + 5, y + 8, z + 9, new LuckyColorPicker().pickColor(), 0, 3);
        world.setBlock(x + 6, y + 8, z + 9, new LuckyColorPicker().pickColor(), 0, 3);
        world.setBlock(x + 7, y + 8, z + 9, new LuckyColorPicker().pickColor(), 0, 3);
        world.setBlock(x + 8, y + 8, z + 9, new LuckyColorPicker().pickColor(), 0, 3);
        world.setBlock(x + 9, y + 8, z + 9, new LuckyColorPicker().pickColor(), 0, 3);
        world.setBlock(x + 0, y + 9, z + 0, new LuckyColorPicker().pickColor(), 0, 3);
        world.setBlock(x + 1, y + 9, z + 0, new LuckyColorPicker().pickColor(), 0, 3);
        world.setBlock(x + 2, y + 9, z + 0, new LuckyColorPicker().pickColor(), 0, 3);
        world.setBlock(x + 3, y + 9, z + 0, new LuckyColorPicker().pickColor(), 0, 3);
        world.setBlock(x + 4, y + 9, z + 0, new LuckyColorPicker().pickColor(), 0, 3);
        world.setBlock(x + 5, y + 9, z + 0, new LuckyColorPicker().pickColor(), 0, 3);
        world.setBlock(x + 6, y + 9, z + 0, new LuckyColorPicker().pickColor(), 0, 3);
        world.setBlock(x + 7, y + 9, z + 0, new LuckyColorPicker().pickColor(), 0, 3);
        world.setBlock(x + 8, y + 9, z + 0, new LuckyColorPicker().pickColor(), 0, 3);
        world.setBlock(x + 9, y + 9, z + 0, new LuckyColorPicker().pickColor(), 0, 3);
        world.setBlock(x + 0, y + 9, z + 1, new LuckyColorPicker().pickColor(), 0, 3);
        world.setBlock(x + 1, y + 9, z + 1, new LuckyColorPicker().pickColor(), 0, 3);
        world.setBlock(x + 2, y + 9, z + 1, new LuckyColorPicker().pickColor(), 0, 3);
        world.setBlock(x + 3, y + 9, z + 1, new LuckyColorPicker().pickColor(), 0, 3);
        world.setBlock(x + 4, y + 9, z + 1, new LuckyColorPicker().pickColor(), 0, 3);
        world.setBlock(x + 5, y + 9, z + 1, new LuckyColorPicker().pickColor(), 0, 3);
        world.setBlock(x + 6, y + 9, z + 1, new LuckyColorPicker().pickColor(), 0, 3);
        world.setBlock(x + 7, y + 9, z + 1, new LuckyColorPicker().pickColor(), 0, 3);
        world.setBlock(x + 8, y + 9, z + 1, new LuckyColorPicker().pickColor(), 0, 3);
        world.setBlock(x + 9, y + 9, z + 1, new LuckyColorPicker().pickColor(), 0, 3);
        world.setBlock(x + 0, y + 9, z + 2, new LuckyColorPicker().pickColor(), 0, 3);
        world.setBlock(x + 1, y + 9, z + 2, new LuckyColorPicker().pickColor(), 0, 3);
        world.setBlock(x + 2, y + 9, z + 2, new LuckyColorPicker().pickColor(), 0, 3);
        world.setBlock(x + 3, y + 9, z + 2, new LuckyColorPicker().pickColor(), 0, 3);
        world.setBlock(x + 4, y + 9, z + 2, new LuckyColorPicker().pickColor(), 0, 3);
        world.setBlock(x + 5, y + 9, z + 2, new LuckyColorPicker().pickColor(), 0, 3);
        world.setBlock(x + 6, y + 9, z + 2, new LuckyColorPicker().pickColor(), 0, 3);
        world.setBlock(x + 7, y + 9, z + 2, new LuckyColorPicker().pickColor(), 0, 3);
        world.setBlock(x + 8, y + 9, z + 2, new LuckyColorPicker().pickColor(), 0, 3);
        world.setBlock(x + 9, y + 9, z + 2, new LuckyColorPicker().pickColor(), 0, 3);
        world.setBlock(x + 0, y + 9, z + 3, new LuckyColorPicker().pickColor(), 0, 3);
        world.setBlock(x + 1, y + 9, z + 3, new LuckyColorPicker().pickColor(), 0, 3);
        world.setBlock(x + 2, y + 9, z + 3, new LuckyColorPicker().pickColor(), 0, 3);
        world.setBlock(x + 3, y + 9, z + 3, new LuckyColorPicker().pickColor(), 0, 3);
        world.setBlock(x + 4, y + 9, z + 3, new LuckyColorPicker().pickColor(), 0, 3);
        world.setBlock(x + 5, y + 9, z + 3, new LuckyColorPicker().pickColor(), 0, 3);
        world.setBlock(x + 6, y + 9, z + 3, new LuckyColorPicker().pickColor(), 0, 3);
        world.setBlock(x + 7, y + 9, z + 3, new LuckyColorPicker().pickColor(), 0, 3);
        world.setBlock(x + 8, y + 9, z + 3, new LuckyColorPicker().pickColor(), 0, 3);
        world.setBlock(x + 9, y + 9, z + 3, new LuckyColorPicker().pickColor(), 0, 3);
        world.setBlock(x + 0, y + 9, z + 4, new LuckyColorPicker().pickColor(), 0, 3);
        world.setBlock(x + 1, y + 9, z + 4, new LuckyColorPicker().pickColor(), 0, 3);
        world.setBlock(x + 2, y + 9, z + 4, new LuckyColorPicker().pickColor(), 0, 3);
        world.setBlock(x + 3, y + 9, z + 4, new LuckyColorPicker().pickColor(), 0, 3);
        world.setBlock(x + 4, y + 9, z + 4, new LuckyColorPicker().pickColor(), 0, 3);
        world.setBlock(x + 5, y + 9, z + 4, new LuckyColorPicker().pickColor(), 0, 3);
        world.setBlock(x + 6, y + 9, z + 4, new LuckyColorPicker().pickColor(), 0, 3);
        world.setBlock(x + 7, y + 9, z + 4, new LuckyColorPicker().pickColor(), 0, 3);
        world.setBlock(x + 8, y + 9, z + 4, new LuckyColorPicker().pickColor(), 0, 3);
        world.setBlock(x + 9, y + 9, z + 4, new LuckyColorPicker().pickColor(), 0, 3);
        world.setBlock(x + 0, y + 9, z + 5, new LuckyColorPicker().pickColor(), 0, 3);
        world.setBlock(x + 1, y + 9, z + 5, new LuckyColorPicker().pickColor(), 0, 3);
        world.setBlock(x + 2, y + 9, z + 5, new LuckyColorPicker().pickColor(), 0, 3);
        world.setBlock(x + 3, y + 9, z + 5, new LuckyColorPicker().pickColor(), 0, 3);
        world.setBlock(x + 4, y + 9, z + 5, new LuckyColorPicker().pickColor(), 0, 3);
        world.setBlock(x + 5, y + 9, z + 5, new LuckyColorPicker().pickColor(), 0, 3);
        world.setBlock(x + 6, y + 9, z + 5, new LuckyColorPicker().pickColor(), 0, 3);
        world.setBlock(x + 7, y + 9, z + 5, new LuckyColorPicker().pickColor(), 0, 3);
        world.setBlock(x + 8, y + 9, z + 5, new LuckyColorPicker().pickColor(), 0, 3);
        world.setBlock(x + 9, y + 9, z + 5, new LuckyColorPicker().pickColor(), 0, 3);
        world.setBlock(x + 0, y + 9, z + 6, new LuckyColorPicker().pickColor(), 0, 3);
        world.setBlock(x + 1, y + 9, z + 6, new LuckyColorPicker().pickColor(), 0, 3);
        world.setBlock(x + 2, y + 9, z + 6, new LuckyColorPicker().pickColor(), 0, 3);
        world.setBlock(x + 3, y + 9, z + 6, new LuckyColorPicker().pickColor(), 0, 3);
        world.setBlock(x + 4, y + 9, z + 6, new LuckyColorPicker().pickColor(), 0, 3);
        world.setBlock(x + 5, y + 9, z + 6, new LuckyColorPicker().pickColor(), 0, 3);
        world.setBlock(x + 6, y + 9, z + 6, new LuckyColorPicker().pickColor(), 0, 3);
        world.setBlock(x + 7, y + 9, z + 6, new LuckyColorPicker().pickColor(), 0, 3);
        world.setBlock(x + 8, y + 9, z + 6, new LuckyColorPicker().pickColor(), 0, 3);
        world.setBlock(x + 9, y + 9, z + 6, new LuckyColorPicker().pickColor(), 0, 3);
        world.setBlock(x + 0, y + 9, z + 7, new LuckyColorPicker().pickColor(), 0, 3);
        world.setBlock(x + 1, y + 9, z + 7, new LuckyColorPicker().pickColor(), 0, 3);
        world.setBlock(x + 2, y + 9, z + 7, new LuckyColorPicker().pickColor(), 0, 3);
        world.setBlock(x + 3, y + 9, z + 7, new LuckyColorPicker().pickColor(), 0, 3);
        world.setBlock(x + 4, y + 9, z + 7, new LuckyColorPicker().pickColor(), 0, 3);
        world.setBlock(x + 5, y + 9, z + 7, new LuckyColorPicker().pickColor(), 0, 3);
        world.setBlock(x + 6, y + 9, z + 7, new LuckyColorPicker().pickColor(), 0, 3);
        world.setBlock(x + 7, y + 9, z + 7, new LuckyColorPicker().pickColor(), 0, 3);
        world.setBlock(x + 8, y + 9, z + 7, new LuckyColorPicker().pickColor(), 0, 3);
        world.setBlock(x + 9, y + 9, z + 7, new LuckyColorPicker().pickColor(), 0, 3);
        world.setBlock(x + 0, y + 9, z + 8, new LuckyColorPicker().pickColor(), 0, 3);
        world.setBlock(x + 1, y + 9, z + 8, new LuckyColorPicker().pickColor(), 0, 3);
        world.setBlock(x + 2, y + 9, z + 8, new LuckyColorPicker().pickColor(), 0, 3);
        world.setBlock(x + 3, y + 9, z + 8, new LuckyColorPicker().pickColor(), 0, 3);
        world.setBlock(x + 4, y + 9, z + 8, new LuckyColorPicker().pickColor(), 0, 3);
        world.setBlock(x + 5, y + 9, z + 8, new LuckyColorPicker().pickColor(), 0, 3);
        world.setBlock(x + 6, y + 9, z + 8, new LuckyColorPicker().pickColor(), 0, 3);
        world.setBlock(x + 7, y + 9, z + 8, new LuckyColorPicker().pickColor(), 0, 3);
        world.setBlock(x + 8, y + 9, z + 8, new LuckyColorPicker().pickColor(), 0, 3);
        world.setBlock(x + 9, y + 9, z + 8, new LuckyColorPicker().pickColor(), 0, 3);
        world.setBlock(x + 0, y + 9, z + 9, new LuckyColorPicker().pickColor(), 0, 3);
        world.setBlock(x + 1, y + 9, z + 9, new LuckyColorPicker().pickColor(), 0, 3);
        world.setBlock(x + 2, y + 9, z + 9, new LuckyColorPicker().pickColor(), 0, 3);
        world.setBlock(x + 3, y + 9, z + 9, new LuckyColorPicker().pickColor(), 0, 3);
        world.setBlock(x + 4, y + 9, z + 9, new LuckyColorPicker().pickColor(), 0, 3);
        world.setBlock(x + 5, y + 9, z + 9, new LuckyColorPicker().pickColor(), 0, 3);
        world.setBlock(x + 6, y + 9, z + 9, new LuckyColorPicker().pickColor(), 0, 3);
        world.setBlock(x + 7, y + 9, z + 9, new LuckyColorPicker().pickColor(), 0, 3);
        world.setBlock(x + 8, y + 9, z + 9, new LuckyColorPicker().pickColor(), 0, 3);
        world.setBlock(x + 9, y + 9, z + 9, new LuckyColorPicker().pickColor(), 0, 3);

        //new 001_lucky_cube_5x5().generate_r00(world, rand, x, y, z);
    }
}
