package com.jtrent238.luckyblock.structures.traps;

import net.minecraft.entity.player.EntityPlayer;
import net.minecraft.init.Blocks;
import net.minecraft.world.World;

public class GoodLuckTrap {


	public static void createTrap(World p_149636_1_, EntityPlayer p_149636_2_) {

		int posX = (int) p_149636_2_.posX - 6;
		int posY = (int) p_149636_2_.posY - 1;
		int posZ = (int) p_149636_2_.posZ - 5;
		
		p_149636_1_.setBlock(posX + 0, posY + 0, posZ + 0, Blocks.bedrock, 0, 3);
		p_149636_1_.setBlock(posX + 1, posY + 0, posZ + 0, Blocks.bedrock, 0, 3);
		p_149636_1_.setBlock(posX + 2, posY + 0, posZ + 0, Blocks.bedrock, 0, 3);
		p_149636_1_.setBlock(posX + 3, posY + 0, posZ + 0, Blocks.bedrock, 0, 3);
		p_149636_1_.setBlock(posX + 4, posY + 0, posZ + 0, Blocks.bedrock, 0, 3);
		p_149636_1_.setBlock(posX + 5, posY + 0, posZ + 0, Blocks.bedrock, 0, 3);
		p_149636_1_.setBlock(posX + 6, posY + 0, posZ + 0, Blocks.bedrock, 0, 3);
		p_149636_1_.setBlock(posX + 7, posY + 0, posZ + 0, Blocks.bedrock, 0, 3);
		p_149636_1_.setBlock(posX + 8, posY + 0, posZ + 0, Blocks.bedrock, 0, 3);
		p_149636_1_.setBlock(posX + 9, posY + 0, posZ + 0, Blocks.bedrock, 0, 3);
		p_149636_1_.setBlock(posX + 0, posY + 0, posZ + 1, Blocks.bedrock, 0, 3);
		p_149636_1_.setBlock(posX + 1, posY + 0, posZ + 1, Blocks.bedrock, 0, 3);
		p_149636_1_.setBlock(posX + 2, posY + 0, posZ + 1, Blocks.bedrock, 0, 3);
		p_149636_1_.setBlock(posX + 3, posY + 0, posZ + 1, Blocks.bedrock, 0, 3);
		p_149636_1_.setBlock(posX + 4, posY + 0, posZ + 1, Blocks.bedrock, 0, 3);
		p_149636_1_.setBlock(posX + 5, posY + 0, posZ + 1, Blocks.bedrock, 0, 3);
		p_149636_1_.setBlock(posX + 6, posY + 0, posZ + 1, Blocks.bedrock, 0, 3);
		p_149636_1_.setBlock(posX + 7, posY + 0, posZ + 1, Blocks.bedrock, 0, 3);
		p_149636_1_.setBlock(posX + 8, posY + 0, posZ + 1, Blocks.bedrock, 0, 3);
		p_149636_1_.setBlock(posX + 9, posY + 0, posZ + 1, Blocks.bedrock, 0, 3);
		p_149636_1_.setBlock(posX + 0, posY + 0, posZ + 2, Blocks.bedrock, 0, 3);
		p_149636_1_.setBlock(posX + 1, posY + 0, posZ + 2, Blocks.bedrock, 0, 3);
		p_149636_1_.setBlock(posX + 2, posY + 0, posZ + 2, Blocks.bedrock, 0, 3);
		p_149636_1_.setBlock(posX + 3, posY + 0, posZ + 2, Blocks.bedrock, 0, 3);
		p_149636_1_.setBlock(posX + 4, posY + 0, posZ + 2, Blocks.bedrock, 0, 3);
		p_149636_1_.setBlock(posX + 5, posY + 0, posZ + 2, Blocks.bedrock, 0, 3);
		p_149636_1_.setBlock(posX + 6, posY + 0, posZ + 2, Blocks.bedrock, 0, 3);
		p_149636_1_.setBlock(posX + 7, posY + 0, posZ + 2, Blocks.bedrock, 0, 3);
		p_149636_1_.setBlock(posX + 8, posY + 0, posZ + 2, Blocks.bedrock, 0, 3);
		p_149636_1_.setBlock(posX + 9, posY + 0, posZ + 2, Blocks.bedrock, 0, 3);
		p_149636_1_.setBlock(posX + 0, posY + 0, posZ + 3, Blocks.bedrock, 0, 3);
		p_149636_1_.setBlock(posX + 1, posY + 0, posZ + 3, Blocks.bedrock, 0, 3);
		p_149636_1_.setBlock(posX + 2, posY + 0, posZ + 3, Blocks.bedrock, 0, 3);
		p_149636_1_.setBlock(posX + 3, posY + 0, posZ + 3, Blocks.bedrock, 0, 3);
		p_149636_1_.setBlock(posX + 4, posY + 0, posZ + 3, Blocks.bedrock, 0, 3);
		p_149636_1_.setBlock(posX + 5, posY + 0, posZ + 3, Blocks.bedrock, 0, 3);
		p_149636_1_.setBlock(posX + 6, posY + 0, posZ + 3, Blocks.bedrock, 0, 3);
		p_149636_1_.setBlock(posX + 7, posY + 0, posZ + 3, Blocks.bedrock, 0, 3);
		p_149636_1_.setBlock(posX + 8, posY + 0, posZ + 3, Blocks.bedrock, 0, 3);
		p_149636_1_.setBlock(posX + 9, posY + 0, posZ + 3, Blocks.bedrock, 0, 3);
		p_149636_1_.setBlock(posX + 0, posY + 0, posZ + 4, Blocks.bedrock, 0, 3);
		p_149636_1_.setBlock(posX + 1, posY + 0, posZ + 4, Blocks.bedrock, 0, 3);
		p_149636_1_.setBlock(posX + 2, posY + 0, posZ + 4, Blocks.bedrock, 0, 3);
		p_149636_1_.setBlock(posX + 3, posY + 0, posZ + 4, Blocks.bedrock, 0, 3);
		p_149636_1_.setBlock(posX + 4, posY + 0, posZ + 4, Blocks.bedrock, 0, 3);
		p_149636_1_.setBlock(posX + 5, posY + 0, posZ + 4, Blocks.bedrock, 0, 3);
		p_149636_1_.setBlock(posX + 6, posY + 0, posZ + 4, Blocks.bedrock, 0, 3);
		p_149636_1_.setBlock(posX + 7, posY + 0, posZ + 4, Blocks.bedrock, 0, 3);
		p_149636_1_.setBlock(posX + 8, posY + 0, posZ + 4, Blocks.bedrock, 0, 3);
		p_149636_1_.setBlock(posX + 9, posY + 0, posZ + 4, Blocks.bedrock, 0, 3);
		p_149636_1_.setBlock(posX + 0, posY + 0, posZ + 5, Blocks.bedrock, 0, 3);
		p_149636_1_.setBlock(posX + 1, posY + 0, posZ + 5, Blocks.bedrock, 0, 3);
		p_149636_1_.setBlock(posX + 2, posY + 0, posZ + 5, Blocks.bedrock, 0, 3);
		p_149636_1_.setBlock(posX + 3, posY + 0, posZ + 5, Blocks.bedrock, 0, 3);
		p_149636_1_.setBlock(posX + 4, posY + 0, posZ + 5, Blocks.bedrock, 0, 3);
		p_149636_1_.setBlock(posX + 5, posY + 0, posZ + 5, Blocks.bedrock, 0, 3);
		p_149636_1_.setBlock(posX + 6, posY + 0, posZ + 5, Blocks.bedrock, 0, 3);
		p_149636_1_.setBlock(posX + 7, posY + 0, posZ + 5, Blocks.bedrock, 0, 3);
		p_149636_1_.setBlock(posX + 8, posY + 0, posZ + 5, Blocks.bedrock, 0, 3);
		p_149636_1_.setBlock(posX + 9, posY + 0, posZ + 5, Blocks.bedrock, 0, 3);
		p_149636_1_.setBlock(posX + 0, posY + 0, posZ + 6, Blocks.bedrock, 0, 3);
		p_149636_1_.setBlock(posX + 1, posY + 0, posZ + 6, Blocks.bedrock, 0, 3);
		p_149636_1_.setBlock(posX + 2, posY + 0, posZ + 6, Blocks.bedrock, 0, 3);
		p_149636_1_.setBlock(posX + 3, posY + 0, posZ + 6, Blocks.bedrock, 0, 3);
		p_149636_1_.setBlock(posX + 4, posY + 0, posZ + 6, Blocks.bedrock, 0, 3);
		p_149636_1_.setBlock(posX + 5, posY + 0, posZ + 6, Blocks.bedrock, 0, 3);
		p_149636_1_.setBlock(posX + 6, posY + 0, posZ + 6, Blocks.bedrock, 0, 3);
		p_149636_1_.setBlock(posX + 7, posY + 0, posZ + 6, Blocks.bedrock, 0, 3);
		p_149636_1_.setBlock(posX + 8, posY + 0, posZ + 6, Blocks.bedrock, 0, 3);
		p_149636_1_.setBlock(posX + 9, posY + 0, posZ + 6, Blocks.bedrock, 0, 3);
		p_149636_1_.setBlock(posX + 0, posY + 0, posZ + 7, Blocks.bedrock, 0, 3);
		p_149636_1_.setBlock(posX + 1, posY + 0, posZ + 7, Blocks.bedrock, 0, 3);
		p_149636_1_.setBlock(posX + 2, posY + 0, posZ + 7, Blocks.bedrock, 0, 3);
		p_149636_1_.setBlock(posX + 3, posY + 0, posZ + 7, Blocks.bedrock, 0, 3);
		p_149636_1_.setBlock(posX + 4, posY + 0, posZ + 7, Blocks.bedrock, 0, 3);
		p_149636_1_.setBlock(posX + 5, posY + 0, posZ + 7, Blocks.bedrock, 0, 3);
		p_149636_1_.setBlock(posX + 6, posY + 0, posZ + 7, Blocks.bedrock, 0, 3);
		p_149636_1_.setBlock(posX + 7, posY + 0, posZ + 7, Blocks.bedrock, 0, 3);
		p_149636_1_.setBlock(posX + 8, posY + 0, posZ + 7, Blocks.bedrock, 0, 3);
		p_149636_1_.setBlock(posX + 9, posY + 0, posZ + 7, Blocks.bedrock, 0, 3);
		p_149636_1_.setBlock(posX + 0, posY + 0, posZ + 8, Blocks.bedrock, 0, 3);
		p_149636_1_.setBlock(posX + 1, posY + 0, posZ + 8, Blocks.bedrock, 0, 3);
		p_149636_1_.setBlock(posX + 2, posY + 0, posZ + 8, Blocks.bedrock, 0, 3);
		p_149636_1_.setBlock(posX + 3, posY + 0, posZ + 8, Blocks.bedrock, 0, 3);
		p_149636_1_.setBlock(posX + 4, posY + 0, posZ + 8, Blocks.bedrock, 0, 3);
		p_149636_1_.setBlock(posX + 5, posY + 0, posZ + 8, Blocks.bedrock, 0, 3);
		p_149636_1_.setBlock(posX + 6, posY + 0, posZ + 8, Blocks.bedrock, 0, 3);
		p_149636_1_.setBlock(posX + 7, posY + 0, posZ + 8, Blocks.bedrock, 0, 3);
		p_149636_1_.setBlock(posX + 8, posY + 0, posZ + 8, Blocks.bedrock, 0, 3);
		p_149636_1_.setBlock(posX + 9, posY + 0, posZ + 8, Blocks.bedrock, 0, 3);
		p_149636_1_.setBlock(posX + 0, posY + 0, posZ + 9, Blocks.bedrock, 0, 3);
		p_149636_1_.setBlock(posX + 1, posY + 0, posZ + 9, Blocks.bedrock, 0, 3);
		p_149636_1_.setBlock(posX + 2, posY + 0, posZ + 9, Blocks.bedrock, 0, 3);
		p_149636_1_.setBlock(posX + 3, posY + 0, posZ + 9, Blocks.bedrock, 0, 3);
		p_149636_1_.setBlock(posX + 4, posY + 0, posZ + 9, Blocks.bedrock, 0, 3);
		p_149636_1_.setBlock(posX + 5, posY + 0, posZ + 9, Blocks.bedrock, 0, 3);
		p_149636_1_.setBlock(posX + 6, posY + 0, posZ + 9, Blocks.bedrock, 0, 3);
		p_149636_1_.setBlock(posX + 7, posY + 0, posZ + 9, Blocks.bedrock, 0, 3);
		p_149636_1_.setBlock(posX + 8, posY + 0, posZ + 9, Blocks.bedrock, 0, 3);
		p_149636_1_.setBlock(posX + 9, posY + 0, posZ + 9, Blocks.bedrock, 0, 3);
		p_149636_1_.setBlock(posX + 0, posY + 1, posZ + 0, Blocks.bedrock, 0, 3);
		p_149636_1_.setBlock(posX + 1, posY + 1, posZ + 0, Blocks.bedrock, 0, 3);
		p_149636_1_.setBlock(posX + 2, posY + 1, posZ + 0, Blocks.bedrock, 0, 3);
		p_149636_1_.setBlock(posX + 3, posY + 1, posZ + 0, Blocks.bedrock, 0, 3);
		p_149636_1_.setBlock(posX + 4, posY + 1, posZ + 0, Blocks.bedrock, 0, 3);
		p_149636_1_.setBlock(posX + 5, posY + 1, posZ + 0, Blocks.bedrock, 0, 3);
		p_149636_1_.setBlock(posX + 6, posY + 1, posZ + 0, Blocks.bedrock, 0, 3);
		p_149636_1_.setBlock(posX + 7, posY + 1, posZ + 0, Blocks.bedrock, 0, 3);
		p_149636_1_.setBlock(posX + 8, posY + 1, posZ + 0, Blocks.bedrock, 0, 3);
		p_149636_1_.setBlock(posX + 9, posY + 1, posZ + 0, Blocks.bedrock, 0, 3);
		p_149636_1_.setBlock(posX + 0, posY + 1, posZ + 1, Blocks.bedrock, 0, 3);
		p_149636_1_.setBlock(posX + 1, posY + 1, posZ + 1, Blocks.lava, 8, 3);
		p_149636_1_.setBlock(posX + 2, posY + 1, posZ + 1, Blocks.bedrock, 0, 3);
		p_149636_1_.setBlock(posX + 3, posY + 1, posZ + 1, Blocks.nether_brick, 0, 3);
		p_149636_1_.setBlock(posX + 4, posY + 1, posZ + 1, Blocks.lava, 8, 3);
		p_149636_1_.setBlock(posX + 5, posY + 1, posZ + 1, Blocks.lava, 8, 3);
		p_149636_1_.setBlock(posX + 6, posY + 1, posZ + 1, Blocks.nether_brick, 0, 3);
		p_149636_1_.setBlock(posX + 7, posY + 1, posZ + 1, Blocks.bedrock, 0, 3);
		p_149636_1_.setBlock(posX + 8, posY + 1, posZ + 1, Blocks.lava, 8, 3);
		p_149636_1_.setBlock(posX + 9, posY + 1, posZ + 1, Blocks.bedrock, 0, 3);
		p_149636_1_.setBlock(posX + 0, posY + 1, posZ + 2, Blocks.bedrock, 0, 3);
		p_149636_1_.setBlock(posX + 1, posY + 1, posZ + 2, Blocks.bedrock, 0, 3);
		p_149636_1_.setBlock(posX + 2, posY + 1, posZ + 2, Blocks.lava, 8, 3);
		p_149636_1_.setBlock(posX + 3, posY + 1, posZ + 2, Blocks.double_stone_slab, 6, 3);
		p_149636_1_.setBlock(posX + 4, posY + 1, posZ + 2, Blocks.double_stone_slab, 6, 3);
		p_149636_1_.setBlock(posX + 5, posY + 1, posZ + 2, Blocks.double_stone_slab, 6, 3);
		p_149636_1_.setBlock(posX + 6, posY + 1, posZ + 2, Blocks.double_stone_slab, 6, 3);
		p_149636_1_.setBlock(posX + 7, posY + 1, posZ + 2, Blocks.lava, 8, 3);
		p_149636_1_.setBlock(posX + 8, posY + 1, posZ + 2, Blocks.bedrock, 0, 3);
		p_149636_1_.setBlock(posX + 9, posY + 1, posZ + 2, Blocks.bedrock, 0, 3);
		p_149636_1_.setBlock(posX + 0, posY + 1, posZ + 3, Blocks.bedrock, 0, 3);
		p_149636_1_.setBlock(posX + 1, posY + 1, posZ + 3, Blocks.nether_brick, 0, 3);
		p_149636_1_.setBlock(posX + 2, posY + 1, posZ + 3, Blocks.double_stone_slab, 6, 3);
		p_149636_1_.setBlock(posX + 3, posY + 1, posZ + 3, Blocks.double_stone_slab, 6, 3);
		p_149636_1_.setBlock(posX + 4, posY + 1, posZ + 3, Blocks.stone_slab, 6, 3);
		p_149636_1_.setBlock(posX + 5, posY + 1, posZ + 3, Blocks.stone_slab, 6, 3);
		p_149636_1_.setBlock(posX + 6, posY + 1, posZ + 3, Blocks.double_stone_slab, 6, 3);
		p_149636_1_.setBlock(posX + 7, posY + 1, posZ + 3, Blocks.double_stone_slab, 6, 3);
		p_149636_1_.setBlock(posX + 8, posY + 1, posZ + 3, Blocks.nether_brick, 0, 3);
		p_149636_1_.setBlock(posX + 9, posY + 1, posZ + 3, Blocks.bedrock, 0, 3);
		p_149636_1_.setBlock(posX + 0, posY + 1, posZ + 4, Blocks.bedrock, 0, 3);
		p_149636_1_.setBlock(posX + 1, posY + 1, posZ + 4, Blocks.lava, 8, 3);
		p_149636_1_.setBlock(posX + 2, posY + 1, posZ + 4, Blocks.double_stone_slab, 6, 3);
		p_149636_1_.setBlock(posX + 3, posY + 1, posZ + 4, Blocks.stone_slab, 6, 3);
		p_149636_1_.setBlock(posX + 4, posY + 1, posZ + 4, Blocks.stone_slab, 6, 3);
		p_149636_1_.setBlock(posX + 5, posY + 1, posZ + 4, Blocks.stone_slab, 6, 3);
		p_149636_1_.setBlock(posX + 6, posY + 1, posZ + 4, Blocks.stone_slab, 6, 3);
		p_149636_1_.setBlock(posX + 7, posY + 1, posZ + 4, Blocks.double_stone_slab, 6, 3);
		p_149636_1_.setBlock(posX + 8, posY + 1, posZ + 4, Blocks.lava, 8, 3);
		p_149636_1_.setBlock(posX + 9, posY + 1, posZ + 4, Blocks.bedrock, 0, 3);
		p_149636_1_.setBlock(posX + 0, posY + 1, posZ + 5, Blocks.bedrock, 0, 3);
		p_149636_1_.setBlock(posX + 1, posY + 1, posZ + 5, Blocks.lava, 8, 3);
		p_149636_1_.setBlock(posX + 2, posY + 1, posZ + 5, Blocks.double_stone_slab, 6, 3);
		p_149636_1_.setBlock(posX + 3, posY + 1, posZ + 5, Blocks.stone_slab, 6, 3);
		p_149636_1_.setBlock(posX + 4, posY + 1, posZ + 5, Blocks.stone_slab, 6, 3);
		p_149636_1_.setBlock(posX + 5, posY + 1, posZ + 5, Blocks.stone_slab, 6, 3);
		p_149636_1_.setBlock(posX + 6, posY + 1, posZ + 5, Blocks.stone_slab, 6, 3);
		p_149636_1_.setBlock(posX + 7, posY + 1, posZ + 5, Blocks.double_stone_slab, 6, 3);
		p_149636_1_.setBlock(posX + 8, posY + 1, posZ + 5, Blocks.lava, 8, 3);
		p_149636_1_.setBlock(posX + 9, posY + 1, posZ + 5, Blocks.bedrock, 0, 3);
		p_149636_1_.setBlock(posX + 0, posY + 1, posZ + 6, Blocks.bedrock, 0, 3);
		p_149636_1_.setBlock(posX + 1, posY + 1, posZ + 6, Blocks.nether_brick, 0, 3);
		p_149636_1_.setBlock(posX + 2, posY + 1, posZ + 6, Blocks.double_stone_slab, 6, 3);
		p_149636_1_.setBlock(posX + 3, posY + 1, posZ + 6, Blocks.double_stone_slab, 6, 3);
		p_149636_1_.setBlock(posX + 4, posY + 1, posZ + 6, Blocks.stone_slab, 6, 3);
		p_149636_1_.setBlock(posX + 5, posY + 1, posZ + 6, Blocks.stone_slab, 6, 3);
		p_149636_1_.setBlock(posX + 6, posY + 1, posZ + 6, Blocks.double_stone_slab, 6, 3);
		p_149636_1_.setBlock(posX + 7, posY + 1, posZ + 6, Blocks.double_stone_slab, 6, 3);
		p_149636_1_.setBlock(posX + 8, posY + 1, posZ + 6, Blocks.nether_brick, 0, 3);
		p_149636_1_.setBlock(posX + 9, posY + 1, posZ + 6, Blocks.bedrock, 0, 3);
		p_149636_1_.setBlock(posX + 0, posY + 1, posZ + 7, Blocks.bedrock, 0, 3);
		p_149636_1_.setBlock(posX + 1, posY + 1, posZ + 7, Blocks.bedrock, 0, 3);
		p_149636_1_.setBlock(posX + 2, posY + 1, posZ + 7, Blocks.lava, 8, 3);
		p_149636_1_.setBlock(posX + 3, posY + 1, posZ + 7, Blocks.double_stone_slab, 6, 3);
		p_149636_1_.setBlock(posX + 4, posY + 1, posZ + 7, Blocks.double_stone_slab, 6, 3);
		p_149636_1_.setBlock(posX + 5, posY + 1, posZ + 7, Blocks.double_stone_slab, 6, 3);
		p_149636_1_.setBlock(posX + 6, posY + 1, posZ + 7, Blocks.double_stone_slab, 6, 3);
		p_149636_1_.setBlock(posX + 7, posY + 1, posZ + 7, Blocks.lava, 8, 3);
		p_149636_1_.setBlock(posX + 8, posY + 1, posZ + 7, Blocks.bedrock, 0, 3);
		p_149636_1_.setBlock(posX + 9, posY + 1, posZ + 7, Blocks.bedrock, 0, 3);
		p_149636_1_.setBlock(posX + 0, posY + 1, posZ + 8, Blocks.bedrock, 0, 3);
		p_149636_1_.setBlock(posX + 1, posY + 1, posZ + 8, Blocks.lava, 8, 3);
		p_149636_1_.setBlock(posX + 2, posY + 1, posZ + 8, Blocks.bedrock, 0, 3);
		p_149636_1_.setBlock(posX + 3, posY + 1, posZ + 8, Blocks.nether_brick, 0, 3);
		p_149636_1_.setBlock(posX + 4, posY + 1, posZ + 8, Blocks.lava, 8, 3);
		p_149636_1_.setBlock(posX + 5, posY + 1, posZ + 8, Blocks.lava, 8, 3);
		p_149636_1_.setBlock(posX + 6, posY + 1, posZ + 8, Blocks.nether_brick, 0, 3);
		p_149636_1_.setBlock(posX + 7, posY + 1, posZ + 8, Blocks.bedrock, 0, 3);
		p_149636_1_.setBlock(posX + 8, posY + 1, posZ + 8, Blocks.lava, 8, 3);
		p_149636_1_.setBlock(posX + 9, posY + 1, posZ + 8, Blocks.bedrock, 0, 3);
		p_149636_1_.setBlock(posX + 0, posY + 1, posZ + 9, Blocks.bedrock, 0, 3);
		p_149636_1_.setBlock(posX + 1, posY + 1, posZ + 9, Blocks.bedrock, 0, 3);
		p_149636_1_.setBlock(posX + 2, posY + 1, posZ + 9, Blocks.bedrock, 0, 3);
		p_149636_1_.setBlock(posX + 3, posY + 1, posZ + 9, Blocks.bedrock, 0, 3);
		p_149636_1_.setBlock(posX + 4, posY + 1, posZ + 9, Blocks.bedrock, 0, 3);
		p_149636_1_.setBlock(posX + 5, posY + 1, posZ + 9, Blocks.bedrock, 0, 3);
		p_149636_1_.setBlock(posX + 6, posY + 1, posZ + 9, Blocks.bedrock, 0, 3);
		p_149636_1_.setBlock(posX + 7, posY + 1, posZ + 9, Blocks.bedrock, 0, 3);
		p_149636_1_.setBlock(posX + 8, posY + 1, posZ + 9, Blocks.bedrock, 0, 3);
		p_149636_1_.setBlock(posX + 9, posY + 1, posZ + 9, Blocks.bedrock, 0, 3);
		p_149636_1_.setBlock(posX + 0, posY + 2, posZ + 0, Blocks.bedrock, 0, 3);
		p_149636_1_.setBlock(posX + 1, posY + 2, posZ + 0, Blocks.bedrock, 0, 3);
		p_149636_1_.setBlock(posX + 2, posY + 2, posZ + 0, Blocks.bedrock, 0, 3);
		p_149636_1_.setBlock(posX + 3, posY + 2, posZ + 0, Blocks.bedrock, 0, 3);
		p_149636_1_.setBlock(posX + 4, posY + 2, posZ + 0, Blocks.bedrock, 0, 3);
		p_149636_1_.setBlock(posX + 5, posY + 2, posZ + 0, Blocks.bedrock, 0, 3);
		p_149636_1_.setBlock(posX + 6, posY + 2, posZ + 0, Blocks.bedrock, 0, 3);
		p_149636_1_.setBlock(posX + 7, posY + 2, posZ + 0, Blocks.bedrock, 0, 3);
		p_149636_1_.setBlock(posX + 8, posY + 2, posZ + 0, Blocks.bedrock, 0, 3);
		p_149636_1_.setBlock(posX + 9, posY + 2, posZ + 0, Blocks.bedrock, 0, 3);
		p_149636_1_.setBlock(posX + 0, posY + 2, posZ + 1, Blocks.bedrock, 0, 3);
		p_149636_1_.setBlock(posX + 1, posY + 2, posZ + 1, Blocks.lava, 8, 3);
		p_149636_1_.setBlock(posX + 2, posY + 2, posZ + 1, Blocks.nether_brick, 0, 3);
		p_149636_1_.setBlock(posX + 3, posY + 2, posZ + 1, Blocks.nether_brick, 0, 3);
		p_149636_1_.setBlock(posX + 4, posY + 2, posZ + 1, Blocks.lava, 8, 3);
		p_149636_1_.setBlock(posX + 5, posY + 2, posZ + 1, Blocks.lava, 8, 3);
		p_149636_1_.setBlock(posX + 6, posY + 2, posZ + 1, Blocks.nether_brick, 0, 3);
		p_149636_1_.setBlock(posX + 7, posY + 2, posZ + 1, Blocks.nether_brick, 0, 3);
		p_149636_1_.setBlock(posX + 8, posY + 2, posZ + 1, Blocks.lava, 8, 3);
		p_149636_1_.setBlock(posX + 9, posY + 2, posZ + 1, Blocks.bedrock, 0, 3);
		p_149636_1_.setBlock(posX + 0, posY + 2, posZ + 2, Blocks.bedrock, 0, 3);
		p_149636_1_.setBlock(posX + 1, posY + 2, posZ + 2, Blocks.nether_brick, 0, 3);
		p_149636_1_.setBlock(posX + 2, posY + 2, posZ + 2, Blocks.lava, 8, 3);
		p_149636_1_.setBlock(posX + 3, posY + 2, posZ + 2, Blocks.stone_slab, 6, 3);
		p_149636_1_.setBlock(posX + 4, posY + 2, posZ + 2, Blocks.air, 0, 3);
		p_149636_1_.setBlock(posX + 5, posY + 2, posZ + 2, Blocks.air, 0, 3);
		p_149636_1_.setBlock(posX + 6, posY + 2, posZ + 2, Blocks.stone_slab, 6, 3);
		p_149636_1_.setBlock(posX + 7, posY + 2, posZ + 2, Blocks.lava, 8, 3);
		p_149636_1_.setBlock(posX + 8, posY + 2, posZ + 2, Blocks.nether_brick, 0, 3);
		p_149636_1_.setBlock(posX + 9, posY + 2, posZ + 2, Blocks.bedrock, 0, 3);
		p_149636_1_.setBlock(posX + 0, posY + 2, posZ + 3, Blocks.bedrock, 0, 3);
		p_149636_1_.setBlock(posX + 1, posY + 2, posZ + 3, Blocks.nether_brick, 0, 3);
		p_149636_1_.setBlock(posX + 2, posY + 2, posZ + 3, Blocks.stone_slab, 6, 3);
		p_149636_1_.setBlock(posX + 3, posY + 2, posZ + 3, Blocks.air, 0, 3);
		p_149636_1_.setBlock(posX + 4, posY + 2, posZ + 3, Blocks.air, 0, 3);
		p_149636_1_.setBlock(posX + 5, posY + 2, posZ + 3, Blocks.air, 0, 3);
		p_149636_1_.setBlock(posX + 6, posY + 2, posZ + 3, Blocks.air, 0, 3);
		p_149636_1_.setBlock(posX + 7, posY + 2, posZ + 3, Blocks.stone_slab, 6, 3);
		p_149636_1_.setBlock(posX + 8, posY + 2, posZ + 3, Blocks.nether_brick, 0, 3);
		p_149636_1_.setBlock(posX + 9, posY + 2, posZ + 3, Blocks.bedrock, 0, 3);
		p_149636_1_.setBlock(posX + 0, posY + 2, posZ + 4, Blocks.bedrock, 0, 3);
		p_149636_1_.setBlock(posX + 1, posY + 2, posZ + 4, Blocks.lava, 8, 3);
		p_149636_1_.setBlock(posX + 2, posY + 2, posZ + 4, Blocks.air, 0, 3);
		p_149636_1_.setBlock(posX + 3, posY + 2, posZ + 4, Blocks.air, 0, 3);
		p_149636_1_.setBlock(posX + 4, posY + 2, posZ + 4, Blocks.air, 0, 3);
		p_149636_1_.setBlock(posX + 5, posY + 2, posZ + 4, Blocks.air, 0, 3);
		p_149636_1_.setBlock(posX + 6, posY + 2, posZ + 4, Blocks.air, 0, 3);
		p_149636_1_.setBlock(posX + 7, posY + 2, posZ + 4, Blocks.air, 0, 3);
		p_149636_1_.setBlock(posX + 8, posY + 2, posZ + 4, Blocks.lava, 8, 3);
		p_149636_1_.setBlock(posX + 9, posY + 2, posZ + 4, Blocks.bedrock, 0, 3);
		p_149636_1_.setBlock(posX + 0, posY + 2, posZ + 5, Blocks.bedrock, 0, 3);
		p_149636_1_.setBlock(posX + 1, posY + 2, posZ + 5, Blocks.lava, 8, 3);
		p_149636_1_.setBlock(posX + 2, posY + 2, posZ + 5, Blocks.air, 0, 3);
		p_149636_1_.setBlock(posX + 3, posY + 2, posZ + 5, Blocks.air, 0, 3);
		p_149636_1_.setBlock(posX + 4, posY + 2, posZ + 5, Blocks.air, 0, 3);
		p_149636_1_.setBlock(posX + 5, posY + 2, posZ + 5, Blocks.air, 0, 3);
		p_149636_1_.setBlock(posX + 6, posY + 2, posZ + 5, Blocks.air, 0, 3);
		p_149636_1_.setBlock(posX + 7, posY + 2, posZ + 5, Blocks.air, 0, 3);
		p_149636_1_.setBlock(posX + 8, posY + 2, posZ + 5, Blocks.lava, 8, 3);
		p_149636_1_.setBlock(posX + 9, posY + 2, posZ + 5, Blocks.bedrock, 0, 3);
		p_149636_1_.setBlock(posX + 0, posY + 2, posZ + 6, Blocks.bedrock, 0, 3);
		p_149636_1_.setBlock(posX + 1, posY + 2, posZ + 6, Blocks.nether_brick, 0, 3);
		p_149636_1_.setBlock(posX + 2, posY + 2, posZ + 6, Blocks.stone_slab, 6, 3);
		p_149636_1_.setBlock(posX + 3, posY + 2, posZ + 6, Blocks.air, 0, 3);
		p_149636_1_.setBlock(posX + 4, posY + 2, posZ + 6, Blocks.air, 0, 3);
		p_149636_1_.setBlock(posX + 5, posY + 2, posZ + 6, Blocks.air, 0, 3);
		p_149636_1_.setBlock(posX + 6, posY + 2, posZ + 6, Blocks.air, 0, 3);
		p_149636_1_.setBlock(posX + 7, posY + 2, posZ + 6, Blocks.stone_slab, 6, 3);
		p_149636_1_.setBlock(posX + 8, posY + 2, posZ + 6, Blocks.nether_brick, 0, 3);
		p_149636_1_.setBlock(posX + 9, posY + 2, posZ + 6, Blocks.bedrock, 0, 3);
		p_149636_1_.setBlock(posX + 0, posY + 2, posZ + 7, Blocks.bedrock, 0, 3);
		p_149636_1_.setBlock(posX + 1, posY + 2, posZ + 7, Blocks.nether_brick, 0, 3);
		p_149636_1_.setBlock(posX + 2, posY + 2, posZ + 7, Blocks.lava, 8, 3);
		p_149636_1_.setBlock(posX + 3, posY + 2, posZ + 7, Blocks.stone_slab, 6, 3);
		p_149636_1_.setBlock(posX + 4, posY + 2, posZ + 7, Blocks.air, 0, 3);
		p_149636_1_.setBlock(posX + 5, posY + 2, posZ + 7, Blocks.air, 0, 3);
		p_149636_1_.setBlock(posX + 6, posY + 2, posZ + 7, Blocks.stone_slab, 6, 3);
		p_149636_1_.setBlock(posX + 7, posY + 2, posZ + 7, Blocks.lava, 8, 3);
		p_149636_1_.setBlock(posX + 8, posY + 2, posZ + 7, Blocks.nether_brick, 0, 3);
		p_149636_1_.setBlock(posX + 9, posY + 2, posZ + 7, Blocks.bedrock, 0, 3);
		p_149636_1_.setBlock(posX + 0, posY + 2, posZ + 8, Blocks.bedrock, 0, 3);
		p_149636_1_.setBlock(posX + 1, posY + 2, posZ + 8, Blocks.lava, 8, 3);
		p_149636_1_.setBlock(posX + 2, posY + 2, posZ + 8, Blocks.nether_brick, 0, 3);
		p_149636_1_.setBlock(posX + 3, posY + 2, posZ + 8, Blocks.nether_brick, 0, 3);
		p_149636_1_.setBlock(posX + 4, posY + 2, posZ + 8, Blocks.lava, 8, 3);
		p_149636_1_.setBlock(posX + 5, posY + 2, posZ + 8, Blocks.lava, 8, 3);
		p_149636_1_.setBlock(posX + 6, posY + 2, posZ + 8, Blocks.nether_brick, 0, 3);
		p_149636_1_.setBlock(posX + 7, posY + 2, posZ + 8, Blocks.nether_brick, 0, 3);
		p_149636_1_.setBlock(posX + 8, posY + 2, posZ + 8, Blocks.lava, 8, 3);
		p_149636_1_.setBlock(posX + 9, posY + 2, posZ + 8, Blocks.bedrock, 0, 3);
		p_149636_1_.setBlock(posX + 0, posY + 2, posZ + 9, Blocks.bedrock, 0, 3);
		p_149636_1_.setBlock(posX + 1, posY + 2, posZ + 9, Blocks.bedrock, 0, 3);
		p_149636_1_.setBlock(posX + 2, posY + 2, posZ + 9, Blocks.bedrock, 0, 3);
		p_149636_1_.setBlock(posX + 3, posY + 2, posZ + 9, Blocks.bedrock, 0, 3);
		p_149636_1_.setBlock(posX + 4, posY + 2, posZ + 9, Blocks.bedrock, 0, 3);
		p_149636_1_.setBlock(posX + 5, posY + 2, posZ + 9, Blocks.bedrock, 0, 3);
		p_149636_1_.setBlock(posX + 6, posY + 2, posZ + 9, Blocks.bedrock, 0, 3);
		p_149636_1_.setBlock(posX + 7, posY + 2, posZ + 9, Blocks.bedrock, 0, 3);
		p_149636_1_.setBlock(posX + 8, posY + 2, posZ + 9, Blocks.bedrock, 0, 3);
		p_149636_1_.setBlock(posX + 9, posY + 2, posZ + 9, Blocks.bedrock, 0, 3);
		p_149636_1_.setBlock(posX + 0, posY + 3, posZ + 0, Blocks.bedrock, 0, 3);
		p_149636_1_.setBlock(posX + 1, posY + 3, posZ + 0, Blocks.bedrock, 0, 3);
		p_149636_1_.setBlock(posX + 2, posY + 3, posZ + 0, Blocks.bedrock, 0, 3);
		p_149636_1_.setBlock(posX + 3, posY + 3, posZ + 0, Blocks.bedrock, 0, 3);
		p_149636_1_.setBlock(posX + 4, posY + 3, posZ + 0, Blocks.bedrock, 0, 3);
		p_149636_1_.setBlock(posX + 5, posY + 3, posZ + 0, Blocks.bedrock, 0, 3);
		p_149636_1_.setBlock(posX + 6, posY + 3, posZ + 0, Blocks.bedrock, 0, 3);
		p_149636_1_.setBlock(posX + 7, posY + 3, posZ + 0, Blocks.bedrock, 0, 3);
		p_149636_1_.setBlock(posX + 8, posY + 3, posZ + 0, Blocks.bedrock, 0, 3);
		p_149636_1_.setBlock(posX + 9, posY + 3, posZ + 0, Blocks.bedrock, 0, 3);
		p_149636_1_.setBlock(posX + 0, posY + 3, posZ + 1, Blocks.bedrock, 0, 3);
		p_149636_1_.setBlock(posX + 1, posY + 3, posZ + 1, Blocks.lava, 8, 3);
		p_149636_1_.setBlock(posX + 2, posY + 3, posZ + 1, Blocks.nether_brick, 0, 3);
		p_149636_1_.setBlock(posX + 3, posY + 3, posZ + 1, Blocks.nether_brick, 0, 3);
		p_149636_1_.setBlock(posX + 4, posY + 3, posZ + 1, Blocks.lava, 8, 3);
		p_149636_1_.setBlock(posX + 5, posY + 3, posZ + 1, Blocks.lava, 8, 3);
		p_149636_1_.setBlock(posX + 6, posY + 3, posZ + 1, Blocks.nether_brick, 0, 3);
		p_149636_1_.setBlock(posX + 7, posY + 3, posZ + 1, Blocks.nether_brick, 0, 3);
		p_149636_1_.setBlock(posX + 8, posY + 3, posZ + 1, Blocks.lava, 8, 3);
		p_149636_1_.setBlock(posX + 9, posY + 3, posZ + 1, Blocks.bedrock, 0, 3);
		p_149636_1_.setBlock(posX + 0, posY + 3, posZ + 2, Blocks.bedrock, 0, 3);
		p_149636_1_.setBlock(posX + 1, posY + 3, posZ + 2, Blocks.nether_brick, 0, 3);
		p_149636_1_.setBlock(posX + 2, posY + 3, posZ + 2, Blocks.lava, 8, 3);
		p_149636_1_.setBlock(posX + 3, posY + 3, posZ + 2, Blocks.air, 0, 3);
		p_149636_1_.setBlock(posX + 4, posY + 3, posZ + 2, Blocks.air, 0, 3);
		p_149636_1_.setBlock(posX + 5, posY + 3, posZ + 2, Blocks.air, 0, 3);
		p_149636_1_.setBlock(posX + 6, posY + 3, posZ + 2, Blocks.air, 0, 3);
		p_149636_1_.setBlock(posX + 7, posY + 3, posZ + 2, Blocks.lava, 8, 3);
		p_149636_1_.setBlock(posX + 8, posY + 3, posZ + 2, Blocks.nether_brick, 0, 3);
		p_149636_1_.setBlock(posX + 9, posY + 3, posZ + 2, Blocks.bedrock, 0, 3);
		p_149636_1_.setBlock(posX + 0, posY + 3, posZ + 3, Blocks.bedrock, 0, 3);
		p_149636_1_.setBlock(posX + 1, posY + 3, posZ + 3, Blocks.nether_brick, 0, 3);
		p_149636_1_.setBlock(posX + 2, posY + 3, posZ + 3, Blocks.air, 0, 3);
		p_149636_1_.setBlock(posX + 3, posY + 3, posZ + 3, Blocks.air, 0, 3);
		p_149636_1_.setBlock(posX + 4, posY + 3, posZ + 3, Blocks.air, 0, 3);
		p_149636_1_.setBlock(posX + 5, posY + 3, posZ + 3, Blocks.air, 0, 3);
		p_149636_1_.setBlock(posX + 6, posY + 3, posZ + 3, Blocks.air, 0, 3);
		p_149636_1_.setBlock(posX + 7, posY + 3, posZ + 3, Blocks.air, 0, 3);
		p_149636_1_.setBlock(posX + 8, posY + 3, posZ + 3, Blocks.nether_brick, 0, 3);
		p_149636_1_.setBlock(posX + 9, posY + 3, posZ + 3, Blocks.bedrock, 0, 3);
		p_149636_1_.setBlock(posX + 0, posY + 3, posZ + 4, Blocks.bedrock, 0, 3);
		p_149636_1_.setBlock(posX + 1, posY + 3, posZ + 4, Blocks.lava, 8, 3);
		p_149636_1_.setBlock(posX + 2, posY + 3, posZ + 4, Blocks.air, 0, 3);
		p_149636_1_.setBlock(posX + 3, posY + 3, posZ + 4, Blocks.air, 0, 3);
		p_149636_1_.setBlock(posX + 4, posY + 3, posZ + 4, Blocks.air, 0, 3);
		p_149636_1_.setBlock(posX + 5, posY + 3, posZ + 4, Blocks.air, 0, 3);
		p_149636_1_.setBlock(posX + 6, posY + 3, posZ + 4, Blocks.air, 0, 3);
		p_149636_1_.setBlock(posX + 7, posY + 3, posZ + 4, Blocks.air, 0, 3);
		p_149636_1_.setBlock(posX + 8, posY + 3, posZ + 4, Blocks.lava, 8, 3);
		p_149636_1_.setBlock(posX + 9, posY + 3, posZ + 4, Blocks.bedrock, 0, 3);
		p_149636_1_.setBlock(posX + 0, posY + 3, posZ + 5, Blocks.bedrock, 0, 3);
		p_149636_1_.setBlock(posX + 1, posY + 3, posZ + 5, Blocks.lava, 8, 3);
		p_149636_1_.setBlock(posX + 2, posY + 3, posZ + 5, Blocks.air, 0, 3);
		p_149636_1_.setBlock(posX + 3, posY + 3, posZ + 5, Blocks.air, 0, 3);
		p_149636_1_.setBlock(posX + 4, posY + 3, posZ + 5, Blocks.air, 0, 3);
		p_149636_1_.setBlock(posX + 5, posY + 3, posZ + 5, Blocks.air, 0, 3);
		p_149636_1_.setBlock(posX + 6, posY + 3, posZ + 5, Blocks.air, 0, 3);
		p_149636_1_.setBlock(posX + 7, posY + 3, posZ + 5, Blocks.air, 0, 3);
		p_149636_1_.setBlock(posX + 8, posY + 3, posZ + 5, Blocks.lava, 8, 3);
		p_149636_1_.setBlock(posX + 9, posY + 3, posZ + 5, Blocks.bedrock, 0, 3);
		p_149636_1_.setBlock(posX + 0, posY + 3, posZ + 6, Blocks.bedrock, 0, 3);
		p_149636_1_.setBlock(posX + 1, posY + 3, posZ + 6, Blocks.nether_brick, 0, 3);
		p_149636_1_.setBlock(posX + 2, posY + 3, posZ + 6, Blocks.air, 0, 3);
		p_149636_1_.setBlock(posX + 3, posY + 3, posZ + 6, Blocks.air, 0, 3);
		p_149636_1_.setBlock(posX + 4, posY + 3, posZ + 6, Blocks.air, 0, 3);
		p_149636_1_.setBlock(posX + 5, posY + 3, posZ + 6, Blocks.air, 0, 3);
		p_149636_1_.setBlock(posX + 6, posY + 3, posZ + 6, Blocks.air, 0, 3);
		p_149636_1_.setBlock(posX + 7, posY + 3, posZ + 6, Blocks.air, 0, 3);
		p_149636_1_.setBlock(posX + 8, posY + 3, posZ + 6, Blocks.nether_brick, 0, 3);
		p_149636_1_.setBlock(posX + 9, posY + 3, posZ + 6, Blocks.bedrock, 0, 3);
		p_149636_1_.setBlock(posX + 0, posY + 3, posZ + 7, Blocks.bedrock, 0, 3);
		p_149636_1_.setBlock(posX + 1, posY + 3, posZ + 7, Blocks.nether_brick, 0, 3);
		p_149636_1_.setBlock(posX + 2, posY + 3, posZ + 7, Blocks.lava, 8, 3);
		p_149636_1_.setBlock(posX + 3, posY + 3, posZ + 7, Blocks.air, 0, 3);
		p_149636_1_.setBlock(posX + 4, posY + 3, posZ + 7, Blocks.air, 0, 3);
		p_149636_1_.setBlock(posX + 5, posY + 3, posZ + 7, Blocks.air, 0, 3);
		p_149636_1_.setBlock(posX + 6, posY + 3, posZ + 7, Blocks.air, 0, 3);
		p_149636_1_.setBlock(posX + 7, posY + 3, posZ + 7, Blocks.lava, 8, 3);
		p_149636_1_.setBlock(posX + 8, posY + 3, posZ + 7, Blocks.nether_brick, 0, 3);
		p_149636_1_.setBlock(posX + 9, posY + 3, posZ + 7, Blocks.bedrock, 0, 3);
		p_149636_1_.setBlock(posX + 0, posY + 3, posZ + 8, Blocks.bedrock, 0, 3);
		p_149636_1_.setBlock(posX + 1, posY + 3, posZ + 8, Blocks.lava, 8, 3);
		p_149636_1_.setBlock(posX + 2, posY + 3, posZ + 8, Blocks.nether_brick, 0, 3);
		p_149636_1_.setBlock(posX + 3, posY + 3, posZ + 8, Blocks.nether_brick, 0, 3);
		p_149636_1_.setBlock(posX + 4, posY + 3, posZ + 8, Blocks.lava, 8, 3);
		p_149636_1_.setBlock(posX + 5, posY + 3, posZ + 8, Blocks.lava, 8, 3);
		p_149636_1_.setBlock(posX + 6, posY + 3, posZ + 8, Blocks.nether_brick, 0, 3);
		p_149636_1_.setBlock(posX + 7, posY + 3, posZ + 8, Blocks.nether_brick, 0, 3);
		p_149636_1_.setBlock(posX + 8, posY + 3, posZ + 8, Blocks.lava, 8, 3);
		p_149636_1_.setBlock(posX + 9, posY + 3, posZ + 8, Blocks.bedrock, 0, 3);
		p_149636_1_.setBlock(posX + 0, posY + 3, posZ + 9, Blocks.bedrock, 0, 3);
		p_149636_1_.setBlock(posX + 1, posY + 3, posZ + 9, Blocks.bedrock, 0, 3);
		p_149636_1_.setBlock(posX + 2, posY + 3, posZ + 9, Blocks.bedrock, 0, 3);
		p_149636_1_.setBlock(posX + 3, posY + 3, posZ + 9, Blocks.bedrock, 0, 3);
		p_149636_1_.setBlock(posX + 4, posY + 3, posZ + 9, Blocks.bedrock, 0, 3);
		p_149636_1_.setBlock(posX + 5, posY + 3, posZ + 9, Blocks.bedrock, 0, 3);
		p_149636_1_.setBlock(posX + 6, posY + 3, posZ + 9, Blocks.bedrock, 0, 3);
		p_149636_1_.setBlock(posX + 7, posY + 3, posZ + 9, Blocks.bedrock, 0, 3);
		p_149636_1_.setBlock(posX + 8, posY + 3, posZ + 9, Blocks.bedrock, 0, 3);
		p_149636_1_.setBlock(posX + 9, posY + 3, posZ + 9, Blocks.bedrock, 0, 3);
		p_149636_1_.setBlock(posX + 0, posY + 4, posZ + 0, Blocks.bedrock, 0, 3);
		p_149636_1_.setBlock(posX + 1, posY + 4, posZ + 0, Blocks.bedrock, 0, 3);
		p_149636_1_.setBlock(posX + 2, posY + 4, posZ + 0, Blocks.bedrock, 0, 3);
		p_149636_1_.setBlock(posX + 3, posY + 4, posZ + 0, Blocks.bedrock, 0, 3);
		p_149636_1_.setBlock(posX + 4, posY + 4, posZ + 0, Blocks.bedrock, 0, 3);
		p_149636_1_.setBlock(posX + 5, posY + 4, posZ + 0, Blocks.bedrock, 0, 3);
		p_149636_1_.setBlock(posX + 6, posY + 4, posZ + 0, Blocks.bedrock, 0, 3);
		p_149636_1_.setBlock(posX + 7, posY + 4, posZ + 0, Blocks.bedrock, 0, 3);
		p_149636_1_.setBlock(posX + 8, posY + 4, posZ + 0, Blocks.bedrock, 0, 3);
		p_149636_1_.setBlock(posX + 9, posY + 4, posZ + 0, Blocks.bedrock, 0, 3);
		p_149636_1_.setBlock(posX + 0, posY + 4, posZ + 1, Blocks.bedrock, 0, 3);
		p_149636_1_.setBlock(posX + 1, posY + 4, posZ + 1, Blocks.lava, 8, 3);
		p_149636_1_.setBlock(posX + 2, posY + 4, posZ + 1, Blocks.nether_brick, 0, 3);
		p_149636_1_.setBlock(posX + 3, posY + 4, posZ + 1, Blocks.nether_brick, 0, 3);
		p_149636_1_.setBlock(posX + 4, posY + 4, posZ + 1, Blocks.lava, 8, 3);
		p_149636_1_.setBlock(posX + 5, posY + 4, posZ + 1, Blocks.lava, 8, 3);
		p_149636_1_.setBlock(posX + 6, posY + 4, posZ + 1, Blocks.nether_brick, 0, 3);
		p_149636_1_.setBlock(posX + 7, posY + 4, posZ + 1, Blocks.nether_brick, 0, 3);
		p_149636_1_.setBlock(posX + 8, posY + 4, posZ + 1, Blocks.lava, 8, 3);
		p_149636_1_.setBlock(posX + 9, posY + 4, posZ + 1, Blocks.bedrock, 0, 3);
		p_149636_1_.setBlock(posX + 0, posY + 4, posZ + 2, Blocks.bedrock, 0, 3);
		p_149636_1_.setBlock(posX + 1, posY + 4, posZ + 2, Blocks.nether_brick, 0, 3);
		p_149636_1_.setBlock(posX + 2, posY + 4, posZ + 2, Blocks.lava, 8, 3);
		p_149636_1_.setBlock(posX + 3, posY + 4, posZ + 2, Blocks.air, 0, 3);
		p_149636_1_.setBlock(posX + 4, posY + 4, posZ + 2, Blocks.air, 0, 3);
		p_149636_1_.setBlock(posX + 5, posY + 4, posZ + 2, Blocks.air, 0, 3);
		p_149636_1_.setBlock(posX + 6, posY + 4, posZ + 2, Blocks.air, 0, 3);
		p_149636_1_.setBlock(posX + 7, posY + 4, posZ + 2, Blocks.lava, 8, 3);
		p_149636_1_.setBlock(posX + 8, posY + 4, posZ + 2, Blocks.nether_brick, 0, 3);
		p_149636_1_.setBlock(posX + 9, posY + 4, posZ + 2, Blocks.bedrock, 0, 3);
		p_149636_1_.setBlock(posX + 0, posY + 4, posZ + 3, Blocks.bedrock, 0, 3);
		p_149636_1_.setBlock(posX + 1, posY + 4, posZ + 3, Blocks.nether_brick, 0, 3);
		p_149636_1_.setBlock(posX + 2, posY + 4, posZ + 3, Blocks.air, 0, 3);
		p_149636_1_.setBlock(posX + 3, posY + 4, posZ + 3, Blocks.air, 0, 3);
		p_149636_1_.setBlock(posX + 4, posY + 4, posZ + 3, Blocks.air, 0, 3);
		p_149636_1_.setBlock(posX + 5, posY + 4, posZ + 3, Blocks.air, 0, 3);
		p_149636_1_.setBlock(posX + 6, posY + 4, posZ + 3, Blocks.air, 0, 3);
		p_149636_1_.setBlock(posX + 7, posY + 4, posZ + 3, Blocks.air, 0, 3);
		p_149636_1_.setBlock(posX + 8, posY + 4, posZ + 3, Blocks.nether_brick, 0, 3);
		p_149636_1_.setBlock(posX + 9, posY + 4, posZ + 3, Blocks.bedrock, 0, 3);
		p_149636_1_.setBlock(posX + 0, posY + 4, posZ + 4, Blocks.bedrock, 0, 3);
		p_149636_1_.setBlock(posX + 1, posY + 4, posZ + 4, Blocks.lava, 8, 3);
		p_149636_1_.setBlock(posX + 2, posY + 4, posZ + 4, Blocks.air, 0, 3);
		p_149636_1_.setBlock(posX + 3, posY + 4, posZ + 4, Blocks.air, 0, 3);
		p_149636_1_.setBlock(posX + 4, posY + 4, posZ + 4, Blocks.air, 0, 3);
		p_149636_1_.setBlock(posX + 5, posY + 4, posZ + 4, Blocks.air, 0, 3);
		p_149636_1_.setBlock(posX + 6, posY + 4, posZ + 4, Blocks.air, 0, 3);
		p_149636_1_.setBlock(posX + 7, posY + 4, posZ + 4, Blocks.air, 0, 3);
		p_149636_1_.setBlock(posX + 8, posY + 4, posZ + 4, Blocks.lava, 8, 3);
		p_149636_1_.setBlock(posX + 9, posY + 4, posZ + 4, Blocks.bedrock, 0, 3);
		p_149636_1_.setBlock(posX + 0, posY + 4, posZ + 5, Blocks.bedrock, 0, 3);
		p_149636_1_.setBlock(posX + 1, posY + 4, posZ + 5, Blocks.lava, 8, 3);
		p_149636_1_.setBlock(posX + 2, posY + 4, posZ + 5, Blocks.air, 0, 3);
		p_149636_1_.setBlock(posX + 3, posY + 4, posZ + 5, Blocks.air, 0, 3);
		p_149636_1_.setBlock(posX + 4, posY + 4, posZ + 5, Blocks.air, 0, 3);
		p_149636_1_.setBlock(posX + 5, posY + 4, posZ + 5, Blocks.air, 0, 3);
		p_149636_1_.setBlock(posX + 6, posY + 4, posZ + 5, Blocks.air, 0, 3);
		p_149636_1_.setBlock(posX + 7, posY + 4, posZ + 5, Blocks.air, 0, 3);
		p_149636_1_.setBlock(posX + 8, posY + 4, posZ + 5, Blocks.lava, 8, 3);
		p_149636_1_.setBlock(posX + 9, posY + 4, posZ + 5, Blocks.bedrock, 0, 3);
		p_149636_1_.setBlock(posX + 0, posY + 4, posZ + 6, Blocks.bedrock, 0, 3);
		p_149636_1_.setBlock(posX + 1, posY + 4, posZ + 6, Blocks.nether_brick, 0, 3);
		p_149636_1_.setBlock(posX + 2, posY + 4, posZ + 6, Blocks.air, 0, 3);
		p_149636_1_.setBlock(posX + 3, posY + 4, posZ + 6, Blocks.air, 0, 3);
		p_149636_1_.setBlock(posX + 4, posY + 4, posZ + 6, Blocks.air, 0, 3);
		p_149636_1_.setBlock(posX + 5, posY + 4, posZ + 6, Blocks.air, 0, 3);
		p_149636_1_.setBlock(posX + 6, posY + 4, posZ + 6, Blocks.air, 0, 3);
		p_149636_1_.setBlock(posX + 7, posY + 4, posZ + 6, Blocks.air, 0, 3);
		p_149636_1_.setBlock(posX + 8, posY + 4, posZ + 6, Blocks.nether_brick, 0, 3);
		p_149636_1_.setBlock(posX + 9, posY + 4, posZ + 6, Blocks.bedrock, 0, 3);
		p_149636_1_.setBlock(posX + 0, posY + 4, posZ + 7, Blocks.bedrock, 0, 3);
		p_149636_1_.setBlock(posX + 1, posY + 4, posZ + 7, Blocks.nether_brick, 0, 3);
		p_149636_1_.setBlock(posX + 2, posY + 4, posZ + 7, Blocks.lava, 8, 3);
		p_149636_1_.setBlock(posX + 3, posY + 4, posZ + 7, Blocks.air, 0, 3);
		p_149636_1_.setBlock(posX + 4, posY + 4, posZ + 7, Blocks.air, 0, 3);
		p_149636_1_.setBlock(posX + 5, posY + 4, posZ + 7, Blocks.air, 0, 3);
		p_149636_1_.setBlock(posX + 6, posY + 4, posZ + 7, Blocks.air, 0, 3);
		p_149636_1_.setBlock(posX + 7, posY + 4, posZ + 7, Blocks.lava, 8, 3);
		p_149636_1_.setBlock(posX + 8, posY + 4, posZ + 7, Blocks.nether_brick, 0, 3);
		p_149636_1_.setBlock(posX + 9, posY + 4, posZ + 7, Blocks.bedrock, 0, 3);
		p_149636_1_.setBlock(posX + 0, posY + 4, posZ + 8, Blocks.bedrock, 0, 3);
		p_149636_1_.setBlock(posX + 1, posY + 4, posZ + 8, Blocks.lava, 8, 3);
		p_149636_1_.setBlock(posX + 2, posY + 4, posZ + 8, Blocks.nether_brick, 0, 3);
		p_149636_1_.setBlock(posX + 3, posY + 4, posZ + 8, Blocks.nether_brick, 0, 3);
		p_149636_1_.setBlock(posX + 4, posY + 4, posZ + 8, Blocks.lava, 8, 3);
		p_149636_1_.setBlock(posX + 5, posY + 4, posZ + 8, Blocks.lava, 8, 3);
		p_149636_1_.setBlock(posX + 6, posY + 4, posZ + 8, Blocks.nether_brick, 0, 3);
		p_149636_1_.setBlock(posX + 7, posY + 4, posZ + 8, Blocks.nether_brick, 0, 3);
		p_149636_1_.setBlock(posX + 8, posY + 4, posZ + 8, Blocks.lava, 8, 3);
		p_149636_1_.setBlock(posX + 9, posY + 4, posZ + 8, Blocks.bedrock, 0, 3);
		p_149636_1_.setBlock(posX + 0, posY + 4, posZ + 9, Blocks.bedrock, 0, 3);
		p_149636_1_.setBlock(posX + 1, posY + 4, posZ + 9, Blocks.bedrock, 0, 3);
		p_149636_1_.setBlock(posX + 2, posY + 4, posZ + 9, Blocks.bedrock, 0, 3);
		p_149636_1_.setBlock(posX + 3, posY + 4, posZ + 9, Blocks.bedrock, 0, 3);
		p_149636_1_.setBlock(posX + 4, posY + 4, posZ + 9, Blocks.bedrock, 0, 3);
		p_149636_1_.setBlock(posX + 5, posY + 4, posZ + 9, Blocks.bedrock, 0, 3);
		p_149636_1_.setBlock(posX + 6, posY + 4, posZ + 9, Blocks.bedrock, 0, 3);
		p_149636_1_.setBlock(posX + 7, posY + 4, posZ + 9, Blocks.bedrock, 0, 3);
		p_149636_1_.setBlock(posX + 8, posY + 4, posZ + 9, Blocks.bedrock, 0, 3);
		p_149636_1_.setBlock(posX + 9, posY + 4, posZ + 9, Blocks.bedrock, 0, 3);
		p_149636_1_.setBlock(posX + 0, posY + 5, posZ + 0, Blocks.bedrock, 0, 3);
		p_149636_1_.setBlock(posX + 1, posY + 5, posZ + 0, Blocks.bedrock, 0, 3);
		p_149636_1_.setBlock(posX + 2, posY + 5, posZ + 0, Blocks.bedrock, 0, 3);
		p_149636_1_.setBlock(posX + 3, posY + 5, posZ + 0, Blocks.bedrock, 0, 3);
		p_149636_1_.setBlock(posX + 4, posY + 5, posZ + 0, Blocks.bedrock, 0, 3);
		p_149636_1_.setBlock(posX + 5, posY + 5, posZ + 0, Blocks.bedrock, 0, 3);
		p_149636_1_.setBlock(posX + 6, posY + 5, posZ + 0, Blocks.bedrock, 0, 3);
		p_149636_1_.setBlock(posX + 7, posY + 5, posZ + 0, Blocks.bedrock, 0, 3);
		p_149636_1_.setBlock(posX + 8, posY + 5, posZ + 0, Blocks.bedrock, 0, 3);
		p_149636_1_.setBlock(posX + 9, posY + 5, posZ + 0, Blocks.bedrock, 0, 3);
		p_149636_1_.setBlock(posX + 0, posY + 5, posZ + 1, Blocks.bedrock, 0, 3);
		p_149636_1_.setBlock(posX + 1, posY + 5, posZ + 1, Blocks.lava, 8, 3);
		p_149636_1_.setBlock(posX + 2, posY + 5, posZ + 1, Blocks.nether_brick, 0, 3);
		p_149636_1_.setBlock(posX + 3, posY + 5, posZ + 1, Blocks.nether_brick, 0, 3);
		p_149636_1_.setBlock(posX + 4, posY + 5, posZ + 1, Blocks.lava, 8, 3);
		p_149636_1_.setBlock(posX + 5, posY + 5, posZ + 1, Blocks.lava, 8, 3);
		p_149636_1_.setBlock(posX + 6, posY + 5, posZ + 1, Blocks.nether_brick, 0, 3);
		p_149636_1_.setBlock(posX + 7, posY + 5, posZ + 1, Blocks.nether_brick, 0, 3);
		p_149636_1_.setBlock(posX + 8, posY + 5, posZ + 1, Blocks.lava, 8, 3);
		p_149636_1_.setBlock(posX + 9, posY + 5, posZ + 1, Blocks.bedrock, 0, 3);
		p_149636_1_.setBlock(posX + 0, posY + 5, posZ + 2, Blocks.bedrock, 0, 3);
		p_149636_1_.setBlock(posX + 1, posY + 5, posZ + 2, Blocks.nether_brick, 0, 3);
		p_149636_1_.setBlock(posX + 2, posY + 5, posZ + 2, Blocks.lava, 8, 3);
		p_149636_1_.setBlock(posX + 3, posY + 5, posZ + 2, Blocks.air, 0, 3);
		p_149636_1_.setBlock(posX + 4, posY + 5, posZ + 2, Blocks.air, 0, 3);
		p_149636_1_.setBlock(posX + 5, posY + 5, posZ + 2, Blocks.air, 0, 3);
		p_149636_1_.setBlock(posX + 6, posY + 5, posZ + 2, Blocks.air, 0, 3);
		p_149636_1_.setBlock(posX + 7, posY + 5, posZ + 2, Blocks.lava, 8, 3);
		p_149636_1_.setBlock(posX + 8, posY + 5, posZ + 2, Blocks.nether_brick, 0, 3);
		p_149636_1_.setBlock(posX + 9, posY + 5, posZ + 2, Blocks.bedrock, 0, 3);
		p_149636_1_.setBlock(posX + 0, posY + 5, posZ + 3, Blocks.bedrock, 0, 3);
		p_149636_1_.setBlock(posX + 1, posY + 5, posZ + 3, Blocks.nether_brick, 0, 3);
		p_149636_1_.setBlock(posX + 2, posY + 5, posZ + 3, Blocks.air, 0, 3);
		p_149636_1_.setBlock(posX + 3, posY + 5, posZ + 3, Blocks.air, 0, 3);
		p_149636_1_.setBlock(posX + 4, posY + 5, posZ + 3, Blocks.air, 0, 3);
		p_149636_1_.setBlock(posX + 5, posY + 5, posZ + 3, Blocks.air, 0, 3);
		p_149636_1_.setBlock(posX + 6, posY + 5, posZ + 3, Blocks.air, 0, 3);
		p_149636_1_.setBlock(posX + 7, posY + 5, posZ + 3, Blocks.air, 0, 3);
		p_149636_1_.setBlock(posX + 8, posY + 5, posZ + 3, Blocks.nether_brick, 0, 3);
		p_149636_1_.setBlock(posX + 9, posY + 5, posZ + 3, Blocks.bedrock, 0, 3);
		p_149636_1_.setBlock(posX + 0, posY + 5, posZ + 4, Blocks.bedrock, 0, 3);
		p_149636_1_.setBlock(posX + 1, posY + 5, posZ + 4, Blocks.lava, 8, 3);
		p_149636_1_.setBlock(posX + 2, posY + 5, posZ + 4, Blocks.air, 0, 3);
		p_149636_1_.setBlock(posX + 3, posY + 5, posZ + 4, Blocks.air, 0, 3);
		p_149636_1_.setBlock(posX + 4, posY + 5, posZ + 4, Blocks.air, 0, 3);
		p_149636_1_.setBlock(posX + 5, posY + 5, posZ + 4, Blocks.air, 0, 3);
		p_149636_1_.setBlock(posX + 6, posY + 5, posZ + 4, Blocks.air, 0, 3);
		p_149636_1_.setBlock(posX + 7, posY + 5, posZ + 4, Blocks.air, 0, 3);
		p_149636_1_.setBlock(posX + 8, posY + 5, posZ + 4, Blocks.lava, 8, 3);
		p_149636_1_.setBlock(posX + 9, posY + 5, posZ + 4, Blocks.bedrock, 0, 3);
		p_149636_1_.setBlock(posX + 0, posY + 5, posZ + 5, Blocks.bedrock, 0, 3);
		p_149636_1_.setBlock(posX + 1, posY + 5, posZ + 5, Blocks.lava, 8, 3);
		p_149636_1_.setBlock(posX + 2, posY + 5, posZ + 5, Blocks.air, 0, 3);
		p_149636_1_.setBlock(posX + 3, posY + 5, posZ + 5, Blocks.air, 0, 3);
		p_149636_1_.setBlock(posX + 4, posY + 5, posZ + 5, Blocks.air, 0, 3);
		p_149636_1_.setBlock(posX + 5, posY + 5, posZ + 5, Blocks.air, 0, 3);
		p_149636_1_.setBlock(posX + 6, posY + 5, posZ + 5, Blocks.air, 0, 3);
		p_149636_1_.setBlock(posX + 7, posY + 5, posZ + 5, Blocks.air, 0, 3);
		p_149636_1_.setBlock(posX + 8, posY + 5, posZ + 5, Blocks.lava, 8, 3);
		p_149636_1_.setBlock(posX + 9, posY + 5, posZ + 5, Blocks.bedrock, 0, 3);
		p_149636_1_.setBlock(posX + 0, posY + 5, posZ + 6, Blocks.bedrock, 0, 3);
		p_149636_1_.setBlock(posX + 1, posY + 5, posZ + 6, Blocks.nether_brick, 0, 3);
		p_149636_1_.setBlock(posX + 2, posY + 5, posZ + 6, Blocks.air, 0, 3);
		p_149636_1_.setBlock(posX + 3, posY + 5, posZ + 6, Blocks.air, 0, 3);
		p_149636_1_.setBlock(posX + 4, posY + 5, posZ + 6, Blocks.air, 0, 3);
		p_149636_1_.setBlock(posX + 5, posY + 5, posZ + 6, Blocks.air, 0, 3);
		p_149636_1_.setBlock(posX + 6, posY + 5, posZ + 6, Blocks.air, 0, 3);
		p_149636_1_.setBlock(posX + 7, posY + 5, posZ + 6, Blocks.air, 0, 3);
		p_149636_1_.setBlock(posX + 8, posY + 5, posZ + 6, Blocks.nether_brick, 0, 3);
		p_149636_1_.setBlock(posX + 9, posY + 5, posZ + 6, Blocks.bedrock, 0, 3);
		p_149636_1_.setBlock(posX + 0, posY + 5, posZ + 7, Blocks.bedrock, 0, 3);
		p_149636_1_.setBlock(posX + 1, posY + 5, posZ + 7, Blocks.nether_brick, 0, 3);
		p_149636_1_.setBlock(posX + 2, posY + 5, posZ + 7, Blocks.lava, 8, 3);
		p_149636_1_.setBlock(posX + 3, posY + 5, posZ + 7, Blocks.air, 0, 3);
		p_149636_1_.setBlock(posX + 4, posY + 5, posZ + 7, Blocks.air, 0, 3);
		p_149636_1_.setBlock(posX + 5, posY + 5, posZ + 7, Blocks.air, 0, 3);
		p_149636_1_.setBlock(posX + 6, posY + 5, posZ + 7, Blocks.air, 0, 3);
		p_149636_1_.setBlock(posX + 7, posY + 5, posZ + 7, Blocks.lava, 8, 3);
		p_149636_1_.setBlock(posX + 8, posY + 5, posZ + 7, Blocks.nether_brick, 0, 3);
		p_149636_1_.setBlock(posX + 9, posY + 5, posZ + 7, Blocks.bedrock, 0, 3);
		p_149636_1_.setBlock(posX + 0, posY + 5, posZ + 8, Blocks.bedrock, 0, 3);
		p_149636_1_.setBlock(posX + 1, posY + 5, posZ + 8, Blocks.lava, 8, 3);
		p_149636_1_.setBlock(posX + 2, posY + 5, posZ + 8, Blocks.nether_brick, 0, 3);
		p_149636_1_.setBlock(posX + 3, posY + 5, posZ + 8, Blocks.nether_brick, 0, 3);
		p_149636_1_.setBlock(posX + 4, posY + 5, posZ + 8, Blocks.lava, 8, 3);
		p_149636_1_.setBlock(posX + 5, posY + 5, posZ + 8, Blocks.lava, 8, 3);
		p_149636_1_.setBlock(posX + 6, posY + 5, posZ + 8, Blocks.nether_brick, 0, 3);
		p_149636_1_.setBlock(posX + 7, posY + 5, posZ + 8, Blocks.nether_brick, 0, 3);
		p_149636_1_.setBlock(posX + 8, posY + 5, posZ + 8, Blocks.lava, 8, 3);
		p_149636_1_.setBlock(posX + 9, posY + 5, posZ + 8, Blocks.bedrock, 0, 3);
		p_149636_1_.setBlock(posX + 0, posY + 5, posZ + 9, Blocks.bedrock, 0, 3);
		p_149636_1_.setBlock(posX + 1, posY + 5, posZ + 9, Blocks.bedrock, 0, 3);
		p_149636_1_.setBlock(posX + 2, posY + 5, posZ + 9, Blocks.bedrock, 0, 3);
		p_149636_1_.setBlock(posX + 3, posY + 5, posZ + 9, Blocks.bedrock, 0, 3);
		p_149636_1_.setBlock(posX + 4, posY + 5, posZ + 9, Blocks.bedrock, 0, 3);
		p_149636_1_.setBlock(posX + 5, posY + 5, posZ + 9, Blocks.bedrock, 0, 3);
		p_149636_1_.setBlock(posX + 6, posY + 5, posZ + 9, Blocks.bedrock, 0, 3);
		p_149636_1_.setBlock(posX + 7, posY + 5, posZ + 9, Blocks.bedrock, 0, 3);
		p_149636_1_.setBlock(posX + 8, posY + 5, posZ + 9, Blocks.bedrock, 0, 3);
		p_149636_1_.setBlock(posX + 9, posY + 5, posZ + 9, Blocks.bedrock, 0, 3);
		p_149636_1_.setBlock(posX + 0, posY + 6, posZ + 0, Blocks.bedrock, 0, 3);
		p_149636_1_.setBlock(posX + 1, posY + 6, posZ + 0, Blocks.bedrock, 0, 3);
		p_149636_1_.setBlock(posX + 2, posY + 6, posZ + 0, Blocks.bedrock, 0, 3);
		p_149636_1_.setBlock(posX + 3, posY + 6, posZ + 0, Blocks.bedrock, 0, 3);
		p_149636_1_.setBlock(posX + 4, posY + 6, posZ + 0, Blocks.bedrock, 0, 3);
		p_149636_1_.setBlock(posX + 5, posY + 6, posZ + 0, Blocks.bedrock, 0, 3);
		p_149636_1_.setBlock(posX + 6, posY + 6, posZ + 0, Blocks.bedrock, 0, 3);
		p_149636_1_.setBlock(posX + 7, posY + 6, posZ + 0, Blocks.bedrock, 0, 3);
		p_149636_1_.setBlock(posX + 8, posY + 6, posZ + 0, Blocks.bedrock, 0, 3);
		p_149636_1_.setBlock(posX + 9, posY + 6, posZ + 0, Blocks.bedrock, 0, 3);
		p_149636_1_.setBlock(posX + 0, posY + 6, posZ + 1, Blocks.bedrock, 0, 3);
		p_149636_1_.setBlock(posX + 1, posY + 6, posZ + 1, Blocks.lava, 8, 3);
		p_149636_1_.setBlock(posX + 2, posY + 6, posZ + 1, Blocks.nether_brick, 0, 3);
		p_149636_1_.setBlock(posX + 3, posY + 6, posZ + 1, Blocks.nether_brick, 0, 3);
		p_149636_1_.setBlock(posX + 4, posY + 6, posZ + 1, Blocks.lava, 8, 3);
		p_149636_1_.setBlock(posX + 5, posY + 6, posZ + 1, Blocks.lava, 8, 3);
		p_149636_1_.setBlock(posX + 6, posY + 6, posZ + 1, Blocks.nether_brick, 0, 3);
		p_149636_1_.setBlock(posX + 7, posY + 6, posZ + 1, Blocks.nether_brick, 0, 3);
		p_149636_1_.setBlock(posX + 8, posY + 6, posZ + 1, Blocks.lava, 8, 3);
		p_149636_1_.setBlock(posX + 9, posY + 6, posZ + 1, Blocks.bedrock, 0, 3);
		p_149636_1_.setBlock(posX + 0, posY + 6, posZ + 2, Blocks.bedrock, 0, 3);
		p_149636_1_.setBlock(posX + 1, posY + 6, posZ + 2, Blocks.nether_brick, 0, 3);
		p_149636_1_.setBlock(posX + 2, posY + 6, posZ + 2, Blocks.lava, 8, 3);
		p_149636_1_.setBlock(posX + 3, posY + 6, posZ + 2, Blocks.air, 0, 3);
		p_149636_1_.setBlock(posX + 4, posY + 6, posZ + 2, Blocks.air, 0, 3);
		p_149636_1_.setBlock(posX + 5, posY + 6, posZ + 2, Blocks.air, 0, 3);
		p_149636_1_.setBlock(posX + 6, posY + 6, posZ + 2, Blocks.air, 0, 3);
		p_149636_1_.setBlock(posX + 7, posY + 6, posZ + 2, Blocks.lava, 8, 3);
		p_149636_1_.setBlock(posX + 8, posY + 6, posZ + 2, Blocks.nether_brick, 0, 3);
		p_149636_1_.setBlock(posX + 9, posY + 6, posZ + 2, Blocks.bedrock, 0, 3);
		p_149636_1_.setBlock(posX + 0, posY + 6, posZ + 3, Blocks.bedrock, 0, 3);
		p_149636_1_.setBlock(posX + 1, posY + 6, posZ + 3, Blocks.nether_brick, 0, 3);
		p_149636_1_.setBlock(posX + 2, posY + 6, posZ + 3, Blocks.air, 0, 3);
		p_149636_1_.setBlock(posX + 3, posY + 6, posZ + 3, Blocks.air, 0, 3);
		p_149636_1_.setBlock(posX + 4, posY + 6, posZ + 3, Blocks.air, 0, 3);
		p_149636_1_.setBlock(posX + 5, posY + 6, posZ + 3, Blocks.air, 0, 3);
		p_149636_1_.setBlock(posX + 6, posY + 6, posZ + 3, Blocks.air, 0, 3);
		p_149636_1_.setBlock(posX + 7, posY + 6, posZ + 3, Blocks.air, 0, 3);
		p_149636_1_.setBlock(posX + 8, posY + 6, posZ + 3, Blocks.nether_brick, 0, 3);
		p_149636_1_.setBlock(posX + 9, posY + 6, posZ + 3, Blocks.bedrock, 0, 3);
		p_149636_1_.setBlock(posX + 0, posY + 6, posZ + 4, Blocks.bedrock, 0, 3);
		p_149636_1_.setBlock(posX + 1, posY + 6, posZ + 4, Blocks.lava, 8, 3);
		p_149636_1_.setBlock(posX + 2, posY + 6, posZ + 4, Blocks.air, 0, 3);
		p_149636_1_.setBlock(posX + 3, posY + 6, posZ + 4, Blocks.air, 0, 3);
		p_149636_1_.setBlock(posX + 4, posY + 6, posZ + 4, Blocks.air, 0, 3);
		p_149636_1_.setBlock(posX + 5, posY + 6, posZ + 4, Blocks.air, 0, 3);
		p_149636_1_.setBlock(posX + 6, posY + 6, posZ + 4, Blocks.air, 0, 3);
		p_149636_1_.setBlock(posX + 7, posY + 6, posZ + 4, Blocks.air, 0, 3);
		p_149636_1_.setBlock(posX + 8, posY + 6, posZ + 4, Blocks.lava, 8, 3);
		p_149636_1_.setBlock(posX + 9, posY + 6, posZ + 4, Blocks.bedrock, 0, 3);
		p_149636_1_.setBlock(posX + 0, posY + 6, posZ + 5, Blocks.bedrock, 0, 3);
		p_149636_1_.setBlock(posX + 1, posY + 6, posZ + 5, Blocks.lava, 8, 3);
		p_149636_1_.setBlock(posX + 2, posY + 6, posZ + 5, Blocks.air, 0, 3);
		p_149636_1_.setBlock(posX + 3, posY + 6, posZ + 5, Blocks.air, 0, 3);
		p_149636_1_.setBlock(posX + 4, posY + 6, posZ + 5, Blocks.air, 0, 3);
		p_149636_1_.setBlock(posX + 5, posY + 6, posZ + 5, Blocks.air, 0, 3);
		p_149636_1_.setBlock(posX + 6, posY + 6, posZ + 5, Blocks.air, 0, 3);
		p_149636_1_.setBlock(posX + 7, posY + 6, posZ + 5, Blocks.air, 0, 3);
		p_149636_1_.setBlock(posX + 8, posY + 6, posZ + 5, Blocks.lava, 8, 3);
		p_149636_1_.setBlock(posX + 9, posY + 6, posZ + 5, Blocks.bedrock, 0, 3);
		p_149636_1_.setBlock(posX + 0, posY + 6, posZ + 6, Blocks.bedrock, 0, 3);
		p_149636_1_.setBlock(posX + 1, posY + 6, posZ + 6, Blocks.nether_brick, 0, 3);
		p_149636_1_.setBlock(posX + 2, posY + 6, posZ + 6, Blocks.air, 0, 3);
		p_149636_1_.setBlock(posX + 3, posY + 6, posZ + 6, Blocks.air, 0, 3);
		p_149636_1_.setBlock(posX + 4, posY + 6, posZ + 6, Blocks.air, 0, 3);
		p_149636_1_.setBlock(posX + 5, posY + 6, posZ + 6, Blocks.air, 0, 3);
		p_149636_1_.setBlock(posX + 6, posY + 6, posZ + 6, Blocks.air, 0, 3);
		p_149636_1_.setBlock(posX + 7, posY + 6, posZ + 6, Blocks.air, 0, 3);
		p_149636_1_.setBlock(posX + 8, posY + 6, posZ + 6, Blocks.nether_brick, 0, 3);
		p_149636_1_.setBlock(posX + 9, posY + 6, posZ + 6, Blocks.bedrock, 0, 3);
		p_149636_1_.setBlock(posX + 0, posY + 6, posZ + 7, Blocks.bedrock, 0, 3);
		p_149636_1_.setBlock(posX + 1, posY + 6, posZ + 7, Blocks.nether_brick, 0, 3);
		p_149636_1_.setBlock(posX + 2, posY + 6, posZ + 7, Blocks.lava, 8, 3);
		p_149636_1_.setBlock(posX + 3, posY + 6, posZ + 7, Blocks.air, 0, 3);
		p_149636_1_.setBlock(posX + 4, posY + 6, posZ + 7, Blocks.air, 0, 3);
		p_149636_1_.setBlock(posX + 5, posY + 6, posZ + 7, Blocks.air, 0, 3);
		p_149636_1_.setBlock(posX + 6, posY + 6, posZ + 7, Blocks.air, 0, 3);
		p_149636_1_.setBlock(posX + 7, posY + 6, posZ + 7, Blocks.lava, 8, 3);
		p_149636_1_.setBlock(posX + 8, posY + 6, posZ + 7, Blocks.nether_brick, 0, 3);
		p_149636_1_.setBlock(posX + 9, posY + 6, posZ + 7, Blocks.bedrock, 0, 3);
		p_149636_1_.setBlock(posX + 0, posY + 6, posZ + 8, Blocks.bedrock, 0, 3);
		p_149636_1_.setBlock(posX + 1, posY + 6, posZ + 8, Blocks.lava, 8, 3);
		p_149636_1_.setBlock(posX + 2, posY + 6, posZ + 8, Blocks.nether_brick, 0, 3);
		p_149636_1_.setBlock(posX + 3, posY + 6, posZ + 8, Blocks.nether_brick, 0, 3);
		p_149636_1_.setBlock(posX + 4, posY + 6, posZ + 8, Blocks.lava, 8, 3);
		p_149636_1_.setBlock(posX + 5, posY + 6, posZ + 8, Blocks.lava, 8, 3);
		p_149636_1_.setBlock(posX + 6, posY + 6, posZ + 8, Blocks.nether_brick, 0, 3);
		p_149636_1_.setBlock(posX + 7, posY + 6, posZ + 8, Blocks.nether_brick, 0, 3);
		p_149636_1_.setBlock(posX + 8, posY + 6, posZ + 8, Blocks.lava, 8, 3);
		p_149636_1_.setBlock(posX + 9, posY + 6, posZ + 8, Blocks.bedrock, 0, 3);
		p_149636_1_.setBlock(posX + 0, posY + 6, posZ + 9, Blocks.bedrock, 0, 3);
		p_149636_1_.setBlock(posX + 1, posY + 6, posZ + 9, Blocks.bedrock, 0, 3);
		p_149636_1_.setBlock(posX + 2, posY + 6, posZ + 9, Blocks.bedrock, 0, 3);
		p_149636_1_.setBlock(posX + 3, posY + 6, posZ + 9, Blocks.bedrock, 0, 3);
		p_149636_1_.setBlock(posX + 4, posY + 6, posZ + 9, Blocks.bedrock, 0, 3);
		p_149636_1_.setBlock(posX + 5, posY + 6, posZ + 9, Blocks.bedrock, 0, 3);
		p_149636_1_.setBlock(posX + 6, posY + 6, posZ + 9, Blocks.bedrock, 0, 3);
		p_149636_1_.setBlock(posX + 7, posY + 6, posZ + 9, Blocks.bedrock, 0, 3);
		p_149636_1_.setBlock(posX + 8, posY + 6, posZ + 9, Blocks.bedrock, 0, 3);
		p_149636_1_.setBlock(posX + 9, posY + 6, posZ + 9, Blocks.bedrock, 0, 3);
		p_149636_1_.setBlock(posX + 0, posY + 7, posZ + 0, Blocks.bedrock, 0, 3);
		p_149636_1_.setBlock(posX + 1, posY + 7, posZ + 0, Blocks.bedrock, 0, 3);
		p_149636_1_.setBlock(posX + 2, posY + 7, posZ + 0, Blocks.bedrock, 0, 3);
		p_149636_1_.setBlock(posX + 3, posY + 7, posZ + 0, Blocks.bedrock, 0, 3);
		p_149636_1_.setBlock(posX + 4, posY + 7, posZ + 0, Blocks.bedrock, 0, 3);
		p_149636_1_.setBlock(posX + 5, posY + 7, posZ + 0, Blocks.bedrock, 0, 3);
		p_149636_1_.setBlock(posX + 6, posY + 7, posZ + 0, Blocks.bedrock, 0, 3);
		p_149636_1_.setBlock(posX + 7, posY + 7, posZ + 0, Blocks.bedrock, 0, 3);
		p_149636_1_.setBlock(posX + 8, posY + 7, posZ + 0, Blocks.bedrock, 0, 3);
		p_149636_1_.setBlock(posX + 9, posY + 7, posZ + 0, Blocks.bedrock, 0, 3);
		p_149636_1_.setBlock(posX + 0, posY + 7, posZ + 1, Blocks.bedrock, 0, 3);
		p_149636_1_.setBlock(posX + 1, posY + 7, posZ + 1, Blocks.lava, 8, 3);
		p_149636_1_.setBlock(posX + 2, posY + 7, posZ + 1, Blocks.nether_brick, 0, 3);
		p_149636_1_.setBlock(posX + 3, posY + 7, posZ + 1, Blocks.nether_brick, 0, 3);
		p_149636_1_.setBlock(posX + 4, posY + 7, posZ + 1, Blocks.lava, 8, 3);
		p_149636_1_.setBlock(posX + 5, posY + 7, posZ + 1, Blocks.lava, 8, 3);
		p_149636_1_.setBlock(posX + 6, posY + 7, posZ + 1, Blocks.nether_brick, 0, 3);
		p_149636_1_.setBlock(posX + 7, posY + 7, posZ + 1, Blocks.nether_brick, 0, 3);
		p_149636_1_.setBlock(posX + 8, posY + 7, posZ + 1, Blocks.lava, 8, 3);
		p_149636_1_.setBlock(posX + 9, posY + 7, posZ + 1, Blocks.bedrock, 0, 3);
		p_149636_1_.setBlock(posX + 0, posY + 7, posZ + 2, Blocks.bedrock, 0, 3);
		p_149636_1_.setBlock(posX + 1, posY + 7, posZ + 2, Blocks.nether_brick, 0, 3);
		p_149636_1_.setBlock(posX + 2, posY + 7, posZ + 2, Blocks.lava, 8, 3);
		p_149636_1_.setBlock(posX + 3, posY + 7, posZ + 2, Blocks.air, 0, 3);
		p_149636_1_.setBlock(posX + 4, posY + 7, posZ + 2, Blocks.air, 0, 3);
		p_149636_1_.setBlock(posX + 5, posY + 7, posZ + 2, Blocks.air, 0, 3);
		p_149636_1_.setBlock(posX + 6, posY + 7, posZ + 2, Blocks.air, 0, 3);
		p_149636_1_.setBlock(posX + 7, posY + 7, posZ + 2, Blocks.lava, 8, 3);
		p_149636_1_.setBlock(posX + 8, posY + 7, posZ + 2, Blocks.nether_brick, 0, 3);
		p_149636_1_.setBlock(posX + 9, posY + 7, posZ + 2, Blocks.bedrock, 0, 3);
		p_149636_1_.setBlock(posX + 0, posY + 7, posZ + 3, Blocks.bedrock, 0, 3);
		p_149636_1_.setBlock(posX + 1, posY + 7, posZ + 3, Blocks.nether_brick, 0, 3);
		p_149636_1_.setBlock(posX + 2, posY + 7, posZ + 3, Blocks.air, 0, 3);
		p_149636_1_.setBlock(posX + 3, posY + 7, posZ + 3, Blocks.air, 0, 3);
		p_149636_1_.setBlock(posX + 4, posY + 7, posZ + 3, Blocks.air, 0, 3);
		p_149636_1_.setBlock(posX + 5, posY + 7, posZ + 3, Blocks.air, 0, 3);
		p_149636_1_.setBlock(posX + 6, posY + 7, posZ + 3, Blocks.air, 0, 3);
		p_149636_1_.setBlock(posX + 7, posY + 7, posZ + 3, Blocks.air, 0, 3);
		p_149636_1_.setBlock(posX + 8, posY + 7, posZ + 3, Blocks.nether_brick, 0, 3);
		p_149636_1_.setBlock(posX + 9, posY + 7, posZ + 3, Blocks.bedrock, 0, 3);
		p_149636_1_.setBlock(posX + 0, posY + 7, posZ + 4, Blocks.bedrock, 0, 3);
		p_149636_1_.setBlock(posX + 1, posY + 7, posZ + 4, Blocks.lava, 8, 3);
		p_149636_1_.setBlock(posX + 2, posY + 7, posZ + 4, Blocks.air, 0, 3);
		p_149636_1_.setBlock(posX + 3, posY + 7, posZ + 4, Blocks.air, 0, 3);
		p_149636_1_.setBlock(posX + 4, posY + 7, posZ + 4, Blocks.air, 0, 3);
		p_149636_1_.setBlock(posX + 5, posY + 7, posZ + 4, Blocks.air, 0, 3);
		p_149636_1_.setBlock(posX + 6, posY + 7, posZ + 4, Blocks.air, 0, 3);
		p_149636_1_.setBlock(posX + 7, posY + 7, posZ + 4, Blocks.air, 0, 3);
		p_149636_1_.setBlock(posX + 8, posY + 7, posZ + 4, Blocks.lava, 8, 3);
		p_149636_1_.setBlock(posX + 9, posY + 7, posZ + 4, Blocks.bedrock, 0, 3);
		p_149636_1_.setBlock(posX + 0, posY + 7, posZ + 5, Blocks.bedrock, 0, 3);
		p_149636_1_.setBlock(posX + 1, posY + 7, posZ + 5, Blocks.lava, 8, 3);
		p_149636_1_.setBlock(posX + 2, posY + 7, posZ + 5, Blocks.air, 0, 3);
		p_149636_1_.setBlock(posX + 3, posY + 7, posZ + 5, Blocks.air, 0, 3);
		p_149636_1_.setBlock(posX + 4, posY + 7, posZ + 5, Blocks.air, 0, 3);
		p_149636_1_.setBlock(posX + 5, posY + 7, posZ + 5, Blocks.air, 0, 3);
		p_149636_1_.setBlock(posX + 6, posY + 7, posZ + 5, Blocks.air, 0, 3);
		p_149636_1_.setBlock(posX + 7, posY + 7, posZ + 5, Blocks.air, 0, 3);
		p_149636_1_.setBlock(posX + 8, posY + 7, posZ + 5, Blocks.lava, 8, 3);
		p_149636_1_.setBlock(posX + 9, posY + 7, posZ + 5, Blocks.bedrock, 0, 3);
		p_149636_1_.setBlock(posX + 0, posY + 7, posZ + 6, Blocks.bedrock, 0, 3);
		p_149636_1_.setBlock(posX + 1, posY + 7, posZ + 6, Blocks.nether_brick, 0, 3);
		p_149636_1_.setBlock(posX + 2, posY + 7, posZ + 6, Blocks.air, 0, 3);
		p_149636_1_.setBlock(posX + 3, posY + 7, posZ + 6, Blocks.air, 0, 3);
		p_149636_1_.setBlock(posX + 4, posY + 7, posZ + 6, Blocks.air, 0, 3);
		p_149636_1_.setBlock(posX + 5, posY + 7, posZ + 6, Blocks.air, 0, 3);
		p_149636_1_.setBlock(posX + 6, posY + 7, posZ + 6, Blocks.air, 0, 3);
		p_149636_1_.setBlock(posX + 7, posY + 7, posZ + 6, Blocks.air, 0, 3);
		p_149636_1_.setBlock(posX + 8, posY + 7, posZ + 6, Blocks.nether_brick, 0, 3);
		p_149636_1_.setBlock(posX + 9, posY + 7, posZ + 6, Blocks.bedrock, 0, 3);
		p_149636_1_.setBlock(posX + 0, posY + 7, posZ + 7, Blocks.bedrock, 0, 3);
		p_149636_1_.setBlock(posX + 1, posY + 7, posZ + 7, Blocks.nether_brick, 0, 3);
		p_149636_1_.setBlock(posX + 2, posY + 7, posZ + 7, Blocks.lava, 8, 3);
		p_149636_1_.setBlock(posX + 3, posY + 7, posZ + 7, Blocks.air, 0, 3);
		p_149636_1_.setBlock(posX + 4, posY + 7, posZ + 7, Blocks.air, 0, 3);
		p_149636_1_.setBlock(posX + 5, posY + 7, posZ + 7, Blocks.air, 0, 3);
		p_149636_1_.setBlock(posX + 6, posY + 7, posZ + 7, Blocks.air, 0, 3);
		p_149636_1_.setBlock(posX + 7, posY + 7, posZ + 7, Blocks.lava, 8, 3);
		p_149636_1_.setBlock(posX + 8, posY + 7, posZ + 7, Blocks.nether_brick, 0, 3);
		p_149636_1_.setBlock(posX + 9, posY + 7, posZ + 7, Blocks.bedrock, 0, 3);
		p_149636_1_.setBlock(posX + 0, posY + 7, posZ + 8, Blocks.bedrock, 0, 3);
		p_149636_1_.setBlock(posX + 1, posY + 7, posZ + 8, Blocks.lava, 8, 3);
		p_149636_1_.setBlock(posX + 2, posY + 7, posZ + 8, Blocks.nether_brick, 0, 3);
		p_149636_1_.setBlock(posX + 3, posY + 7, posZ + 8, Blocks.nether_brick, 0, 3);
		p_149636_1_.setBlock(posX + 4, posY + 7, posZ + 8, Blocks.lava, 8, 3);
		p_149636_1_.setBlock(posX + 5, posY + 7, posZ + 8, Blocks.lava, 8, 3);
		p_149636_1_.setBlock(posX + 6, posY + 7, posZ + 8, Blocks.nether_brick, 0, 3);
		p_149636_1_.setBlock(posX + 7, posY + 7, posZ + 8, Blocks.nether_brick, 0, 3);
		p_149636_1_.setBlock(posX + 8, posY + 7, posZ + 8, Blocks.lava, 8, 3);
		p_149636_1_.setBlock(posX + 9, posY + 7, posZ + 8, Blocks.bedrock, 0, 3);
		p_149636_1_.setBlock(posX + 0, posY + 7, posZ + 9, Blocks.bedrock, 0, 3);
		p_149636_1_.setBlock(posX + 1, posY + 7, posZ + 9, Blocks.bedrock, 0, 3);
		p_149636_1_.setBlock(posX + 2, posY + 7, posZ + 9, Blocks.bedrock, 0, 3);
		p_149636_1_.setBlock(posX + 3, posY + 7, posZ + 9, Blocks.bedrock, 0, 3);
		p_149636_1_.setBlock(posX + 4, posY + 7, posZ + 9, Blocks.bedrock, 0, 3);
		p_149636_1_.setBlock(posX + 5, posY + 7, posZ + 9, Blocks.bedrock, 0, 3);
		p_149636_1_.setBlock(posX + 6, posY + 7, posZ + 9, Blocks.bedrock, 0, 3);
		p_149636_1_.setBlock(posX + 7, posY + 7, posZ + 9, Blocks.bedrock, 0, 3);
		p_149636_1_.setBlock(posX + 8, posY + 7, posZ + 9, Blocks.bedrock, 0, 3);
		p_149636_1_.setBlock(posX + 9, posY + 7, posZ + 9, Blocks.bedrock, 0, 3);
		p_149636_1_.setBlock(posX + 0, posY + 8, posZ + 0, Blocks.bedrock, 0, 3);
		p_149636_1_.setBlock(posX + 1, posY + 8, posZ + 0, Blocks.bedrock, 0, 3);
		p_149636_1_.setBlock(posX + 2, posY + 8, posZ + 0, Blocks.bedrock, 0, 3);
		p_149636_1_.setBlock(posX + 3, posY + 8, posZ + 0, Blocks.bedrock, 0, 3);
		p_149636_1_.setBlock(posX + 4, posY + 8, posZ + 0, Blocks.bedrock, 0, 3);
		p_149636_1_.setBlock(posX + 5, posY + 8, posZ + 0, Blocks.bedrock, 0, 3);
		p_149636_1_.setBlock(posX + 6, posY + 8, posZ + 0, Blocks.bedrock, 0, 3);
		p_149636_1_.setBlock(posX + 7, posY + 8, posZ + 0, Blocks.bedrock, 0, 3);
		p_149636_1_.setBlock(posX + 8, posY + 8, posZ + 0, Blocks.bedrock, 0, 3);
		p_149636_1_.setBlock(posX + 9, posY + 8, posZ + 0, Blocks.bedrock, 0, 3);
		p_149636_1_.setBlock(posX + 0, posY + 8, posZ + 1, Blocks.bedrock, 0, 3);
		p_149636_1_.setBlock(posX + 1, posY + 8, posZ + 1, Blocks.lava, 8, 3);
		p_149636_1_.setBlock(posX + 2, posY + 8, posZ + 1, Blocks.nether_brick, 0, 3);
		p_149636_1_.setBlock(posX + 3, posY + 8, posZ + 1, Blocks.nether_brick, 0, 3);
		p_149636_1_.setBlock(posX + 4, posY + 8, posZ + 1, Blocks.lava, 8, 3);
		p_149636_1_.setBlock(posX + 5, posY + 8, posZ + 1, Blocks.lava, 8, 3);
		p_149636_1_.setBlock(posX + 6, posY + 8, posZ + 1, Blocks.nether_brick, 0, 3);
		p_149636_1_.setBlock(posX + 7, posY + 8, posZ + 1, Blocks.nether_brick, 0, 3);
		p_149636_1_.setBlock(posX + 8, posY + 8, posZ + 1, Blocks.lava, 8, 3);
		p_149636_1_.setBlock(posX + 9, posY + 8, posZ + 1, Blocks.bedrock, 0, 3);
		p_149636_1_.setBlock(posX + 0, posY + 8, posZ + 2, Blocks.bedrock, 0, 3);
		p_149636_1_.setBlock(posX + 1, posY + 8, posZ + 2, Blocks.nether_brick, 0, 3);
		p_149636_1_.setBlock(posX + 2, posY + 8, posZ + 2, Blocks.lava, 8, 3);
		p_149636_1_.setBlock(posX + 3, posY + 8, posZ + 2, Blocks.air, 0, 3);
		p_149636_1_.setBlock(posX + 4, posY + 8, posZ + 2, Blocks.air, 0, 3);
		p_149636_1_.setBlock(posX + 5, posY + 8, posZ + 2, Blocks.air, 0, 3);
		p_149636_1_.setBlock(posX + 6, posY + 8, posZ + 2, Blocks.air, 0, 3);
		p_149636_1_.setBlock(posX + 7, posY + 8, posZ + 2, Blocks.lava, 8, 3);
		p_149636_1_.setBlock(posX + 8, posY + 8, posZ + 2, Blocks.nether_brick, 0, 3);
		p_149636_1_.setBlock(posX + 9, posY + 8, posZ + 2, Blocks.bedrock, 0, 3);
		p_149636_1_.setBlock(posX + 0, posY + 8, posZ + 3, Blocks.bedrock, 0, 3);
		p_149636_1_.setBlock(posX + 1, posY + 8, posZ + 3, Blocks.nether_brick, 0, 3);
		p_149636_1_.setBlock(posX + 2, posY + 8, posZ + 3, Blocks.air, 0, 3);
		p_149636_1_.setBlock(posX + 3, posY + 8, posZ + 3, Blocks.air, 0, 3);
		p_149636_1_.setBlock(posX + 4, posY + 8, posZ + 3, Blocks.air, 0, 3);
		p_149636_1_.setBlock(posX + 5, posY + 8, posZ + 3, Blocks.air, 0, 3);
		p_149636_1_.setBlock(posX + 6, posY + 8, posZ + 3, Blocks.air, 0, 3);
		p_149636_1_.setBlock(posX + 7, posY + 8, posZ + 3, Blocks.air, 0, 3);
		p_149636_1_.setBlock(posX + 8, posY + 8, posZ + 3, Blocks.nether_brick, 0, 3);
		p_149636_1_.setBlock(posX + 9, posY + 8, posZ + 3, Blocks.bedrock, 0, 3);
		p_149636_1_.setBlock(posX + 0, posY + 8, posZ + 4, Blocks.bedrock, 0, 3);
		p_149636_1_.setBlock(posX + 1, posY + 8, posZ + 4, Blocks.lava, 8, 3);
		p_149636_1_.setBlock(posX + 2, posY + 8, posZ + 4, Blocks.air, 0, 3);
		p_149636_1_.setBlock(posX + 3, posY + 8, posZ + 4, Blocks.air, 0, 3);
		p_149636_1_.setBlock(posX + 4, posY + 8, posZ + 4, Blocks.air, 0, 3);
		p_149636_1_.setBlock(posX + 5, posY + 8, posZ + 4, Blocks.air, 0, 3);
		p_149636_1_.setBlock(posX + 6, posY + 8, posZ + 4, Blocks.air, 0, 3);
		p_149636_1_.setBlock(posX + 7, posY + 8, posZ + 4, Blocks.air, 0, 3);
		p_149636_1_.setBlock(posX + 8, posY + 8, posZ + 4, Blocks.lava, 8, 3);
		p_149636_1_.setBlock(posX + 9, posY + 8, posZ + 4, Blocks.bedrock, 0, 3);
		p_149636_1_.setBlock(posX + 0, posY + 8, posZ + 5, Blocks.bedrock, 0, 3);
		p_149636_1_.setBlock(posX + 1, posY + 8, posZ + 5, Blocks.lava, 8, 3);
		p_149636_1_.setBlock(posX + 2, posY + 8, posZ + 5, Blocks.air, 0, 3);
		p_149636_1_.setBlock(posX + 3, posY + 8, posZ + 5, Blocks.air, 0, 3);
		p_149636_1_.setBlock(posX + 4, posY + 8, posZ + 5, Blocks.air, 0, 3);
		p_149636_1_.setBlock(posX + 5, posY + 8, posZ + 5, Blocks.air, 0, 3);
		p_149636_1_.setBlock(posX + 6, posY + 8, posZ + 5, Blocks.air, 0, 3);
		p_149636_1_.setBlock(posX + 7, posY + 8, posZ + 5, Blocks.air, 0, 3);
		p_149636_1_.setBlock(posX + 8, posY + 8, posZ + 5, Blocks.lava, 8, 3);
		p_149636_1_.setBlock(posX + 9, posY + 8, posZ + 5, Blocks.bedrock, 0, 3);
		p_149636_1_.setBlock(posX + 0, posY + 8, posZ + 6, Blocks.bedrock, 0, 3);
		p_149636_1_.setBlock(posX + 1, posY + 8, posZ + 6, Blocks.nether_brick, 0, 3);
		p_149636_1_.setBlock(posX + 2, posY + 8, posZ + 6, Blocks.air, 0, 3);
		p_149636_1_.setBlock(posX + 3, posY + 8, posZ + 6, Blocks.air, 0, 3);
		p_149636_1_.setBlock(posX + 4, posY + 8, posZ + 6, Blocks.air, 0, 3);
		p_149636_1_.setBlock(posX + 5, posY + 8, posZ + 6, Blocks.air, 0, 3);
		p_149636_1_.setBlock(posX + 6, posY + 8, posZ + 6, Blocks.air, 0, 3);
		p_149636_1_.setBlock(posX + 7, posY + 8, posZ + 6, Blocks.air, 0, 3);
		p_149636_1_.setBlock(posX + 8, posY + 8, posZ + 6, Blocks.nether_brick, 0, 3);
		p_149636_1_.setBlock(posX + 9, posY + 8, posZ + 6, Blocks.bedrock, 0, 3);
		p_149636_1_.setBlock(posX + 0, posY + 8, posZ + 7, Blocks.bedrock, 0, 3);
		p_149636_1_.setBlock(posX + 1, posY + 8, posZ + 7, Blocks.nether_brick, 0, 3);
		p_149636_1_.setBlock(posX + 2, posY + 8, posZ + 7, Blocks.lava, 8, 3);
		p_149636_1_.setBlock(posX + 3, posY + 8, posZ + 7, Blocks.air, 0, 3);
		p_149636_1_.setBlock(posX + 4, posY + 8, posZ + 7, Blocks.air, 0, 3);
		p_149636_1_.setBlock(posX + 5, posY + 8, posZ + 7, Blocks.air, 0, 3);
		p_149636_1_.setBlock(posX + 6, posY + 8, posZ + 7, Blocks.air, 0, 3);
		p_149636_1_.setBlock(posX + 7, posY + 8, posZ + 7, Blocks.lava, 8, 3);
		p_149636_1_.setBlock(posX + 8, posY + 8, posZ + 7, Blocks.nether_brick, 0, 3);
		p_149636_1_.setBlock(posX + 9, posY + 8, posZ + 7, Blocks.bedrock, 0, 3);
		p_149636_1_.setBlock(posX + 0, posY + 8, posZ + 8, Blocks.bedrock, 0, 3);
		p_149636_1_.setBlock(posX + 1, posY + 8, posZ + 8, Blocks.lava, 8, 3);
		p_149636_1_.setBlock(posX + 2, posY + 8, posZ + 8, Blocks.nether_brick, 0, 3);
		p_149636_1_.setBlock(posX + 3, posY + 8, posZ + 8, Blocks.nether_brick, 0, 3);
		p_149636_1_.setBlock(posX + 4, posY + 8, posZ + 8, Blocks.lava, 8, 3);
		p_149636_1_.setBlock(posX + 5, posY + 8, posZ + 8, Blocks.lava, 8, 3);
		p_149636_1_.setBlock(posX + 6, posY + 8, posZ + 8, Blocks.nether_brick, 0, 3);
		p_149636_1_.setBlock(posX + 7, posY + 8, posZ + 8, Blocks.nether_brick, 0, 3);
		p_149636_1_.setBlock(posX + 8, posY + 8, posZ + 8, Blocks.lava, 8, 3);
		p_149636_1_.setBlock(posX + 9, posY + 8, posZ + 8, Blocks.bedrock, 0, 3);
		p_149636_1_.setBlock(posX + 0, posY + 8, posZ + 9, Blocks.bedrock, 0, 3);
		p_149636_1_.setBlock(posX + 1, posY + 8, posZ + 9, Blocks.bedrock, 0, 3);
		p_149636_1_.setBlock(posX + 2, posY + 8, posZ + 9, Blocks.bedrock, 0, 3);
		p_149636_1_.setBlock(posX + 3, posY + 8, posZ + 9, Blocks.bedrock, 0, 3);
		p_149636_1_.setBlock(posX + 4, posY + 8, posZ + 9, Blocks.bedrock, 0, 3);
		p_149636_1_.setBlock(posX + 5, posY + 8, posZ + 9, Blocks.bedrock, 0, 3);
		p_149636_1_.setBlock(posX + 6, posY + 8, posZ + 9, Blocks.bedrock, 0, 3);
		p_149636_1_.setBlock(posX + 7, posY + 8, posZ + 9, Blocks.bedrock, 0, 3);
		p_149636_1_.setBlock(posX + 8, posY + 8, posZ + 9, Blocks.bedrock, 0, 3);
		p_149636_1_.setBlock(posX + 9, posY + 8, posZ + 9, Blocks.bedrock, 0, 3);
		p_149636_1_.setBlock(posX + 0, posY + 9, posZ + 0, Blocks.bedrock, 0, 3);
		p_149636_1_.setBlock(posX + 1, posY + 9, posZ + 0, Blocks.bedrock, 0, 3);
		p_149636_1_.setBlock(posX + 2, posY + 9, posZ + 0, Blocks.bedrock, 0, 3);
		p_149636_1_.setBlock(posX + 3, posY + 9, posZ + 0, Blocks.bedrock, 0, 3);
		p_149636_1_.setBlock(posX + 4, posY + 9, posZ + 0, Blocks.bedrock, 0, 3);
		p_149636_1_.setBlock(posX + 5, posY + 9, posZ + 0, Blocks.bedrock, 0, 3);
		p_149636_1_.setBlock(posX + 6, posY + 9, posZ + 0, Blocks.bedrock, 0, 3);
		p_149636_1_.setBlock(posX + 7, posY + 9, posZ + 0, Blocks.bedrock, 0, 3);
		p_149636_1_.setBlock(posX + 8, posY + 9, posZ + 0, Blocks.bedrock, 0, 3);
		p_149636_1_.setBlock(posX + 9, posY + 9, posZ + 0, Blocks.bedrock, 0, 3);
		p_149636_1_.setBlock(posX + 0, posY + 9, posZ + 1, Blocks.bedrock, 0, 3);
		p_149636_1_.setBlock(posX + 1, posY + 9, posZ + 1, Blocks.lava, 8, 3);
		p_149636_1_.setBlock(posX + 2, posY + 9, posZ + 1, Blocks.nether_brick, 0, 3);
		p_149636_1_.setBlock(posX + 3, posY + 9, posZ + 1, Blocks.nether_brick, 0, 3);
		p_149636_1_.setBlock(posX + 4, posY + 9, posZ + 1, Blocks.lava, 8, 3);
		p_149636_1_.setBlock(posX + 5, posY + 9, posZ + 1, Blocks.lava, 8, 3);
		p_149636_1_.setBlock(posX + 6, posY + 9, posZ + 1, Blocks.nether_brick, 0, 3);
		p_149636_1_.setBlock(posX + 7, posY + 9, posZ + 1, Blocks.nether_brick, 0, 3);
		p_149636_1_.setBlock(posX + 8, posY + 9, posZ + 1, Blocks.lava, 8, 3);
		p_149636_1_.setBlock(posX + 9, posY + 9, posZ + 1, Blocks.bedrock, 0, 3);
		p_149636_1_.setBlock(posX + 0, posY + 9, posZ + 2, Blocks.bedrock, 0, 3);
		p_149636_1_.setBlock(posX + 1, posY + 9, posZ + 2, Blocks.nether_brick, 0, 3);
		p_149636_1_.setBlock(posX + 2, posY + 9, posZ + 2, Blocks.lava, 0, 3);
		p_149636_1_.setBlock(posX + 3, posY + 9, posZ + 2, Blocks.nether_brick, 0, 3);
		p_149636_1_.setBlock(posX + 4, posY + 9, posZ + 2, Blocks.nether_brick, 0, 3);
		p_149636_1_.setBlock(posX + 5, posY + 9, posZ + 2, Blocks.nether_brick, 0, 3);
		p_149636_1_.setBlock(posX + 6, posY + 9, posZ + 2, Blocks.nether_brick, 0, 3);
		p_149636_1_.setBlock(posX + 7, posY + 9, posZ + 2, Blocks.lava, 0, 3);
		p_149636_1_.setBlock(posX + 8, posY + 9, posZ + 2, Blocks.nether_brick, 0, 3);
		p_149636_1_.setBlock(posX + 9, posY + 9, posZ + 2, Blocks.bedrock, 0, 3);
		p_149636_1_.setBlock(posX + 0, posY + 9, posZ + 3, Blocks.bedrock, 0, 3);
		p_149636_1_.setBlock(posX + 1, posY + 9, posZ + 3, Blocks.nether_brick, 0, 3);
		p_149636_1_.setBlock(posX + 2, posY + 9, posZ + 3, Blocks.nether_brick, 0, 3);
		p_149636_1_.setBlock(posX + 3, posY + 9, posZ + 3, Blocks.nether_brick, 0, 3);
		p_149636_1_.setBlock(posX + 4, posY + 9, posZ + 3, Blocks.nether_brick, 0, 3);
		p_149636_1_.setBlock(posX + 5, posY + 9, posZ + 3, Blocks.nether_brick, 0, 3);
		p_149636_1_.setBlock(posX + 6, posY + 9, posZ + 3, Blocks.nether_brick, 0, 3);
		p_149636_1_.setBlock(posX + 7, posY + 9, posZ + 3, Blocks.nether_brick, 0, 3);
		p_149636_1_.setBlock(posX + 8, posY + 9, posZ + 3, Blocks.nether_brick, 0, 3);
		p_149636_1_.setBlock(posX + 9, posY + 9, posZ + 3, Blocks.bedrock, 0, 3);
		p_149636_1_.setBlock(posX + 0, posY + 9, posZ + 4, Blocks.bedrock, 0, 3);
		p_149636_1_.setBlock(posX + 1, posY + 9, posZ + 4, Blocks.lava, 8, 3);
		p_149636_1_.setBlock(posX + 2, posY + 9, posZ + 4, Blocks.nether_brick, 0, 3);
		p_149636_1_.setBlock(posX + 3, posY + 9, posZ + 4, Blocks.nether_brick, 0, 3);
		p_149636_1_.setBlock(posX + 4, posY + 9, posZ + 4, Blocks.nether_brick, 0, 3);
		p_149636_1_.setBlock(posX + 5, posY + 9, posZ + 4, Blocks.nether_brick, 0, 3);
		p_149636_1_.setBlock(posX + 6, posY + 9, posZ + 4, Blocks.nether_brick, 0, 3);
		p_149636_1_.setBlock(posX + 7, posY + 9, posZ + 4, Blocks.nether_brick, 0, 3);
		p_149636_1_.setBlock(posX + 8, posY + 9, posZ + 4, Blocks.lava, 8, 3);
		p_149636_1_.setBlock(posX + 9, posY + 9, posZ + 4, Blocks.bedrock, 0, 3);
		p_149636_1_.setBlock(posX + 0, posY + 9, posZ + 5, Blocks.bedrock, 0, 3);
		p_149636_1_.setBlock(posX + 1, posY + 9, posZ + 5, Blocks.lava, 8, 3);
		p_149636_1_.setBlock(posX + 2, posY + 9, posZ + 5, Blocks.nether_brick, 0, 3);
		p_149636_1_.setBlock(posX + 3, posY + 9, posZ + 5, Blocks.nether_brick, 0, 3);
		p_149636_1_.setBlock(posX + 4, posY + 9, posZ + 5, Blocks.nether_brick, 0, 3);
		p_149636_1_.setBlock(posX + 5, posY + 9, posZ + 5, Blocks.nether_brick, 0, 3);
		p_149636_1_.setBlock(posX + 6, posY + 9, posZ + 5, Blocks.nether_brick, 0, 3);
		p_149636_1_.setBlock(posX + 7, posY + 9, posZ + 5, Blocks.nether_brick, 0, 3);
		p_149636_1_.setBlock(posX + 8, posY + 9, posZ + 5, Blocks.lava, 8, 3);
		p_149636_1_.setBlock(posX + 9, posY + 9, posZ + 5, Blocks.bedrock, 0, 3);
		p_149636_1_.setBlock(posX + 0, posY + 9, posZ + 6, Blocks.bedrock, 0, 3);
		p_149636_1_.setBlock(posX + 1, posY + 9, posZ + 6, Blocks.nether_brick, 0, 3);
		p_149636_1_.setBlock(posX + 2, posY + 9, posZ + 6, Blocks.nether_brick, 0, 3);
		p_149636_1_.setBlock(posX + 3, posY + 9, posZ + 6, Blocks.nether_brick, 0, 3);
		p_149636_1_.setBlock(posX + 4, posY + 9, posZ + 6, Blocks.nether_brick, 0, 3);
		p_149636_1_.setBlock(posX + 5, posY + 9, posZ + 6, Blocks.nether_brick, 0, 3);
		p_149636_1_.setBlock(posX + 6, posY + 9, posZ + 6, Blocks.nether_brick, 0, 3);
		p_149636_1_.setBlock(posX + 7, posY + 9, posZ + 6, Blocks.nether_brick, 0, 3);
		p_149636_1_.setBlock(posX + 8, posY + 9, posZ + 6, Blocks.nether_brick, 0, 3);
		p_149636_1_.setBlock(posX + 9, posY + 9, posZ + 6, Blocks.bedrock, 0, 3);
		p_149636_1_.setBlock(posX + 0, posY + 9, posZ + 7, Blocks.bedrock, 0, 3);
		p_149636_1_.setBlock(posX + 1, posY + 9, posZ + 7, Blocks.nether_brick, 0, 3);
		p_149636_1_.setBlock(posX + 2, posY + 9, posZ + 7, Blocks.lava, 0, 3);
		p_149636_1_.setBlock(posX + 3, posY + 9, posZ + 7, Blocks.nether_brick, 0, 3);
		p_149636_1_.setBlock(posX + 4, posY + 9, posZ + 7, Blocks.nether_brick, 0, 3);
		p_149636_1_.setBlock(posX + 5, posY + 9, posZ + 7, Blocks.nether_brick, 0, 3);
		p_149636_1_.setBlock(posX + 6, posY + 9, posZ + 7, Blocks.nether_brick, 0, 3);
		p_149636_1_.setBlock(posX + 7, posY + 9, posZ + 7, Blocks.lava, 0, 3);
		p_149636_1_.setBlock(posX + 8, posY + 9, posZ + 7, Blocks.nether_brick, 0, 3);
		p_149636_1_.setBlock(posX + 9, posY + 9, posZ + 7, Blocks.bedrock, 0, 3);
		p_149636_1_.setBlock(posX + 0, posY + 9, posZ + 8, Blocks.bedrock, 0, 3);
		p_149636_1_.setBlock(posX + 1, posY + 9, posZ + 8, Blocks.lava, 8, 3);
		p_149636_1_.setBlock(posX + 2, posY + 9, posZ + 8, Blocks.nether_brick, 0, 3);
		p_149636_1_.setBlock(posX + 3, posY + 9, posZ + 8, Blocks.nether_brick, 0, 3);
		p_149636_1_.setBlock(posX + 4, posY + 9, posZ + 8, Blocks.lava, 8, 3);
		p_149636_1_.setBlock(posX + 5, posY + 9, posZ + 8, Blocks.lava, 8, 3);
		p_149636_1_.setBlock(posX + 6, posY + 9, posZ + 8, Blocks.nether_brick, 0, 3);
		p_149636_1_.setBlock(posX + 7, posY + 9, posZ + 8, Blocks.nether_brick, 0, 3);
		p_149636_1_.setBlock(posX + 8, posY + 9, posZ + 8, Blocks.lava, 8, 3);
		p_149636_1_.setBlock(posX + 9, posY + 9, posZ + 8, Blocks.bedrock, 0, 3);
		p_149636_1_.setBlock(posX + 0, posY + 9, posZ + 9, Blocks.bedrock, 0, 3);
		p_149636_1_.setBlock(posX + 1, posY + 9, posZ + 9, Blocks.bedrock, 0, 3);
		p_149636_1_.setBlock(posX + 2, posY + 9, posZ + 9, Blocks.bedrock, 0, 3);
		p_149636_1_.setBlock(posX + 3, posY + 9, posZ + 9, Blocks.bedrock, 0, 3);
		p_149636_1_.setBlock(posX + 4, posY + 9, posZ + 9, Blocks.bedrock, 0, 3);
		p_149636_1_.setBlock(posX + 5, posY + 9, posZ + 9, Blocks.bedrock, 0, 3);
		p_149636_1_.setBlock(posX + 6, posY + 9, posZ + 9, Blocks.bedrock, 0, 3);
		p_149636_1_.setBlock(posX + 7, posY + 9, posZ + 9, Blocks.bedrock, 0, 3);
		p_149636_1_.setBlock(posX + 8, posY + 9, posZ + 9, Blocks.bedrock, 0, 3);
		p_149636_1_.setBlock(posX + 9, posY + 9, posZ + 9, Blocks.bedrock, 0, 3);
    	

	}

}
