package com.jtrent238.luckyblock.structures.traps;

import net.minecraft.entity.player.EntityPlayer;
import net.minecraft.init.Blocks;
import net.minecraft.world.World;

public class TntTrap {

    public static void createTrap(World world, EntityPlayer p_149636_2_) {

        int tnt_trap_0_posX = (int) p_149636_2_.posX - 6;
        int tnt_trap_0_posY = (int) p_149636_2_.posY - 1;
        int tnt_trap_0_posZ = (int) p_149636_2_.posZ - 5;

        world.setBlock(tnt_trap_0_posX + 0, tnt_trap_0_posY + 0, tnt_trap_0_posZ + 0, Blocks.grass, 0, 3);
        world.setBlock(tnt_trap_0_posX + 1, tnt_trap_0_posY + 0, tnt_trap_0_posZ + 0, Blocks.grass, 0, 3);
        world.setBlock(tnt_trap_0_posX + 2, tnt_trap_0_posY + 0, tnt_trap_0_posZ + 0, Blocks.grass, 0, 3);
        world.setBlock(tnt_trap_0_posX + 3, tnt_trap_0_posY + 0, tnt_trap_0_posZ + 0, Blocks.grass, 0, 3);
        world.setBlock(tnt_trap_0_posX + 4, tnt_trap_0_posY + 0, tnt_trap_0_posZ + 0, Blocks.grass, 0, 3);
        world.setBlock(tnt_trap_0_posX + 5, tnt_trap_0_posY + 0, tnt_trap_0_posZ + 0, Blocks.grass, 0, 3);
        world.setBlock(tnt_trap_0_posX + 6, tnt_trap_0_posY + 0, tnt_trap_0_posZ + 0, Blocks.grass, 0, 3);
        world.setBlock(tnt_trap_0_posX + 7, tnt_trap_0_posY + 0, tnt_trap_0_posZ + 0, Blocks.grass, 0, 3);
        world.setBlock(tnt_trap_0_posX + 8, tnt_trap_0_posY + 0, tnt_trap_0_posZ + 0, Blocks.grass, 0, 3);
        world.setBlock(tnt_trap_0_posX + 9, tnt_trap_0_posY + 0, tnt_trap_0_posZ + 0, Blocks.grass, 0, 3);
        world.setBlock(tnt_trap_0_posX + 10, tnt_trap_0_posY + 0, tnt_trap_0_posZ + 0, Blocks.grass, 0, 3);
        world.setBlock(tnt_trap_0_posX + 11, tnt_trap_0_posY + 0, tnt_trap_0_posZ + 0, Blocks.grass, 0, 3);
        world.setBlock(tnt_trap_0_posX + 0, tnt_trap_0_posY + 0, tnt_trap_0_posZ + 1, Blocks.grass, 0, 3);
        world.setBlock(tnt_trap_0_posX + 1, tnt_trap_0_posY + 0, tnt_trap_0_posZ + 1, Blocks.dirt, 0, 3);
        world.setBlock(tnt_trap_0_posX + 2, tnt_trap_0_posY + 0, tnt_trap_0_posZ + 1, Blocks.grass, 0, 3);
        world.setBlock(tnt_trap_0_posX + 3, tnt_trap_0_posY + 0, tnt_trap_0_posZ + 1, Blocks.dirt, 0, 3);
        world.setBlock(tnt_trap_0_posX + 4, tnt_trap_0_posY + 0, tnt_trap_0_posZ + 1, Blocks.grass, 0, 3);
        world.setBlock(tnt_trap_0_posX + 5, tnt_trap_0_posY + 0, tnt_trap_0_posZ + 1, Blocks.grass, 0, 3);
        world.setBlock(tnt_trap_0_posX + 6, tnt_trap_0_posY + 0, tnt_trap_0_posZ + 1, Blocks.grass, 0, 3);
        world.setBlock(tnt_trap_0_posX + 7, tnt_trap_0_posY + 0, tnt_trap_0_posZ + 1, Blocks.dirt, 0, 3);
        world.setBlock(tnt_trap_0_posX + 8, tnt_trap_0_posY + 0, tnt_trap_0_posZ + 1, Blocks.grass, 0, 3);
        world.setBlock(tnt_trap_0_posX + 9, tnt_trap_0_posY + 0, tnt_trap_0_posZ + 1, Blocks.grass, 0, 3);
        world.setBlock(tnt_trap_0_posX + 10, tnt_trap_0_posY + 0, tnt_trap_0_posZ + 1, Blocks.grass, 0, 3);
        world.setBlock(tnt_trap_0_posX + 11, tnt_trap_0_posY + 0, tnt_trap_0_posZ + 1, Blocks.grass, 0, 3);
        world.setBlock(tnt_trap_0_posX + 0, tnt_trap_0_posY + 0, tnt_trap_0_posZ + 2, Blocks.grass, 0, 3);
        world.setBlock(tnt_trap_0_posX + 1, tnt_trap_0_posY + 0, tnt_trap_0_posZ + 2, Blocks.dirt, 0, 3);
        world.setBlock(tnt_trap_0_posX + 2, tnt_trap_0_posY + 0, tnt_trap_0_posZ + 2, Blocks.tnt, 0, 3);
        world.setBlock(tnt_trap_0_posX + 3, tnt_trap_0_posY + 0, tnt_trap_0_posZ + 2, Blocks.tnt, 0, 3);
        world.setBlock(tnt_trap_0_posX + 4, tnt_trap_0_posY + 0, tnt_trap_0_posZ + 2, Blocks.tnt, 0, 3);
        world.setBlock(tnt_trap_0_posX + 5, tnt_trap_0_posY + 0, tnt_trap_0_posZ + 2, Blocks.tnt, 0, 3);
        world.setBlock(tnt_trap_0_posX + 6, tnt_trap_0_posY + 0, tnt_trap_0_posZ + 2, Blocks.tnt, 0, 3);
        world.setBlock(tnt_trap_0_posX + 7, tnt_trap_0_posY + 0, tnt_trap_0_posZ + 2, Blocks.tnt, 0, 3);
        world.setBlock(tnt_trap_0_posX + 8, tnt_trap_0_posY + 0, tnt_trap_0_posZ + 2, Blocks.tnt, 0, 3);
        world.setBlock(tnt_trap_0_posX + 9, tnt_trap_0_posY + 0, tnt_trap_0_posZ + 2, Blocks.tnt, 0, 3);
        world.setBlock(tnt_trap_0_posX + 10, tnt_trap_0_posY + 0, tnt_trap_0_posZ + 2, Blocks.grass, 0, 3);
        world.setBlock(tnt_trap_0_posX + 11, tnt_trap_0_posY + 0, tnt_trap_0_posZ + 2, Blocks.grass, 0, 3);
        world.setBlock(tnt_trap_0_posX + 0, tnt_trap_0_posY + 0, tnt_trap_0_posZ + 3, Blocks.grass, 0, 3);
        world.setBlock(tnt_trap_0_posX + 1, tnt_trap_0_posY + 0, tnt_trap_0_posZ + 3, Blocks.dirt, 0, 3);
        world.setBlock(tnt_trap_0_posX + 2, tnt_trap_0_posY + 0, tnt_trap_0_posZ + 3, Blocks.tnt, 0, 3);
        world.setBlock(tnt_trap_0_posX + 3, tnt_trap_0_posY + 0, tnt_trap_0_posZ + 3, Blocks.tnt, 0, 3);
        world.setBlock(tnt_trap_0_posX + 4, tnt_trap_0_posY + 0, tnt_trap_0_posZ + 3, Blocks.tnt, 0, 3);
        world.setBlock(tnt_trap_0_posX + 5, tnt_trap_0_posY + 0, tnt_trap_0_posZ + 3, Blocks.tnt, 0, 3);
        world.setBlock(tnt_trap_0_posX + 6, tnt_trap_0_posY + 0, tnt_trap_0_posZ + 3, Blocks.tnt, 0, 3);
        world.setBlock(tnt_trap_0_posX + 7, tnt_trap_0_posY + 0, tnt_trap_0_posZ + 3, Blocks.tnt, 0, 3);
        world.setBlock(tnt_trap_0_posX + 8, tnt_trap_0_posY + 0, tnt_trap_0_posZ + 3, Blocks.tnt, 0, 3);
        world.setBlock(tnt_trap_0_posX + 9, tnt_trap_0_posY + 0, tnt_trap_0_posZ + 3, Blocks.tnt, 0, 3);
        world.setBlock(tnt_trap_0_posX + 10, tnt_trap_0_posY + 0, tnt_trap_0_posZ + 3, Blocks.grass, 0, 3);
        world.setBlock(tnt_trap_0_posX + 11, tnt_trap_0_posY + 0, tnt_trap_0_posZ + 3, Blocks.grass, 0, 3);
        world.setBlock(tnt_trap_0_posX + 0, tnt_trap_0_posY + 0, tnt_trap_0_posZ + 4, Blocks.grass, 0, 3);
        world.setBlock(tnt_trap_0_posX + 1, tnt_trap_0_posY + 0, tnt_trap_0_posZ + 4, Blocks.dirt, 0, 3);
        world.setBlock(tnt_trap_0_posX + 2, tnt_trap_0_posY + 0, tnt_trap_0_posZ + 4, Blocks.tnt, 0, 3);
        world.setBlock(tnt_trap_0_posX + 3, tnt_trap_0_posY + 0, tnt_trap_0_posZ + 4, Blocks.tnt, 0, 3);
        world.setBlock(tnt_trap_0_posX + 4, tnt_trap_0_posY + 0, tnt_trap_0_posZ + 4, Blocks.tnt, 0, 3);
        world.setBlock(tnt_trap_0_posX + 5, tnt_trap_0_posY + 0, tnt_trap_0_posZ + 4, Blocks.tnt, 0, 3);
        world.setBlock(tnt_trap_0_posX + 6, tnt_trap_0_posY + 0, tnt_trap_0_posZ + 4, Blocks.tnt, 0, 3);
        world.setBlock(tnt_trap_0_posX + 7, tnt_trap_0_posY + 0, tnt_trap_0_posZ + 4, Blocks.tnt, 0, 3);
        world.setBlock(tnt_trap_0_posX + 8, tnt_trap_0_posY + 0, tnt_trap_0_posZ + 4, Blocks.tnt, 0, 3);
        world.setBlock(tnt_trap_0_posX + 9, tnt_trap_0_posY + 0, tnt_trap_0_posZ + 4, Blocks.tnt, 0, 3);
        world.setBlock(tnt_trap_0_posX + 10, tnt_trap_0_posY + 0, tnt_trap_0_posZ + 4, Blocks.dirt, 0, 3);
        world.setBlock(tnt_trap_0_posX + 11, tnt_trap_0_posY + 0, tnt_trap_0_posZ + 4, Blocks.grass, 0, 3);
        world.setBlock(tnt_trap_0_posX + 0, tnt_trap_0_posY + 0, tnt_trap_0_posZ + 5, Blocks.grass, 0, 3);
        world.setBlock(tnt_trap_0_posX + 1, tnt_trap_0_posY + 0, tnt_trap_0_posZ + 5, Blocks.grass, 0, 3);
        world.setBlock(tnt_trap_0_posX + 2, tnt_trap_0_posY + 0, tnt_trap_0_posZ + 5, Blocks.tnt, 0, 3);
        world.setBlock(tnt_trap_0_posX + 3, tnt_trap_0_posY + 0, tnt_trap_0_posZ + 5, Blocks.tnt, 0, 3);
        world.setBlock(tnt_trap_0_posX + 4, tnt_trap_0_posY + 0, tnt_trap_0_posZ + 5, Blocks.tnt, 0, 3);
        world.setBlock(tnt_trap_0_posX + 5, tnt_trap_0_posY + 0, tnt_trap_0_posZ + 5, Blocks.tnt, 0, 3);
        world.setBlock(tnt_trap_0_posX + 6, tnt_trap_0_posY + 0, tnt_trap_0_posZ + 5, Blocks.tnt, 0, 3);
        world.setBlock(tnt_trap_0_posX + 7, tnt_trap_0_posY + 0, tnt_trap_0_posZ + 5, Blocks.tnt, 0, 3);
        world.setBlock(tnt_trap_0_posX + 8, tnt_trap_0_posY + 0, tnt_trap_0_posZ + 5, Blocks.tnt, 0, 3);
        world.setBlock(tnt_trap_0_posX + 9, tnt_trap_0_posY + 0, tnt_trap_0_posZ + 5, Blocks.tnt, 0, 3);
        world.setBlock(tnt_trap_0_posX + 10, tnt_trap_0_posY + 0, tnt_trap_0_posZ + 5, Blocks.grass, 0, 3);
        world.setBlock(tnt_trap_0_posX + 11, tnt_trap_0_posY + 0, tnt_trap_0_posZ + 5, Blocks.grass, 0, 3);
        world.setBlock(tnt_trap_0_posX + 0, tnt_trap_0_posY + 0, tnt_trap_0_posZ + 6, Blocks.grass, 0, 3);
        world.setBlock(tnt_trap_0_posX + 1, tnt_trap_0_posY + 0, tnt_trap_0_posZ + 6, Blocks.dirt, 0, 3);
        world.setBlock(tnt_trap_0_posX + 2, tnt_trap_0_posY + 0, tnt_trap_0_posZ + 6, Blocks.tnt, 0, 3);
        world.setBlock(tnt_trap_0_posX + 3, tnt_trap_0_posY + 0, tnt_trap_0_posZ + 6, Blocks.tnt, 0, 3);
        world.setBlock(tnt_trap_0_posX + 4, tnt_trap_0_posY + 0, tnt_trap_0_posZ + 6, Blocks.tnt, 0, 3);
        world.setBlock(tnt_trap_0_posX + 5, tnt_trap_0_posY + 0, tnt_trap_0_posZ + 6, Blocks.tnt, 0, 3);
        world.setBlock(tnt_trap_0_posX + 6, tnt_trap_0_posY + 0, tnt_trap_0_posZ + 6, Blocks.tnt, 0, 3);
        world.setBlock(tnt_trap_0_posX + 7, tnt_trap_0_posY + 0, tnt_trap_0_posZ + 6, Blocks.tnt, 0, 3);
        world.setBlock(tnt_trap_0_posX + 8, tnt_trap_0_posY + 0, tnt_trap_0_posZ + 6, Blocks.tnt, 0, 3);
        world.setBlock(tnt_trap_0_posX + 9, tnt_trap_0_posY + 0, tnt_trap_0_posZ + 6, Blocks.tnt, 0, 3);
        world.setBlock(tnt_trap_0_posX + 10, tnt_trap_0_posY + 0, tnt_trap_0_posZ + 6, Blocks.dirt, 0, 3);
        world.setBlock(tnt_trap_0_posX + 11, tnt_trap_0_posY + 0, tnt_trap_0_posZ + 6, Blocks.grass, 0, 3);
        world.setBlock(tnt_trap_0_posX + 0, tnt_trap_0_posY + 0, tnt_trap_0_posZ + 7, Blocks.grass, 0, 3);
        world.setBlock(tnt_trap_0_posX + 1, tnt_trap_0_posY + 0, tnt_trap_0_posZ + 7, Blocks.dirt, 0, 3);
        world.setBlock(tnt_trap_0_posX + 2, tnt_trap_0_posY + 0, tnt_trap_0_posZ + 7, Blocks.tnt, 0, 3);
        world.setBlock(tnt_trap_0_posX + 3, tnt_trap_0_posY + 0, tnt_trap_0_posZ + 7, Blocks.tnt, 0, 3);
        world.setBlock(tnt_trap_0_posX + 4, tnt_trap_0_posY + 0, tnt_trap_0_posZ + 7, Blocks.tnt, 0, 3);
        world.setBlock(tnt_trap_0_posX + 5, tnt_trap_0_posY + 0, tnt_trap_0_posZ + 7, Blocks.tnt, 0, 3);
        world.setBlock(tnt_trap_0_posX + 6, tnt_trap_0_posY + 0, tnt_trap_0_posZ + 7, Blocks.tnt, 0, 3);
        world.setBlock(tnt_trap_0_posX + 7, tnt_trap_0_posY + 0, tnt_trap_0_posZ + 7, Blocks.tnt, 0, 3);
        world.setBlock(tnt_trap_0_posX + 8, tnt_trap_0_posY + 0, tnt_trap_0_posZ + 7, Blocks.tnt, 0, 3);
        world.setBlock(tnt_trap_0_posX + 9, tnt_trap_0_posY + 0, tnt_trap_0_posZ + 7, Blocks.tnt, 0, 3);
        world.setBlock(tnt_trap_0_posX + 10, tnt_trap_0_posY + 0, tnt_trap_0_posZ + 7, Blocks.dirt, 0, 3);
        world.setBlock(tnt_trap_0_posX + 11, tnt_trap_0_posY + 0, tnt_trap_0_posZ + 7, Blocks.grass, 0, 3);
        world.setBlock(tnt_trap_0_posX + 0, tnt_trap_0_posY + 0, tnt_trap_0_posZ + 8, Blocks.grass, 0, 3);
        world.setBlock(tnt_trap_0_posX + 1, tnt_trap_0_posY + 0, tnt_trap_0_posZ + 8, Blocks.dirt, 0, 3);
        world.setBlock(tnt_trap_0_posX + 2, tnt_trap_0_posY + 0, tnt_trap_0_posZ + 8, Blocks.tnt, 0, 3);
        world.setBlock(tnt_trap_0_posX + 3, tnt_trap_0_posY + 0, tnt_trap_0_posZ + 8, Blocks.tnt, 0, 3);
        world.setBlock(tnt_trap_0_posX + 4, tnt_trap_0_posY + 0, tnt_trap_0_posZ + 8, Blocks.tnt, 0, 3);
        world.setBlock(tnt_trap_0_posX + 5, tnt_trap_0_posY + 0, tnt_trap_0_posZ + 8, Blocks.tnt, 0, 3);
        world.setBlock(tnt_trap_0_posX + 6, tnt_trap_0_posY + 0, tnt_trap_0_posZ + 8, Blocks.tnt, 0, 3);
        world.setBlock(tnt_trap_0_posX + 7, tnt_trap_0_posY + 0, tnt_trap_0_posZ + 8, Blocks.tnt, 0, 3);
        world.setBlock(tnt_trap_0_posX + 8, tnt_trap_0_posY + 0, tnt_trap_0_posZ + 8, Blocks.tnt, 0, 3);
        world.setBlock(tnt_trap_0_posX + 9, tnt_trap_0_posY + 0, tnt_trap_0_posZ + 8, Blocks.tnt, 0, 3);
        world.setBlock(tnt_trap_0_posX + 10, tnt_trap_0_posY + 0, tnt_trap_0_posZ + 8, Blocks.grass, 0, 3);
        world.setBlock(tnt_trap_0_posX + 11, tnt_trap_0_posY + 0, tnt_trap_0_posZ + 8, Blocks.grass, 0, 3);
        world.setBlock(tnt_trap_0_posX + 0, tnt_trap_0_posY + 0, tnt_trap_0_posZ + 9, Blocks.grass, 0, 3);
        world.setBlock(tnt_trap_0_posX + 1, tnt_trap_0_posY + 0, tnt_trap_0_posZ + 9, Blocks.dirt, 0, 3);
        world.setBlock(tnt_trap_0_posX + 2, tnt_trap_0_posY + 0, tnt_trap_0_posZ + 9, Blocks.tnt, 0, 3);
        world.setBlock(tnt_trap_0_posX + 3, tnt_trap_0_posY + 0, tnt_trap_0_posZ + 9, Blocks.tnt, 0, 3);
        world.setBlock(tnt_trap_0_posX + 4, tnt_trap_0_posY + 0, tnt_trap_0_posZ + 9, Blocks.tnt, 0, 3);
        world.setBlock(tnt_trap_0_posX + 5, tnt_trap_0_posY + 0, tnt_trap_0_posZ + 9, Blocks.tnt, 0, 3);
        world.setBlock(tnt_trap_0_posX + 6, tnt_trap_0_posY + 0, tnt_trap_0_posZ + 9, Blocks.tnt, 0, 3);
        world.setBlock(tnt_trap_0_posX + 7, tnt_trap_0_posY + 0, tnt_trap_0_posZ + 9, Blocks.tnt, 0, 3);
        world.setBlock(tnt_trap_0_posX + 8, tnt_trap_0_posY + 0, tnt_trap_0_posZ + 9, Blocks.tnt, 0, 3);
        world.setBlock(tnt_trap_0_posX + 9, tnt_trap_0_posY + 0, tnt_trap_0_posZ + 9, Blocks.tnt, 0, 3);
        world.setBlock(tnt_trap_0_posX + 10, tnt_trap_0_posY + 0, tnt_trap_0_posZ + 9, Blocks.dirt, 0, 3);
        world.setBlock(tnt_trap_0_posX + 11, tnt_trap_0_posY + 0, tnt_trap_0_posZ + 9, Blocks.grass, 0, 3);
        world.setBlock(tnt_trap_0_posX + 0, tnt_trap_0_posY + 0, tnt_trap_0_posZ + 10, Blocks.grass, 0, 3);
        world.setBlock(tnt_trap_0_posX + 1, tnt_trap_0_posY + 0, tnt_trap_0_posZ + 10, Blocks.dirt, 0, 3);
        world.setBlock(tnt_trap_0_posX + 2, tnt_trap_0_posY + 0, tnt_trap_0_posZ + 10, Blocks.dirt, 0, 3);
        world.setBlock(tnt_trap_0_posX + 3, tnt_trap_0_posY + 0, tnt_trap_0_posZ + 10, Blocks.grass, 0, 3);
        world.setBlock(tnt_trap_0_posX + 4, tnt_trap_0_posY + 0, tnt_trap_0_posZ + 10, Blocks.grass, 0, 3);
        world.setBlock(tnt_trap_0_posX + 5, tnt_trap_0_posY + 0, tnt_trap_0_posZ + 10, Blocks.dirt, 0, 3);
        world.setBlock(tnt_trap_0_posX + 6, tnt_trap_0_posY + 0, tnt_trap_0_posZ + 10, Blocks.grass, 0, 3);
        world.setBlock(tnt_trap_0_posX + 7, tnt_trap_0_posY + 0, tnt_trap_0_posZ + 10, Blocks.dirt, 0, 3);
        world.setBlock(tnt_trap_0_posX + 8, tnt_trap_0_posY + 0, tnt_trap_0_posZ + 10, Blocks.dirt, 0, 3);
        world.setBlock(tnt_trap_0_posX + 9, tnt_trap_0_posY + 0, tnt_trap_0_posZ + 10, Blocks.dirt, 0, 3);
        world.setBlock(tnt_trap_0_posX + 10, tnt_trap_0_posY + 0, tnt_trap_0_posZ + 10, Blocks.grass, 0, 3);
        world.setBlock(tnt_trap_0_posX + 11, tnt_trap_0_posY + 0, tnt_trap_0_posZ + 10, Blocks.grass, 0, 3);
        world.setBlock(tnt_trap_0_posX + 0, tnt_trap_0_posY + 0, tnt_trap_0_posZ + 11, Blocks.grass, 0, 3);
        world.setBlock(tnt_trap_0_posX + 1, tnt_trap_0_posY + 0, tnt_trap_0_posZ + 11, Blocks.grass, 0, 3);
        world.setBlock(tnt_trap_0_posX + 2, tnt_trap_0_posY + 0, tnt_trap_0_posZ + 11, Blocks.grass, 0, 3);
        world.setBlock(tnt_trap_0_posX + 3, tnt_trap_0_posY + 0, tnt_trap_0_posZ + 11, Blocks.grass, 0, 3);
        world.setBlock(tnt_trap_0_posX + 4, tnt_trap_0_posY + 0, tnt_trap_0_posZ + 11, Blocks.grass, 0, 3);
        world.setBlock(tnt_trap_0_posX + 5, tnt_trap_0_posY + 0, tnt_trap_0_posZ + 11, Blocks.grass, 0, 3);
        world.setBlock(tnt_trap_0_posX + 6, tnt_trap_0_posY + 0, tnt_trap_0_posZ + 11, Blocks.grass, 0, 3);
        world.setBlock(tnt_trap_0_posX + 7, tnt_trap_0_posY + 0, tnt_trap_0_posZ + 11, Blocks.grass, 0, 3);
        world.setBlock(tnt_trap_0_posX + 8, tnt_trap_0_posY + 0, tnt_trap_0_posZ + 11, Blocks.grass, 0, 3);
        world.setBlock(tnt_trap_0_posX + 9, tnt_trap_0_posY + 0, tnt_trap_0_posZ + 11, Blocks.grass, 0, 3);
        world.setBlock(tnt_trap_0_posX + 10, tnt_trap_0_posY + 0, tnt_trap_0_posZ + 11, Blocks.grass, 0, 3);
        world.setBlock(tnt_trap_0_posX + 11, tnt_trap_0_posY + 0, tnt_trap_0_posZ + 11, Blocks.grass, 0, 3);
        world.setBlock(tnt_trap_0_posX + 0, tnt_trap_0_posY + 1, tnt_trap_0_posZ + 0, Blocks.air, 0, 3);
        world.setBlock(tnt_trap_0_posX + 1, tnt_trap_0_posY + 1, tnt_trap_0_posZ + 0, Blocks.air, 0, 3);
        world.setBlock(tnt_trap_0_posX + 2, tnt_trap_0_posY + 1, tnt_trap_0_posZ + 0, Blocks.air, 0, 3);
        world.setBlock(tnt_trap_0_posX + 3, tnt_trap_0_posY + 1, tnt_trap_0_posZ + 0, Blocks.air, 0, 3);
        world.setBlock(tnt_trap_0_posX + 4, tnt_trap_0_posY + 1, tnt_trap_0_posZ + 0, Blocks.air, 0, 3);
        world.setBlock(tnt_trap_0_posX + 5, tnt_trap_0_posY + 1, tnt_trap_0_posZ + 0, Blocks.air, 0, 3);
        world.setBlock(tnt_trap_0_posX + 6, tnt_trap_0_posY + 1, tnt_trap_0_posZ + 0, Blocks.air, 0, 3);
        world.setBlock(tnt_trap_0_posX + 7, tnt_trap_0_posY + 1, tnt_trap_0_posZ + 0, Blocks.air, 0, 3);
        world.setBlock(tnt_trap_0_posX + 8, tnt_trap_0_posY + 1, tnt_trap_0_posZ + 0, Blocks.air, 0, 3);
        world.setBlock(tnt_trap_0_posX + 9, tnt_trap_0_posY + 1, tnt_trap_0_posZ + 0, Blocks.air, 0, 3);
        world.setBlock(tnt_trap_0_posX + 10, tnt_trap_0_posY + 1, tnt_trap_0_posZ + 0, Blocks.air, 0, 3);
        world.setBlock(tnt_trap_0_posX + 11, tnt_trap_0_posY + 1, tnt_trap_0_posZ + 0, Blocks.air, 0, 3);
        world.setBlock(tnt_trap_0_posX + 0, tnt_trap_0_posY + 1, tnt_trap_0_posZ + 1, Blocks.air, 0, 3);
        world.setBlock(tnt_trap_0_posX + 1, tnt_trap_0_posY + 1, tnt_trap_0_posZ + 1, Blocks.redstone_block, 0, 3);
        world.setBlock(tnt_trap_0_posX + 2, tnt_trap_0_posY + 1, tnt_trap_0_posZ + 1, Blocks.redstone_block, 0, 3);
        world.setBlock(tnt_trap_0_posX + 3, tnt_trap_0_posY + 1, tnt_trap_0_posZ + 1, Blocks.redstone_block, 0, 3);
        world.setBlock(tnt_trap_0_posX + 4, tnt_trap_0_posY + 1, tnt_trap_0_posZ + 1, Blocks.redstone_block, 0, 3);
        world.setBlock(tnt_trap_0_posX + 5, tnt_trap_0_posY + 1, tnt_trap_0_posZ + 1, Blocks.redstone_block, 0, 3);
        world.setBlock(tnt_trap_0_posX + 6, tnt_trap_0_posY + 1, tnt_trap_0_posZ + 1, Blocks.redstone_block, 0, 3);
        world.setBlock(tnt_trap_0_posX + 7, tnt_trap_0_posY + 1, tnt_trap_0_posZ + 1, Blocks.redstone_block, 0, 3);
        world.setBlock(tnt_trap_0_posX + 8, tnt_trap_0_posY + 1, tnt_trap_0_posZ + 1, Blocks.redstone_block, 0, 3);
        world.setBlock(tnt_trap_0_posX + 9, tnt_trap_0_posY + 1, tnt_trap_0_posZ + 1, Blocks.redstone_block, 0, 3);
        world.setBlock(tnt_trap_0_posX + 10, tnt_trap_0_posY + 1, tnt_trap_0_posZ + 1, Blocks.redstone_block, 0, 3);
        world.setBlock(tnt_trap_0_posX + 11, tnt_trap_0_posY + 1, tnt_trap_0_posZ + 1, Blocks.air, 0, 3);
        world.setBlock(tnt_trap_0_posX + 0, tnt_trap_0_posY + 1, tnt_trap_0_posZ + 2, Blocks.air, 0, 3);
        world.setBlock(tnt_trap_0_posX + 1, tnt_trap_0_posY + 1, tnt_trap_0_posZ + 2, Blocks.redstone_block, 0, 3);
        world.setBlock(tnt_trap_0_posX + 2, tnt_trap_0_posY + 1, tnt_trap_0_posZ + 2, Blocks.tnt, 0, 3);
        world.setBlock(tnt_trap_0_posX + 3, tnt_trap_0_posY + 1, tnt_trap_0_posZ + 2, Blocks.tnt, 0, 3);
        world.setBlock(tnt_trap_0_posX + 4, tnt_trap_0_posY + 1, tnt_trap_0_posZ + 2, Blocks.tnt, 0, 3);
        world.setBlock(tnt_trap_0_posX + 5, tnt_trap_0_posY + 1, tnt_trap_0_posZ + 2, Blocks.tnt, 0, 3);
        world.setBlock(tnt_trap_0_posX + 6, tnt_trap_0_posY + 1, tnt_trap_0_posZ + 2, Blocks.tnt, 0, 3);
        world.setBlock(tnt_trap_0_posX + 7, tnt_trap_0_posY + 1, tnt_trap_0_posZ + 2, Blocks.tnt, 0, 3);
        world.setBlock(tnt_trap_0_posX + 8, tnt_trap_0_posY + 1, tnt_trap_0_posZ + 2, Blocks.tnt, 0, 3);
        world.setBlock(tnt_trap_0_posX + 9, tnt_trap_0_posY + 1, tnt_trap_0_posZ + 2, Blocks.tnt, 0, 3);
        world.setBlock(tnt_trap_0_posX + 10, tnt_trap_0_posY + 1, tnt_trap_0_posZ + 2, Blocks.redstone_block, 0, 3);
        world.setBlock(tnt_trap_0_posX + 11, tnt_trap_0_posY + 1, tnt_trap_0_posZ + 2, Blocks.air, 0, 3);
        world.setBlock(tnt_trap_0_posX + 0, tnt_trap_0_posY + 1, tnt_trap_0_posZ + 3, Blocks.air, 0, 3);
        world.setBlock(tnt_trap_0_posX + 1, tnt_trap_0_posY + 1, tnt_trap_0_posZ + 3, Blocks.redstone_block, 0, 3);
        world.setBlock(tnt_trap_0_posX + 2, tnt_trap_0_posY + 1, tnt_trap_0_posZ + 3, Blocks.tnt, 0, 3);
        world.setBlock(tnt_trap_0_posX + 3, tnt_trap_0_posY + 1, tnt_trap_0_posZ + 3, Blocks.diamond_block, 0, 3);
        world.setBlock(tnt_trap_0_posX + 4, tnt_trap_0_posY + 1, tnt_trap_0_posZ + 3, Blocks.diamond_block, 0, 3);
        world.setBlock(tnt_trap_0_posX + 5, tnt_trap_0_posY + 1, tnt_trap_0_posZ + 3, Blocks.diamond_block, 0, 3);
        world.setBlock(tnt_trap_0_posX + 6, tnt_trap_0_posY + 1, tnt_trap_0_posZ + 3, Blocks.diamond_block, 0, 3);
        world.setBlock(tnt_trap_0_posX + 7, tnt_trap_0_posY + 1, tnt_trap_0_posZ + 3, Blocks.diamond_block, 0, 3);
        world.setBlock(tnt_trap_0_posX + 8, tnt_trap_0_posY + 1, tnt_trap_0_posZ + 3, Blocks.diamond_block, 0, 3);
        world.setBlock(tnt_trap_0_posX + 9, tnt_trap_0_posY + 1, tnt_trap_0_posZ + 3, Blocks.tnt, 0, 3);
        world.setBlock(tnt_trap_0_posX + 10, tnt_trap_0_posY + 1, tnt_trap_0_posZ + 3, Blocks.redstone_block, 0, 3);
        world.setBlock(tnt_trap_0_posX + 11, tnt_trap_0_posY + 1, tnt_trap_0_posZ + 3, Blocks.air, 0, 3);
        world.setBlock(tnt_trap_0_posX + 0, tnt_trap_0_posY + 1, tnt_trap_0_posZ + 4, Blocks.air, 0, 3);
        world.setBlock(tnt_trap_0_posX + 1, tnt_trap_0_posY + 1, tnt_trap_0_posZ + 4, Blocks.redstone_block, 0, 3);
        world.setBlock(tnt_trap_0_posX + 2, tnt_trap_0_posY + 1, tnt_trap_0_posZ + 4, Blocks.tnt, 0, 3);
        world.setBlock(tnt_trap_0_posX + 3, tnt_trap_0_posY + 1, tnt_trap_0_posZ + 4, Blocks.diamond_block, 0, 3);
        world.setBlock(tnt_trap_0_posX + 4, tnt_trap_0_posY + 1, tnt_trap_0_posZ + 4, Blocks.emerald_block, 0, 3);
        world.setBlock(tnt_trap_0_posX + 5, tnt_trap_0_posY + 1, tnt_trap_0_posZ + 4, Blocks.emerald_block, 0, 3);
        world.setBlock(tnt_trap_0_posX + 6, tnt_trap_0_posY + 1, tnt_trap_0_posZ + 4, Blocks.emerald_block, 0, 3);
        world.setBlock(tnt_trap_0_posX + 7, tnt_trap_0_posY + 1, tnt_trap_0_posZ + 4, Blocks.emerald_block, 0, 3);
        world.setBlock(tnt_trap_0_posX + 8, tnt_trap_0_posY + 1, tnt_trap_0_posZ + 4, Blocks.diamond_block, 0, 3);
        world.setBlock(tnt_trap_0_posX + 9, tnt_trap_0_posY + 1, tnt_trap_0_posZ + 4, Blocks.tnt, 0, 3);
        world.setBlock(tnt_trap_0_posX + 10, tnt_trap_0_posY + 1, tnt_trap_0_posZ + 4, Blocks.redstone_block, 0, 3);
        world.setBlock(tnt_trap_0_posX + 11, tnt_trap_0_posY + 1, tnt_trap_0_posZ + 4, Blocks.air, 0, 3);
        world.setBlock(tnt_trap_0_posX + 0, tnt_trap_0_posY + 1, tnt_trap_0_posZ + 5, Blocks.air, 0, 3);
        world.setBlock(tnt_trap_0_posX + 1, tnt_trap_0_posY + 1, tnt_trap_0_posZ + 5, Blocks.redstone_block, 0, 3);
        world.setBlock(tnt_trap_0_posX + 2, tnt_trap_0_posY + 1, tnt_trap_0_posZ + 5, Blocks.tnt, 0, 3);
        world.setBlock(tnt_trap_0_posX + 3, tnt_trap_0_posY + 1, tnt_trap_0_posZ + 5, Blocks.diamond_block, 0, 3);
        world.setBlock(tnt_trap_0_posX + 4, tnt_trap_0_posY + 1, tnt_trap_0_posZ + 5, Blocks.emerald_block, 0, 3);
        world.setBlock(tnt_trap_0_posX + 5, tnt_trap_0_posY + 1, tnt_trap_0_posZ + 5, Blocks.gold_block, 0, 3);
        world.setBlock(tnt_trap_0_posX + 6, tnt_trap_0_posY + 1, tnt_trap_0_posZ + 5, Blocks.gold_block, 0, 3);
        world.setBlock(tnt_trap_0_posX + 7, tnt_trap_0_posY + 1, tnt_trap_0_posZ + 5, Blocks.emerald_block, 0, 3);
        world.setBlock(tnt_trap_0_posX + 8, tnt_trap_0_posY + 1, tnt_trap_0_posZ + 5, Blocks.diamond_block, 0, 3);
        world.setBlock(tnt_trap_0_posX + 9, tnt_trap_0_posY + 1, tnt_trap_0_posZ + 5, Blocks.tnt, 0, 3);
        world.setBlock(tnt_trap_0_posX + 10, tnt_trap_0_posY + 1, tnt_trap_0_posZ + 5, Blocks.redstone_block, 0, 3);
        world.setBlock(tnt_trap_0_posX + 11, tnt_trap_0_posY + 1, tnt_trap_0_posZ + 5, Blocks.air, 0, 3);
        world.setBlock(tnt_trap_0_posX + 0, tnt_trap_0_posY + 1, tnt_trap_0_posZ + 6, Blocks.air, 0, 3);
        world.setBlock(tnt_trap_0_posX + 1, tnt_trap_0_posY + 1, tnt_trap_0_posZ + 6, Blocks.redstone_block, 0, 3);
        world.setBlock(tnt_trap_0_posX + 2, tnt_trap_0_posY + 1, tnt_trap_0_posZ + 6, Blocks.tnt, 0, 3);
        world.setBlock(tnt_trap_0_posX + 3, tnt_trap_0_posY + 1, tnt_trap_0_posZ + 6, Blocks.diamond_block, 0, 3);
        world.setBlock(tnt_trap_0_posX + 4, tnt_trap_0_posY + 1, tnt_trap_0_posZ + 6, Blocks.emerald_block, 0, 3);
        world.setBlock(tnt_trap_0_posX + 5, tnt_trap_0_posY + 1, tnt_trap_0_posZ + 6, Blocks.gold_block, 0, 3);
        world.setBlock(tnt_trap_0_posX + 6, tnt_trap_0_posY + 1, tnt_trap_0_posZ + 6, Blocks.gold_block, 0, 3);
        world.setBlock(tnt_trap_0_posX + 7, tnt_trap_0_posY + 1, tnt_trap_0_posZ + 6, Blocks.emerald_block, 0, 3);
        world.setBlock(tnt_trap_0_posX + 8, tnt_trap_0_posY + 1, tnt_trap_0_posZ + 6, Blocks.diamond_block, 0, 3);
        world.setBlock(tnt_trap_0_posX + 9, tnt_trap_0_posY + 1, tnt_trap_0_posZ + 6, Blocks.tnt, 0, 3);
        world.setBlock(tnt_trap_0_posX + 10, tnt_trap_0_posY + 1, tnt_trap_0_posZ + 6, Blocks.redstone_block, 0, 3);
        world.setBlock(tnt_trap_0_posX + 11, tnt_trap_0_posY + 1, tnt_trap_0_posZ + 6, Blocks.air, 0, 3);
        world.setBlock(tnt_trap_0_posX + 0, tnt_trap_0_posY + 1, tnt_trap_0_posZ + 7, Blocks.air, 0, 3);
        world.setBlock(tnt_trap_0_posX + 1, tnt_trap_0_posY + 1, tnt_trap_0_posZ + 7, Blocks.redstone_block, 0, 3);
        world.setBlock(tnt_trap_0_posX + 2, tnt_trap_0_posY + 1, tnt_trap_0_posZ + 7, Blocks.tnt, 0, 3);
        world.setBlock(tnt_trap_0_posX + 3, tnt_trap_0_posY + 1, tnt_trap_0_posZ + 7, Blocks.diamond_block, 0, 3);
        world.setBlock(tnt_trap_0_posX + 4, tnt_trap_0_posY + 1, tnt_trap_0_posZ + 7, Blocks.emerald_block, 0, 3);
        world.setBlock(tnt_trap_0_posX + 5, tnt_trap_0_posY + 1, tnt_trap_0_posZ + 7, Blocks.emerald_block, 0, 3);
        world.setBlock(tnt_trap_0_posX + 6, tnt_trap_0_posY + 1, tnt_trap_0_posZ + 7, Blocks.emerald_block, 0, 3);
        world.setBlock(tnt_trap_0_posX + 7, tnt_trap_0_posY + 1, tnt_trap_0_posZ + 7, Blocks.emerald_block, 0, 3);
        world.setBlock(tnt_trap_0_posX + 8, tnt_trap_0_posY + 1, tnt_trap_0_posZ + 7, Blocks.diamond_block, 0, 3);
        world.setBlock(tnt_trap_0_posX + 9, tnt_trap_0_posY + 1, tnt_trap_0_posZ + 7, Blocks.tnt, 0, 3);
        world.setBlock(tnt_trap_0_posX + 10, tnt_trap_0_posY + 1, tnt_trap_0_posZ + 7, Blocks.redstone_block, 0, 3);
        world.setBlock(tnt_trap_0_posX + 11, tnt_trap_0_posY + 1, tnt_trap_0_posZ + 7, Blocks.air, 0, 3);
        world.setBlock(tnt_trap_0_posX + 0, tnt_trap_0_posY + 1, tnt_trap_0_posZ + 8, Blocks.air, 0, 3);
        world.setBlock(tnt_trap_0_posX + 1, tnt_trap_0_posY + 1, tnt_trap_0_posZ + 8, Blocks.redstone_block, 0, 3);
        world.setBlock(tnt_trap_0_posX + 2, tnt_trap_0_posY + 1, tnt_trap_0_posZ + 8, Blocks.tnt, 0, 3);
        world.setBlock(tnt_trap_0_posX + 3, tnt_trap_0_posY + 1, tnt_trap_0_posZ + 8, Blocks.diamond_block, 0, 3);
        world.setBlock(tnt_trap_0_posX + 4, tnt_trap_0_posY + 1, tnt_trap_0_posZ + 8, Blocks.diamond_block, 0, 3);
        world.setBlock(tnt_trap_0_posX + 5, tnt_trap_0_posY + 1, tnt_trap_0_posZ + 8, Blocks.diamond_block, 0, 3);
        world.setBlock(tnt_trap_0_posX + 6, tnt_trap_0_posY + 1, tnt_trap_0_posZ + 8, Blocks.diamond_block, 0, 3);
        world.setBlock(tnt_trap_0_posX + 7, tnt_trap_0_posY + 1, tnt_trap_0_posZ + 8, Blocks.diamond_block, 0, 3);
        world.setBlock(tnt_trap_0_posX + 8, tnt_trap_0_posY + 1, tnt_trap_0_posZ + 8, Blocks.diamond_block, 0, 3);
        world.setBlock(tnt_trap_0_posX + 9, tnt_trap_0_posY + 1, tnt_trap_0_posZ + 8, Blocks.tnt, 0, 3);
        world.setBlock(tnt_trap_0_posX + 10, tnt_trap_0_posY + 1, tnt_trap_0_posZ + 8, Blocks.redstone_block, 0, 3);
        world.setBlock(tnt_trap_0_posX + 11, tnt_trap_0_posY + 1, tnt_trap_0_posZ + 8, Blocks.air, 0, 3);
        world.setBlock(tnt_trap_0_posX + 0, tnt_trap_0_posY + 1, tnt_trap_0_posZ + 9, Blocks.air, 0, 3);
        world.setBlock(tnt_trap_0_posX + 1, tnt_trap_0_posY + 1, tnt_trap_0_posZ + 9, Blocks.redstone_block, 0, 3);
        world.setBlock(tnt_trap_0_posX + 2, tnt_trap_0_posY + 1, tnt_trap_0_posZ + 9, Blocks.tnt, 0, 3);
        world.setBlock(tnt_trap_0_posX + 3, tnt_trap_0_posY + 1, tnt_trap_0_posZ + 9, Blocks.tnt, 0, 3);
        world.setBlock(tnt_trap_0_posX + 4, tnt_trap_0_posY + 1, tnt_trap_0_posZ + 9, Blocks.tnt, 0, 3);
        world.setBlock(tnt_trap_0_posX + 5, tnt_trap_0_posY + 1, tnt_trap_0_posZ + 9, Blocks.tnt, 0, 3);
        world.setBlock(tnt_trap_0_posX + 6, tnt_trap_0_posY + 1, tnt_trap_0_posZ + 9, Blocks.tnt, 0, 3);
        world.setBlock(tnt_trap_0_posX + 7, tnt_trap_0_posY + 1, tnt_trap_0_posZ + 9, Blocks.tnt, 0, 3);
        world.setBlock(tnt_trap_0_posX + 8, tnt_trap_0_posY + 1, tnt_trap_0_posZ + 9, Blocks.tnt, 0, 3);
        world.setBlock(tnt_trap_0_posX + 9, tnt_trap_0_posY + 1, tnt_trap_0_posZ + 9, Blocks.tnt, 0, 3);
        world.setBlock(tnt_trap_0_posX + 10, tnt_trap_0_posY + 1, tnt_trap_0_posZ + 9, Blocks.redstone_block, 0, 3);
        world.setBlock(tnt_trap_0_posX + 11, tnt_trap_0_posY + 1, tnt_trap_0_posZ + 9, Blocks.air, 0, 3);
        world.setBlock(tnt_trap_0_posX + 0, tnt_trap_0_posY + 1, tnt_trap_0_posZ + 10, Blocks.air, 0, 3);
        world.setBlock(tnt_trap_0_posX + 1, tnt_trap_0_posY + 1, tnt_trap_0_posZ + 10, Blocks.redstone_block, 0, 3);
        world.setBlock(tnt_trap_0_posX + 2, tnt_trap_0_posY + 1, tnt_trap_0_posZ + 10, Blocks.redstone_block, 0, 3);
        world.setBlock(tnt_trap_0_posX + 3, tnt_trap_0_posY + 1, tnt_trap_0_posZ + 10, Blocks.redstone_block, 0, 3);
        world.setBlock(tnt_trap_0_posX + 4, tnt_trap_0_posY + 1, tnt_trap_0_posZ + 10, Blocks.redstone_block, 0, 3);
        world.setBlock(tnt_trap_0_posX + 5, tnt_trap_0_posY + 1, tnt_trap_0_posZ + 10, Blocks.redstone_block, 0, 3);
        world.setBlock(tnt_trap_0_posX + 6, tnt_trap_0_posY + 1, tnt_trap_0_posZ + 10, Blocks.redstone_block, 0, 3);
        world.setBlock(tnt_trap_0_posX + 7, tnt_trap_0_posY + 1, tnt_trap_0_posZ + 10, Blocks.redstone_block, 0, 3);
        world.setBlock(tnt_trap_0_posX + 8, tnt_trap_0_posY + 1, tnt_trap_0_posZ + 10, Blocks.redstone_block, 0, 3);
        world.setBlock(tnt_trap_0_posX + 9, tnt_trap_0_posY + 1, tnt_trap_0_posZ + 10, Blocks.redstone_block, 0, 3);
        world.setBlock(tnt_trap_0_posX + 10, tnt_trap_0_posY + 1, tnt_trap_0_posZ + 10, Blocks.redstone_block, 0, 3);
        world.setBlock(tnt_trap_0_posX + 11, tnt_trap_0_posY + 1, tnt_trap_0_posZ + 10, Blocks.air, 0, 3);
        world.setBlock(tnt_trap_0_posX + 0, tnt_trap_0_posY + 1, tnt_trap_0_posZ + 11, Blocks.air, 0, 3);
        world.setBlock(tnt_trap_0_posX + 1, tnt_trap_0_posY + 1, tnt_trap_0_posZ + 11, Blocks.air, 0, 3);
        world.setBlock(tnt_trap_0_posX + 2, tnt_trap_0_posY + 1, tnt_trap_0_posZ + 11, Blocks.air, 0, 3);
        world.setBlock(tnt_trap_0_posX + 3, tnt_trap_0_posY + 1, tnt_trap_0_posZ + 11, Blocks.air, 0, 3);
        world.setBlock(tnt_trap_0_posX + 4, tnt_trap_0_posY + 1, tnt_trap_0_posZ + 11, Blocks.air, 0, 3);
        world.setBlock(tnt_trap_0_posX + 5, tnt_trap_0_posY + 1, tnt_trap_0_posZ + 11, Blocks.air, 0, 3);
        world.setBlock(tnt_trap_0_posX + 6, tnt_trap_0_posY + 1, tnt_trap_0_posZ + 11, Blocks.air, 0, 3);
        world.setBlock(tnt_trap_0_posX + 7, tnt_trap_0_posY + 1, tnt_trap_0_posZ + 11, Blocks.air, 0, 3);
        world.setBlock(tnt_trap_0_posX + 8, tnt_trap_0_posY + 1, tnt_trap_0_posZ + 11, Blocks.air, 0, 3);
        world.setBlock(tnt_trap_0_posX + 9, tnt_trap_0_posY + 1, tnt_trap_0_posZ + 11, Blocks.air, 0, 3);
        world.setBlock(tnt_trap_0_posX + 10, tnt_trap_0_posY + 1, tnt_trap_0_posZ + 11, Blocks.air, 0, 3);
        world.setBlock(tnt_trap_0_posX + 11, tnt_trap_0_posY + 1, tnt_trap_0_posZ + 11, Blocks.air, 0, 3);
        world.setBlock(tnt_trap_0_posX + 0, tnt_trap_0_posY + 2, tnt_trap_0_posZ + 0, Blocks.air, 0, 3);
        world.setBlock(tnt_trap_0_posX + 1, tnt_trap_0_posY + 2, tnt_trap_0_posZ + 0, Blocks.air, 0, 3);
        world.setBlock(tnt_trap_0_posX + 2, tnt_trap_0_posY + 2, tnt_trap_0_posZ + 0, Blocks.air, 0, 3);
        world.setBlock(tnt_trap_0_posX + 3, tnt_trap_0_posY + 2, tnt_trap_0_posZ + 0, Blocks.air, 0, 3);
        world.setBlock(tnt_trap_0_posX + 4, tnt_trap_0_posY + 2, tnt_trap_0_posZ + 0, Blocks.air, 0, 3);
        world.setBlock(tnt_trap_0_posX + 5, tnt_trap_0_posY + 2, tnt_trap_0_posZ + 0, Blocks.air, 0, 3);
        world.setBlock(tnt_trap_0_posX + 6, tnt_trap_0_posY + 2, tnt_trap_0_posZ + 0, Blocks.air, 0, 3);
        world.setBlock(tnt_trap_0_posX + 7, tnt_trap_0_posY + 2, tnt_trap_0_posZ + 0, Blocks.air, 0, 3);
        world.setBlock(tnt_trap_0_posX + 8, tnt_trap_0_posY + 2, tnt_trap_0_posZ + 0, Blocks.air, 0, 3);
        world.setBlock(tnt_trap_0_posX + 9, tnt_trap_0_posY + 2, tnt_trap_0_posZ + 0, Blocks.air, 0, 3);
        world.setBlock(tnt_trap_0_posX + 10, tnt_trap_0_posY + 2, tnt_trap_0_posZ + 0, Blocks.air, 0, 3);
        world.setBlock(tnt_trap_0_posX + 11, tnt_trap_0_posY + 2, tnt_trap_0_posZ + 0, Blocks.air, 0, 3);
        world.setBlock(tnt_trap_0_posX + 0, tnt_trap_0_posY + 2, tnt_trap_0_posZ + 1, Blocks.air, 0, 3);
        world.setBlock(tnt_trap_0_posX + 1, tnt_trap_0_posY + 2, tnt_trap_0_posZ + 1, Blocks.redstone_block, 0, 3);
        world.setBlock(tnt_trap_0_posX + 2, tnt_trap_0_posY + 2, tnt_trap_0_posZ + 1, Blocks.redstone_block, 0, 3);
        world.setBlock(tnt_trap_0_posX + 3, tnt_trap_0_posY + 2, tnt_trap_0_posZ + 1, Blocks.redstone_block, 0, 3);
        world.setBlock(tnt_trap_0_posX + 4, tnt_trap_0_posY + 2, tnt_trap_0_posZ + 1, Blocks.redstone_block, 0, 3);
        world.setBlock(tnt_trap_0_posX + 5, tnt_trap_0_posY + 2, tnt_trap_0_posZ + 1, Blocks.redstone_block, 0, 3);
        world.setBlock(tnt_trap_0_posX + 6, tnt_trap_0_posY + 2, tnt_trap_0_posZ + 1, Blocks.redstone_block, 0, 3);
        world.setBlock(tnt_trap_0_posX + 7, tnt_trap_0_posY + 2, tnt_trap_0_posZ + 1, Blocks.redstone_block, 0, 3);
        world.setBlock(tnt_trap_0_posX + 8, tnt_trap_0_posY + 2, tnt_trap_0_posZ + 1, Blocks.redstone_block, 0, 3);
        world.setBlock(tnt_trap_0_posX + 9, tnt_trap_0_posY + 2, tnt_trap_0_posZ + 1, Blocks.redstone_block, 0, 3);
        world.setBlock(tnt_trap_0_posX + 10, tnt_trap_0_posY + 2, tnt_trap_0_posZ + 1, Blocks.redstone_block, 0, 3);
        world.setBlock(tnt_trap_0_posX + 11, tnt_trap_0_posY + 2, tnt_trap_0_posZ + 1, Blocks.air, 0, 3);
        world.setBlock(tnt_trap_0_posX + 0, tnt_trap_0_posY + 2, tnt_trap_0_posZ + 2, Blocks.air, 0, 3);
        world.setBlock(tnt_trap_0_posX + 1, tnt_trap_0_posY + 2, tnt_trap_0_posZ + 2, Blocks.redstone_block, 0, 3);
        world.setBlock(tnt_trap_0_posX + 2, tnt_trap_0_posY + 2, tnt_trap_0_posZ + 2, Blocks.tnt, 0, 3);
        world.setBlock(tnt_trap_0_posX + 3, tnt_trap_0_posY + 2, tnt_trap_0_posZ + 2, Blocks.tnt, 0, 3);
        world.setBlock(tnt_trap_0_posX + 4, tnt_trap_0_posY + 2, tnt_trap_0_posZ + 2, Blocks.tnt, 0, 3);
        world.setBlock(tnt_trap_0_posX + 5, tnt_trap_0_posY + 2, tnt_trap_0_posZ + 2, Blocks.tnt, 0, 3);
        world.setBlock(tnt_trap_0_posX + 6, tnt_trap_0_posY + 2, tnt_trap_0_posZ + 2, Blocks.tnt, 0, 3);
        world.setBlock(tnt_trap_0_posX + 7, tnt_trap_0_posY + 2, tnt_trap_0_posZ + 2, Blocks.tnt, 0, 3);
        world.setBlock(tnt_trap_0_posX + 8, tnt_trap_0_posY + 2, tnt_trap_0_posZ + 2, Blocks.tnt, 0, 3);
        world.setBlock(tnt_trap_0_posX + 9, tnt_trap_0_posY + 2, tnt_trap_0_posZ + 2, Blocks.tnt, 0, 3);
        world.setBlock(tnt_trap_0_posX + 10, tnt_trap_0_posY + 2, tnt_trap_0_posZ + 2, Blocks.redstone_block, 0, 3);
        world.setBlock(tnt_trap_0_posX + 11, tnt_trap_0_posY + 2, tnt_trap_0_posZ + 2, Blocks.air, 0, 3);
        world.setBlock(tnt_trap_0_posX + 0, tnt_trap_0_posY + 2, tnt_trap_0_posZ + 3, Blocks.air, 0, 3);
        world.setBlock(tnt_trap_0_posX + 1, tnt_trap_0_posY + 2, tnt_trap_0_posZ + 3, Blocks.redstone_block, 0, 3);
        world.setBlock(tnt_trap_0_posX + 2, tnt_trap_0_posY + 2, tnt_trap_0_posZ + 3, Blocks.tnt, 0, 3);
        world.setBlock(tnt_trap_0_posX + 3, tnt_trap_0_posY + 2, tnt_trap_0_posZ + 3, Blocks.diamond_block, 0, 3);
        world.setBlock(tnt_trap_0_posX + 4, tnt_trap_0_posY + 2, tnt_trap_0_posZ + 3, Blocks.diamond_block, 0, 3);
        world.setBlock(tnt_trap_0_posX + 5, tnt_trap_0_posY + 2, tnt_trap_0_posZ + 3, Blocks.diamond_block, 0, 3);
        world.setBlock(tnt_trap_0_posX + 6, tnt_trap_0_posY + 2, tnt_trap_0_posZ + 3, Blocks.diamond_block, 0, 3);
        world.setBlock(tnt_trap_0_posX + 7, tnt_trap_0_posY + 2, tnt_trap_0_posZ + 3, Blocks.diamond_block, 0, 3);
        world.setBlock(tnt_trap_0_posX + 8, tnt_trap_0_posY + 2, tnt_trap_0_posZ + 3, Blocks.diamond_block, 0, 3);
        world.setBlock(tnt_trap_0_posX + 9, tnt_trap_0_posY + 2, tnt_trap_0_posZ + 3, Blocks.tnt, 0, 3);
        world.setBlock(tnt_trap_0_posX + 10, tnt_trap_0_posY + 2, tnt_trap_0_posZ + 3, Blocks.redstone_block, 0, 3);
        world.setBlock(tnt_trap_0_posX + 11, tnt_trap_0_posY + 2, tnt_trap_0_posZ + 3, Blocks.air, 0, 3);
        world.setBlock(tnt_trap_0_posX + 0, tnt_trap_0_posY + 2, tnt_trap_0_posZ + 4, Blocks.air, 0, 3);
        world.setBlock(tnt_trap_0_posX + 1, tnt_trap_0_posY + 2, tnt_trap_0_posZ + 4, Blocks.redstone_block, 0, 3);
        world.setBlock(tnt_trap_0_posX + 2, tnt_trap_0_posY + 2, tnt_trap_0_posZ + 4, Blocks.tnt, 0, 3);
        world.setBlock(tnt_trap_0_posX + 3, tnt_trap_0_posY + 2, tnt_trap_0_posZ + 4, Blocks.diamond_block, 0, 3);
        world.setBlock(tnt_trap_0_posX + 4, tnt_trap_0_posY + 2, tnt_trap_0_posZ + 4, Blocks.air, 0, 3);
        world.setBlock(tnt_trap_0_posX + 5, tnt_trap_0_posY + 2, tnt_trap_0_posZ + 4, Blocks.air, 0, 3);
        world.setBlock(tnt_trap_0_posX + 6, tnt_trap_0_posY + 2, tnt_trap_0_posZ + 4, Blocks.air, 0, 3);
        world.setBlock(tnt_trap_0_posX + 7, tnt_trap_0_posY + 2, tnt_trap_0_posZ + 4, Blocks.air, 0, 3);
        world.setBlock(tnt_trap_0_posX + 8, tnt_trap_0_posY + 2, tnt_trap_0_posZ + 4, Blocks.diamond_block, 0, 3);
        world.setBlock(tnt_trap_0_posX + 9, tnt_trap_0_posY + 2, tnt_trap_0_posZ + 4, Blocks.tnt, 0, 3);
        world.setBlock(tnt_trap_0_posX + 10, tnt_trap_0_posY + 2, tnt_trap_0_posZ + 4, Blocks.redstone_block, 0, 3);
        world.setBlock(tnt_trap_0_posX + 11, tnt_trap_0_posY + 2, tnt_trap_0_posZ + 4, Blocks.air, 0, 3);
        world.setBlock(tnt_trap_0_posX + 0, tnt_trap_0_posY + 2, tnt_trap_0_posZ + 5, Blocks.air, 0, 3);
        world.setBlock(tnt_trap_0_posX + 1, tnt_trap_0_posY + 2, tnt_trap_0_posZ + 5, Blocks.redstone_block, 0, 3);
        world.setBlock(tnt_trap_0_posX + 2, tnt_trap_0_posY + 2, tnt_trap_0_posZ + 5, Blocks.tnt, 0, 3);
        world.setBlock(tnt_trap_0_posX + 3, tnt_trap_0_posY + 2, tnt_trap_0_posZ + 5, Blocks.diamond_block, 0, 3);
        world.setBlock(tnt_trap_0_posX + 4, tnt_trap_0_posY + 2, tnt_trap_0_posZ + 5, Blocks.air, 0, 3);
        world.setBlock(tnt_trap_0_posX + 5, tnt_trap_0_posY + 2, tnt_trap_0_posZ + 5, Blocks.air, 0, 3);
        world.setBlock(tnt_trap_0_posX + 6, tnt_trap_0_posY + 2, tnt_trap_0_posZ + 5, Blocks.air, 0, 3);
        world.setBlock(tnt_trap_0_posX + 7, tnt_trap_0_posY + 2, tnt_trap_0_posZ + 5, Blocks.air, 0, 3);
        world.setBlock(tnt_trap_0_posX + 8, tnt_trap_0_posY + 2, tnt_trap_0_posZ + 5, Blocks.diamond_block, 0, 3);
        world.setBlock(tnt_trap_0_posX + 9, tnt_trap_0_posY + 2, tnt_trap_0_posZ + 5, Blocks.tnt, 0, 3);
        world.setBlock(tnt_trap_0_posX + 10, tnt_trap_0_posY + 2, tnt_trap_0_posZ + 5, Blocks.redstone_block, 0, 3);
        world.setBlock(tnt_trap_0_posX + 11, tnt_trap_0_posY + 2, tnt_trap_0_posZ + 5, Blocks.air, 0, 3);
        world.setBlock(tnt_trap_0_posX + 0, tnt_trap_0_posY + 2, tnt_trap_0_posZ + 6, Blocks.air, 0, 3);
        world.setBlock(tnt_trap_0_posX + 1, tnt_trap_0_posY + 2, tnt_trap_0_posZ + 6, Blocks.redstone_block, 0, 3);
        world.setBlock(tnt_trap_0_posX + 2, tnt_trap_0_posY + 2, tnt_trap_0_posZ + 6, Blocks.tnt, 0, 3);
        world.setBlock(tnt_trap_0_posX + 3, tnt_trap_0_posY + 2, tnt_trap_0_posZ + 6, Blocks.diamond_block, 0, 3);
        world.setBlock(tnt_trap_0_posX + 4, tnt_trap_0_posY + 2, tnt_trap_0_posZ + 6, Blocks.air, 0, 3);
        world.setBlock(tnt_trap_0_posX + 5, tnt_trap_0_posY + 2, tnt_trap_0_posZ + 6, Blocks.air, 0, 3);
        world.setBlock(tnt_trap_0_posX + 6, tnt_trap_0_posY + 2, tnt_trap_0_posZ + 6, Blocks.air, 0, 3);
        world.setBlock(tnt_trap_0_posX + 7, tnt_trap_0_posY + 2, tnt_trap_0_posZ + 6, Blocks.air, 0, 3);
        world.setBlock(tnt_trap_0_posX + 8, tnt_trap_0_posY + 2, tnt_trap_0_posZ + 6, Blocks.diamond_block, 0, 3);
        world.setBlock(tnt_trap_0_posX + 9, tnt_trap_0_posY + 2, tnt_trap_0_posZ + 6, Blocks.tnt, 0, 3);
        world.setBlock(tnt_trap_0_posX + 10, tnt_trap_0_posY + 2, tnt_trap_0_posZ + 6, Blocks.redstone_block, 0, 3);
        world.setBlock(tnt_trap_0_posX + 11, tnt_trap_0_posY + 2, tnt_trap_0_posZ + 6, Blocks.air, 0, 3);
        world.setBlock(tnt_trap_0_posX + 0, tnt_trap_0_posY + 2, tnt_trap_0_posZ + 7, Blocks.air, 0, 3);
        world.setBlock(tnt_trap_0_posX + 1, tnt_trap_0_posY + 2, tnt_trap_0_posZ + 7, Blocks.redstone_block, 0, 3);
        world.setBlock(tnt_trap_0_posX + 2, tnt_trap_0_posY + 2, tnt_trap_0_posZ + 7, Blocks.tnt, 0, 3);
        world.setBlock(tnt_trap_0_posX + 3, tnt_trap_0_posY + 2, tnt_trap_0_posZ + 7, Blocks.diamond_block, 0, 3);
        world.setBlock(tnt_trap_0_posX + 4, tnt_trap_0_posY + 2, tnt_trap_0_posZ + 7, Blocks.air, 0, 3);
        world.setBlock(tnt_trap_0_posX + 5, tnt_trap_0_posY + 2, tnt_trap_0_posZ + 7, Blocks.air, 0, 3);
        world.setBlock(tnt_trap_0_posX + 6, tnt_trap_0_posY + 2, tnt_trap_0_posZ + 7, Blocks.air, 0, 3);
        world.setBlock(tnt_trap_0_posX + 7, tnt_trap_0_posY + 2, tnt_trap_0_posZ + 7, Blocks.air, 0, 3);
        world.setBlock(tnt_trap_0_posX + 8, tnt_trap_0_posY + 2, tnt_trap_0_posZ + 7, Blocks.diamond_block, 0, 3);
        world.setBlock(tnt_trap_0_posX + 9, tnt_trap_0_posY + 2, tnt_trap_0_posZ + 7, Blocks.tnt, 0, 3);
        world.setBlock(tnt_trap_0_posX + 10, tnt_trap_0_posY + 2, tnt_trap_0_posZ + 7, Blocks.redstone_block, 0, 3);
        world.setBlock(tnt_trap_0_posX + 11, tnt_trap_0_posY + 2, tnt_trap_0_posZ + 7, Blocks.air, 0, 3);
        world.setBlock(tnt_trap_0_posX + 0, tnt_trap_0_posY + 2, tnt_trap_0_posZ + 8, Blocks.air, 0, 3);
        world.setBlock(tnt_trap_0_posX + 1, tnt_trap_0_posY + 2, tnt_trap_0_posZ + 8, Blocks.redstone_block, 0, 3);
        world.setBlock(tnt_trap_0_posX + 2, tnt_trap_0_posY + 2, tnt_trap_0_posZ + 8, Blocks.tnt, 0, 3);
        world.setBlock(tnt_trap_0_posX + 3, tnt_trap_0_posY + 2, tnt_trap_0_posZ + 8, Blocks.diamond_block, 0, 3);
        world.setBlock(tnt_trap_0_posX + 4, tnt_trap_0_posY + 2, tnt_trap_0_posZ + 8, Blocks.diamond_block, 0, 3);
        world.setBlock(tnt_trap_0_posX + 5, tnt_trap_0_posY + 2, tnt_trap_0_posZ + 8, Blocks.diamond_block, 0, 3);
        world.setBlock(tnt_trap_0_posX + 6, tnt_trap_0_posY + 2, tnt_trap_0_posZ + 8, Blocks.diamond_block, 0, 3);
        world.setBlock(tnt_trap_0_posX + 7, tnt_trap_0_posY + 2, tnt_trap_0_posZ + 8, Blocks.diamond_block, 0, 3);
        world.setBlock(tnt_trap_0_posX + 8, tnt_trap_0_posY + 2, tnt_trap_0_posZ + 8, Blocks.diamond_block, 0, 3);
        world.setBlock(tnt_trap_0_posX + 9, tnt_trap_0_posY + 2, tnt_trap_0_posZ + 8, Blocks.tnt, 0, 3);
        world.setBlock(tnt_trap_0_posX + 10, tnt_trap_0_posY + 2, tnt_trap_0_posZ + 8, Blocks.redstone_block, 0, 3);
        world.setBlock(tnt_trap_0_posX + 11, tnt_trap_0_posY + 2, tnt_trap_0_posZ + 8, Blocks.air, 0, 3);
        world.setBlock(tnt_trap_0_posX + 0, tnt_trap_0_posY + 2, tnt_trap_0_posZ + 9, Blocks.air, 0, 3);
        world.setBlock(tnt_trap_0_posX + 1, tnt_trap_0_posY + 2, tnt_trap_0_posZ + 9, Blocks.redstone_block, 0, 3);
        world.setBlock(tnt_trap_0_posX + 2, tnt_trap_0_posY + 2, tnt_trap_0_posZ + 9, Blocks.tnt, 0, 3);
        world.setBlock(tnt_trap_0_posX + 3, tnt_trap_0_posY + 2, tnt_trap_0_posZ + 9, Blocks.tnt, 0, 3);
        world.setBlock(tnt_trap_0_posX + 4, tnt_trap_0_posY + 2, tnt_trap_0_posZ + 9, Blocks.tnt, 0, 3);
        world.setBlock(tnt_trap_0_posX + 5, tnt_trap_0_posY + 2, tnt_trap_0_posZ + 9, Blocks.tnt, 0, 3);
        world.setBlock(tnt_trap_0_posX + 6, tnt_trap_0_posY + 2, tnt_trap_0_posZ + 9, Blocks.tnt, 0, 3);
        world.setBlock(tnt_trap_0_posX + 7, tnt_trap_0_posY + 2, tnt_trap_0_posZ + 9, Blocks.tnt, 0, 3);
        world.setBlock(tnt_trap_0_posX + 8, tnt_trap_0_posY + 2, tnt_trap_0_posZ + 9, Blocks.tnt, 0, 3);
        world.setBlock(tnt_trap_0_posX + 9, tnt_trap_0_posY + 2, tnt_trap_0_posZ + 9, Blocks.tnt, 0, 3);
        world.setBlock(tnt_trap_0_posX + 10, tnt_trap_0_posY + 2, tnt_trap_0_posZ + 9, Blocks.redstone_block, 0, 3);
        world.setBlock(tnt_trap_0_posX + 11, tnt_trap_0_posY + 2, tnt_trap_0_posZ + 9, Blocks.air, 0, 3);
        world.setBlock(tnt_trap_0_posX + 0, tnt_trap_0_posY + 2, tnt_trap_0_posZ + 10, Blocks.air, 0, 3);
        world.setBlock(tnt_trap_0_posX + 1, tnt_trap_0_posY + 2, tnt_trap_0_posZ + 10, Blocks.redstone_block, 0, 3);
        world.setBlock(tnt_trap_0_posX + 2, tnt_trap_0_posY + 2, tnt_trap_0_posZ + 10, Blocks.redstone_block, 0, 3);
        world.setBlock(tnt_trap_0_posX + 3, tnt_trap_0_posY + 2, tnt_trap_0_posZ + 10, Blocks.redstone_block, 0, 3);
        world.setBlock(tnt_trap_0_posX + 4, tnt_trap_0_posY + 2, tnt_trap_0_posZ + 10, Blocks.redstone_block, 0, 3);
        world.setBlock(tnt_trap_0_posX + 5, tnt_trap_0_posY + 2, tnt_trap_0_posZ + 10, Blocks.redstone_block, 0, 3);
        world.setBlock(tnt_trap_0_posX + 6, tnt_trap_0_posY + 2, tnt_trap_0_posZ + 10, Blocks.redstone_block, 0, 3);
        world.setBlock(tnt_trap_0_posX + 7, tnt_trap_0_posY + 2, tnt_trap_0_posZ + 10, Blocks.redstone_block, 0, 3);
        world.setBlock(tnt_trap_0_posX + 8, tnt_trap_0_posY + 2, tnt_trap_0_posZ + 10, Blocks.redstone_block, 0, 3);
        world.setBlock(tnt_trap_0_posX + 9, tnt_trap_0_posY + 2, tnt_trap_0_posZ + 10, Blocks.redstone_block, 0, 3);
        world.setBlock(tnt_trap_0_posX + 10, tnt_trap_0_posY + 2, tnt_trap_0_posZ + 10, Blocks.redstone_block, 0, 3);
        world.setBlock(tnt_trap_0_posX + 11, tnt_trap_0_posY + 2, tnt_trap_0_posZ + 10, Blocks.air, 0, 3);
        world.setBlock(tnt_trap_0_posX + 0, tnt_trap_0_posY + 2, tnt_trap_0_posZ + 11, Blocks.air, 0, 3);
        world.setBlock(tnt_trap_0_posX + 1, tnt_trap_0_posY + 2, tnt_trap_0_posZ + 11, Blocks.air, 0, 3);
        world.setBlock(tnt_trap_0_posX + 2, tnt_trap_0_posY + 2, tnt_trap_0_posZ + 11, Blocks.air, 0, 3);
        world.setBlock(tnt_trap_0_posX + 3, tnt_trap_0_posY + 2, tnt_trap_0_posZ + 11, Blocks.air, 0, 3);
        world.setBlock(tnt_trap_0_posX + 4, tnt_trap_0_posY + 2, tnt_trap_0_posZ + 11, Blocks.air, 0, 3);
        world.setBlock(tnt_trap_0_posX + 5, tnt_trap_0_posY + 2, tnt_trap_0_posZ + 11, Blocks.air, 0, 3);
        world.setBlock(tnt_trap_0_posX + 6, tnt_trap_0_posY + 2, tnt_trap_0_posZ + 11, Blocks.air, 0, 3);
        world.setBlock(tnt_trap_0_posX + 7, tnt_trap_0_posY + 2, tnt_trap_0_posZ + 11, Blocks.air, 0, 3);
        world.setBlock(tnt_trap_0_posX + 8, tnt_trap_0_posY + 2, tnt_trap_0_posZ + 11, Blocks.air, 0, 3);
        world.setBlock(tnt_trap_0_posX + 9, tnt_trap_0_posY + 2, tnt_trap_0_posZ + 11, Blocks.air, 0, 3);
        world.setBlock(tnt_trap_0_posX + 10, tnt_trap_0_posY + 2, tnt_trap_0_posZ + 11, Blocks.air, 0, 3);
        world.setBlock(tnt_trap_0_posX + 11, tnt_trap_0_posY + 2, tnt_trap_0_posZ + 11, Blocks.air, 0, 3);
        world.setBlock(tnt_trap_0_posX + 0, tnt_trap_0_posY + 3, tnt_trap_0_posZ + 0, Blocks.air, 0, 3);
        world.setBlock(tnt_trap_0_posX + 1, tnt_trap_0_posY + 3, tnt_trap_0_posZ + 0, Blocks.air, 0, 3);
        world.setBlock(tnt_trap_0_posX + 2, tnt_trap_0_posY + 3, tnt_trap_0_posZ + 0, Blocks.air, 0, 3);
        world.setBlock(tnt_trap_0_posX + 3, tnt_trap_0_posY + 3, tnt_trap_0_posZ + 0, Blocks.air, 0, 3);
        world.setBlock(tnt_trap_0_posX + 4, tnt_trap_0_posY + 3, tnt_trap_0_posZ + 0, Blocks.air, 0, 3);
        world.setBlock(tnt_trap_0_posX + 5, tnt_trap_0_posY + 3, tnt_trap_0_posZ + 0, Blocks.air, 0, 3);
        world.setBlock(tnt_trap_0_posX + 6, tnt_trap_0_posY + 3, tnt_trap_0_posZ + 0, Blocks.air, 0, 3);
        world.setBlock(tnt_trap_0_posX + 7, tnt_trap_0_posY + 3, tnt_trap_0_posZ + 0, Blocks.air, 0, 3);
        world.setBlock(tnt_trap_0_posX + 8, tnt_trap_0_posY + 3, tnt_trap_0_posZ + 0, Blocks.air, 0, 3);
        world.setBlock(tnt_trap_0_posX + 9, tnt_trap_0_posY + 3, tnt_trap_0_posZ + 0, Blocks.air, 0, 3);
        world.setBlock(tnt_trap_0_posX + 10, tnt_trap_0_posY + 3, tnt_trap_0_posZ + 0, Blocks.air, 0, 3);
        world.setBlock(tnt_trap_0_posX + 11, tnt_trap_0_posY + 3, tnt_trap_0_posZ + 0, Blocks.air, 0, 3);
        world.setBlock(tnt_trap_0_posX + 0, tnt_trap_0_posY + 3, tnt_trap_0_posZ + 1, Blocks.air, 0, 3);
        world.setBlock(tnt_trap_0_posX + 1, tnt_trap_0_posY + 3, tnt_trap_0_posZ + 1, Blocks.redstone_block, 0, 3);
        world.setBlock(tnt_trap_0_posX + 2, tnt_trap_0_posY + 3, tnt_trap_0_posZ + 1, Blocks.redstone_block, 0, 3);
        world.setBlock(tnt_trap_0_posX + 3, tnt_trap_0_posY + 3, tnt_trap_0_posZ + 1, Blocks.redstone_block, 0, 3);
        world.setBlock(tnt_trap_0_posX + 4, tnt_trap_0_posY + 3, tnt_trap_0_posZ + 1, Blocks.redstone_block, 0, 3);
        world.setBlock(tnt_trap_0_posX + 5, tnt_trap_0_posY + 3, tnt_trap_0_posZ + 1, Blocks.redstone_block, 0, 3);
        world.setBlock(tnt_trap_0_posX + 6, tnt_trap_0_posY + 3, tnt_trap_0_posZ + 1, Blocks.redstone_block, 0, 3);
        world.setBlock(tnt_trap_0_posX + 7, tnt_trap_0_posY + 3, tnt_trap_0_posZ + 1, Blocks.redstone_block, 0, 3);
        world.setBlock(tnt_trap_0_posX + 8, tnt_trap_0_posY + 3, tnt_trap_0_posZ + 1, Blocks.redstone_block, 0, 3);
        world.setBlock(tnt_trap_0_posX + 9, tnt_trap_0_posY + 3, tnt_trap_0_posZ + 1, Blocks.redstone_block, 0, 3);
        world.setBlock(tnt_trap_0_posX + 10, tnt_trap_0_posY + 3, tnt_trap_0_posZ + 1, Blocks.redstone_block, 0, 3);
        world.setBlock(tnt_trap_0_posX + 11, tnt_trap_0_posY + 3, tnt_trap_0_posZ + 1, Blocks.air, 0, 3);
        world.setBlock(tnt_trap_0_posX + 0, tnt_trap_0_posY + 3, tnt_trap_0_posZ + 2, Blocks.air, 0, 3);
        world.setBlock(tnt_trap_0_posX + 1, tnt_trap_0_posY + 3, tnt_trap_0_posZ + 2, Blocks.redstone_block, 0, 3);
        world.setBlock(tnt_trap_0_posX + 2, tnt_trap_0_posY + 3, tnt_trap_0_posZ + 2, Blocks.tnt, 0, 3);
        world.setBlock(tnt_trap_0_posX + 3, tnt_trap_0_posY + 3, tnt_trap_0_posZ + 2, Blocks.tnt, 0, 3);
        world.setBlock(tnt_trap_0_posX + 4, tnt_trap_0_posY + 3, tnt_trap_0_posZ + 2, Blocks.tnt, 0, 3);
        world.setBlock(tnt_trap_0_posX + 5, tnt_trap_0_posY + 3, tnt_trap_0_posZ + 2, Blocks.tnt, 0, 3);
        world.setBlock(tnt_trap_0_posX + 6, tnt_trap_0_posY + 3, tnt_trap_0_posZ + 2, Blocks.tnt, 0, 3);
        world.setBlock(tnt_trap_0_posX + 7, tnt_trap_0_posY + 3, tnt_trap_0_posZ + 2, Blocks.tnt, 0, 3);
        world.setBlock(tnt_trap_0_posX + 8, tnt_trap_0_posY + 3, tnt_trap_0_posZ + 2, Blocks.tnt, 0, 3);
        world.setBlock(tnt_trap_0_posX + 9, tnt_trap_0_posY + 3, tnt_trap_0_posZ + 2, Blocks.tnt, 0, 3);
        world.setBlock(tnt_trap_0_posX + 10, tnt_trap_0_posY + 3, tnt_trap_0_posZ + 2, Blocks.redstone_block, 0, 3);
        world.setBlock(tnt_trap_0_posX + 11, tnt_trap_0_posY + 3, tnt_trap_0_posZ + 2, Blocks.air, 0, 3);
        world.setBlock(tnt_trap_0_posX + 0, tnt_trap_0_posY + 3, tnt_trap_0_posZ + 3, Blocks.air, 0, 3);
        world.setBlock(tnt_trap_0_posX + 1, tnt_trap_0_posY + 3, tnt_trap_0_posZ + 3, Blocks.redstone_block, 0, 3);
        world.setBlock(tnt_trap_0_posX + 2, tnt_trap_0_posY + 3, tnt_trap_0_posZ + 3, Blocks.tnt, 0, 3);
        world.setBlock(tnt_trap_0_posX + 3, tnt_trap_0_posY + 3, tnt_trap_0_posZ + 3, Blocks.diamond_block, 0, 3);
        world.setBlock(tnt_trap_0_posX + 4, tnt_trap_0_posY + 3, tnt_trap_0_posZ + 3, Blocks.diamond_block, 0, 3);
        world.setBlock(tnt_trap_0_posX + 5, tnt_trap_0_posY + 3, tnt_trap_0_posZ + 3, Blocks.diamond_block, 0, 3);
        world.setBlock(tnt_trap_0_posX + 6, tnt_trap_0_posY + 3, tnt_trap_0_posZ + 3, Blocks.diamond_block, 0, 3);
        world.setBlock(tnt_trap_0_posX + 7, tnt_trap_0_posY + 3, tnt_trap_0_posZ + 3, Blocks.diamond_block, 0, 3);
        world.setBlock(tnt_trap_0_posX + 8, tnt_trap_0_posY + 3, tnt_trap_0_posZ + 3, Blocks.diamond_block, 0, 3);
        world.setBlock(tnt_trap_0_posX + 9, tnt_trap_0_posY + 3, tnt_trap_0_posZ + 3, Blocks.tnt, 0, 3);
        world.setBlock(tnt_trap_0_posX + 10, tnt_trap_0_posY + 3, tnt_trap_0_posZ + 3, Blocks.redstone_block, 0, 3);
        world.setBlock(tnt_trap_0_posX + 11, tnt_trap_0_posY + 3, tnt_trap_0_posZ + 3, Blocks.air, 0, 3);
        world.setBlock(tnt_trap_0_posX + 0, tnt_trap_0_posY + 3, tnt_trap_0_posZ + 4, Blocks.air, 0, 3);
        world.setBlock(tnt_trap_0_posX + 1, tnt_trap_0_posY + 3, tnt_trap_0_posZ + 4, Blocks.redstone_block, 0, 3);
        world.setBlock(tnt_trap_0_posX + 2, tnt_trap_0_posY + 3, tnt_trap_0_posZ + 4, Blocks.tnt, 0, 3);
        world.setBlock(tnt_trap_0_posX + 3, tnt_trap_0_posY + 3, tnt_trap_0_posZ + 4, Blocks.diamond_block, 0, 3);
        world.setBlock(tnt_trap_0_posX + 4, tnt_trap_0_posY + 3, tnt_trap_0_posZ + 4, Blocks.air, 0, 3);
        world.setBlock(tnt_trap_0_posX + 5, tnt_trap_0_posY + 3, tnt_trap_0_posZ + 4, Blocks.air, 0, 3);
        world.setBlock(tnt_trap_0_posX + 6, tnt_trap_0_posY + 3, tnt_trap_0_posZ + 4, Blocks.air, 0, 3);
        world.setBlock(tnt_trap_0_posX + 7, tnt_trap_0_posY + 3, tnt_trap_0_posZ + 4, Blocks.air, 0, 3);
        world.setBlock(tnt_trap_0_posX + 8, tnt_trap_0_posY + 3, tnt_trap_0_posZ + 4, Blocks.diamond_block, 0, 3);
        world.setBlock(tnt_trap_0_posX + 9, tnt_trap_0_posY + 3, tnt_trap_0_posZ + 4, Blocks.tnt, 0, 3);
        world.setBlock(tnt_trap_0_posX + 10, tnt_trap_0_posY + 3, tnt_trap_0_posZ + 4, Blocks.redstone_block, 0, 3);
        world.setBlock(tnt_trap_0_posX + 11, tnt_trap_0_posY + 3, tnt_trap_0_posZ + 4, Blocks.air, 0, 3);
        world.setBlock(tnt_trap_0_posX + 0, tnt_trap_0_posY + 3, tnt_trap_0_posZ + 5, Blocks.air, 0, 3);
        world.setBlock(tnt_trap_0_posX + 1, tnt_trap_0_posY + 3, tnt_trap_0_posZ + 5, Blocks.redstone_block, 0, 3);
        world.setBlock(tnt_trap_0_posX + 2, tnt_trap_0_posY + 3, tnt_trap_0_posZ + 5, Blocks.tnt, 0, 3);
        world.setBlock(tnt_trap_0_posX + 3, tnt_trap_0_posY + 3, tnt_trap_0_posZ + 5, Blocks.diamond_block, 0, 3);
        world.setBlock(tnt_trap_0_posX + 4, tnt_trap_0_posY + 3, tnt_trap_0_posZ + 5, Blocks.air, 0, 3);
        world.setBlock(tnt_trap_0_posX + 5, tnt_trap_0_posY + 3, tnt_trap_0_posZ + 5, Blocks.air, 0, 3);
        world.setBlock(tnt_trap_0_posX + 6, tnt_trap_0_posY + 3, tnt_trap_0_posZ + 5, Blocks.air, 0, 3);
        world.setBlock(tnt_trap_0_posX + 7, tnt_trap_0_posY + 3, tnt_trap_0_posZ + 5, Blocks.air, 0, 3);
        world.setBlock(tnt_trap_0_posX + 8, tnt_trap_0_posY + 3, tnt_trap_0_posZ + 5, Blocks.diamond_block, 0, 3);
        world.setBlock(tnt_trap_0_posX + 9, tnt_trap_0_posY + 3, tnt_trap_0_posZ + 5, Blocks.tnt, 0, 3);
        world.setBlock(tnt_trap_0_posX + 10, tnt_trap_0_posY + 3, tnt_trap_0_posZ + 5, Blocks.redstone_block, 0, 3);
        world.setBlock(tnt_trap_0_posX + 11, tnt_trap_0_posY + 3, tnt_trap_0_posZ + 5, Blocks.air, 0, 3);
        world.setBlock(tnt_trap_0_posX + 0, tnt_trap_0_posY + 3, tnt_trap_0_posZ + 6, Blocks.air, 0, 3);
        world.setBlock(tnt_trap_0_posX + 1, tnt_trap_0_posY + 3, tnt_trap_0_posZ + 6, Blocks.redstone_block, 0, 3);
        world.setBlock(tnt_trap_0_posX + 2, tnt_trap_0_posY + 3, tnt_trap_0_posZ + 6, Blocks.tnt, 0, 3);
        world.setBlock(tnt_trap_0_posX + 3, tnt_trap_0_posY + 3, tnt_trap_0_posZ + 6, Blocks.diamond_block, 0, 3);
        world.setBlock(tnt_trap_0_posX + 4, tnt_trap_0_posY + 3, tnt_trap_0_posZ + 6, Blocks.air, 0, 3);
        world.setBlock(tnt_trap_0_posX + 5, tnt_trap_0_posY + 3, tnt_trap_0_posZ + 6, Blocks.air, 0, 3);
        world.setBlock(tnt_trap_0_posX + 6, tnt_trap_0_posY + 3, tnt_trap_0_posZ + 6, Blocks.air, 0, 3);
        world.setBlock(tnt_trap_0_posX + 7, tnt_trap_0_posY + 3, tnt_trap_0_posZ + 6, Blocks.air, 0, 3);
        world.setBlock(tnt_trap_0_posX + 8, tnt_trap_0_posY + 3, tnt_trap_0_posZ + 6, Blocks.diamond_block, 0, 3);
        world.setBlock(tnt_trap_0_posX + 9, tnt_trap_0_posY + 3, tnt_trap_0_posZ + 6, Blocks.tnt, 0, 3);
        world.setBlock(tnt_trap_0_posX + 10, tnt_trap_0_posY + 3, tnt_trap_0_posZ + 6, Blocks.redstone_block, 0, 3);
        world.setBlock(tnt_trap_0_posX + 11, tnt_trap_0_posY + 3, tnt_trap_0_posZ + 6, Blocks.air, 0, 3);
        world.setBlock(tnt_trap_0_posX + 0, tnt_trap_0_posY + 3, tnt_trap_0_posZ + 7, Blocks.air, 0, 3);
        world.setBlock(tnt_trap_0_posX + 1, tnt_trap_0_posY + 3, tnt_trap_0_posZ + 7, Blocks.redstone_block, 0, 3);
        world.setBlock(tnt_trap_0_posX + 2, tnt_trap_0_posY + 3, tnt_trap_0_posZ + 7, Blocks.tnt, 0, 3);
        world.setBlock(tnt_trap_0_posX + 3, tnt_trap_0_posY + 3, tnt_trap_0_posZ + 7, Blocks.diamond_block, 0, 3);
        world.setBlock(tnt_trap_0_posX + 4, tnt_trap_0_posY + 3, tnt_trap_0_posZ + 7, Blocks.air, 0, 3);
        world.setBlock(tnt_trap_0_posX + 5, tnt_trap_0_posY + 3, tnt_trap_0_posZ + 7, Blocks.air, 0, 3);
        world.setBlock(tnt_trap_0_posX + 6, tnt_trap_0_posY + 3, tnt_trap_0_posZ + 7, Blocks.air, 0, 3);
        world.setBlock(tnt_trap_0_posX + 7, tnt_trap_0_posY + 3, tnt_trap_0_posZ + 7, Blocks.air, 0, 3);
        world.setBlock(tnt_trap_0_posX + 8, tnt_trap_0_posY + 3, tnt_trap_0_posZ + 7, Blocks.diamond_block, 0, 3);
        world.setBlock(tnt_trap_0_posX + 9, tnt_trap_0_posY + 3, tnt_trap_0_posZ + 7, Blocks.tnt, 0, 3);
        world.setBlock(tnt_trap_0_posX + 10, tnt_trap_0_posY + 3, tnt_trap_0_posZ + 7, Blocks.redstone_block, 0, 3);
        world.setBlock(tnt_trap_0_posX + 11, tnt_trap_0_posY + 3, tnt_trap_0_posZ + 7, Blocks.air, 0, 3);
        world.setBlock(tnt_trap_0_posX + 0, tnt_trap_0_posY + 3, tnt_trap_0_posZ + 8, Blocks.air, 0, 3);
        world.setBlock(tnt_trap_0_posX + 1, tnt_trap_0_posY + 3, tnt_trap_0_posZ + 8, Blocks.redstone_block, 0, 3);
        world.setBlock(tnt_trap_0_posX + 2, tnt_trap_0_posY + 3, tnt_trap_0_posZ + 8, Blocks.tnt, 0, 3);
        world.setBlock(tnt_trap_0_posX + 3, tnt_trap_0_posY + 3, tnt_trap_0_posZ + 8, Blocks.diamond_block, 0, 3);
        world.setBlock(tnt_trap_0_posX + 4, tnt_trap_0_posY + 3, tnt_trap_0_posZ + 8, Blocks.diamond_block, 0, 3);
        world.setBlock(tnt_trap_0_posX + 5, tnt_trap_0_posY + 3, tnt_trap_0_posZ + 8, Blocks.diamond_block, 0, 3);
        world.setBlock(tnt_trap_0_posX + 6, tnt_trap_0_posY + 3, tnt_trap_0_posZ + 8, Blocks.diamond_block, 0, 3);
        world.setBlock(tnt_trap_0_posX + 7, tnt_trap_0_posY + 3, tnt_trap_0_posZ + 8, Blocks.diamond_block, 0, 3);
        world.setBlock(tnt_trap_0_posX + 8, tnt_trap_0_posY + 3, tnt_trap_0_posZ + 8, Blocks.diamond_block, 0, 3);
        world.setBlock(tnt_trap_0_posX + 9, tnt_trap_0_posY + 3, tnt_trap_0_posZ + 8, Blocks.tnt, 0, 3);
        world.setBlock(tnt_trap_0_posX + 10, tnt_trap_0_posY + 3, tnt_trap_0_posZ + 8, Blocks.redstone_block, 0, 3);
        world.setBlock(tnt_trap_0_posX + 11, tnt_trap_0_posY + 3, tnt_trap_0_posZ + 8, Blocks.air, 0, 3);
        world.setBlock(tnt_trap_0_posX + 0, tnt_trap_0_posY + 3, tnt_trap_0_posZ + 9, Blocks.air, 0, 3);
        world.setBlock(tnt_trap_0_posX + 1, tnt_trap_0_posY + 3, tnt_trap_0_posZ + 9, Blocks.redstone_block, 0, 3);
        world.setBlock(tnt_trap_0_posX + 2, tnt_trap_0_posY + 3, tnt_trap_0_posZ + 9, Blocks.tnt, 0, 3);
        world.setBlock(tnt_trap_0_posX + 3, tnt_trap_0_posY + 3, tnt_trap_0_posZ + 9, Blocks.tnt, 0, 3);
        world.setBlock(tnt_trap_0_posX + 4, tnt_trap_0_posY + 3, tnt_trap_0_posZ + 9, Blocks.tnt, 0, 3);
        world.setBlock(tnt_trap_0_posX + 5, tnt_trap_0_posY + 3, tnt_trap_0_posZ + 9, Blocks.tnt, 0, 3);
        world.setBlock(tnt_trap_0_posX + 6, tnt_trap_0_posY + 3, tnt_trap_0_posZ + 9, Blocks.tnt, 0, 3);
        world.setBlock(tnt_trap_0_posX + 7, tnt_trap_0_posY + 3, tnt_trap_0_posZ + 9, Blocks.tnt, 0, 3);
        world.setBlock(tnt_trap_0_posX + 8, tnt_trap_0_posY + 3, tnt_trap_0_posZ + 9, Blocks.tnt, 0, 3);
        world.setBlock(tnt_trap_0_posX + 9, tnt_trap_0_posY + 3, tnt_trap_0_posZ + 9, Blocks.tnt, 0, 3);
        world.setBlock(tnt_trap_0_posX + 10, tnt_trap_0_posY + 3, tnt_trap_0_posZ + 9, Blocks.redstone_block, 0, 3);
        world.setBlock(tnt_trap_0_posX + 11, tnt_trap_0_posY + 3, tnt_trap_0_posZ + 9, Blocks.air, 0, 3);
        world.setBlock(tnt_trap_0_posX + 0, tnt_trap_0_posY + 3, tnt_trap_0_posZ + 10, Blocks.air, 0, 3);
        world.setBlock(tnt_trap_0_posX + 1, tnt_trap_0_posY + 3, tnt_trap_0_posZ + 10, Blocks.redstone_block, 0, 3);
        world.setBlock(tnt_trap_0_posX + 2, tnt_trap_0_posY + 3, tnt_trap_0_posZ + 10, Blocks.redstone_block, 0, 3);
        world.setBlock(tnt_trap_0_posX + 3, tnt_trap_0_posY + 3, tnt_trap_0_posZ + 10, Blocks.redstone_block, 0, 3);
        world.setBlock(tnt_trap_0_posX + 4, tnt_trap_0_posY + 3, tnt_trap_0_posZ + 10, Blocks.redstone_block, 0, 3);
        world.setBlock(tnt_trap_0_posX + 5, tnt_trap_0_posY + 3, tnt_trap_0_posZ + 10, Blocks.redstone_block, 0, 3);
        world.setBlock(tnt_trap_0_posX + 6, tnt_trap_0_posY + 3, tnt_trap_0_posZ + 10, Blocks.redstone_block, 0, 3);
        world.setBlock(tnt_trap_0_posX + 7, tnt_trap_0_posY + 3, tnt_trap_0_posZ + 10, Blocks.redstone_block, 0, 3);
        world.setBlock(tnt_trap_0_posX + 8, tnt_trap_0_posY + 3, tnt_trap_0_posZ + 10, Blocks.redstone_block, 0, 3);
        world.setBlock(tnt_trap_0_posX + 9, tnt_trap_0_posY + 3, tnt_trap_0_posZ + 10, Blocks.redstone_block, 0, 3);
        world.setBlock(tnt_trap_0_posX + 10, tnt_trap_0_posY + 3, tnt_trap_0_posZ + 10, Blocks.redstone_block, 0, 3);
        world.setBlock(tnt_trap_0_posX + 11, tnt_trap_0_posY + 3, tnt_trap_0_posZ + 10, Blocks.air, 0, 3);
        world.setBlock(tnt_trap_0_posX + 0, tnt_trap_0_posY + 3, tnt_trap_0_posZ + 11, Blocks.air, 0, 3);
        world.setBlock(tnt_trap_0_posX + 1, tnt_trap_0_posY + 3, tnt_trap_0_posZ + 11, Blocks.air, 0, 3);
        world.setBlock(tnt_trap_0_posX + 2, tnt_trap_0_posY + 3, tnt_trap_0_posZ + 11, Blocks.air, 0, 3);
        world.setBlock(tnt_trap_0_posX + 3, tnt_trap_0_posY + 3, tnt_trap_0_posZ + 11, Blocks.air, 0, 3);
        world.setBlock(tnt_trap_0_posX + 4, tnt_trap_0_posY + 3, tnt_trap_0_posZ + 11, Blocks.air, 0, 3);
        world.setBlock(tnt_trap_0_posX + 5, tnt_trap_0_posY + 3, tnt_trap_0_posZ + 11, Blocks.air, 0, 3);
        world.setBlock(tnt_trap_0_posX + 6, tnt_trap_0_posY + 3, tnt_trap_0_posZ + 11, Blocks.air, 0, 3);
        world.setBlock(tnt_trap_0_posX + 7, tnt_trap_0_posY + 3, tnt_trap_0_posZ + 11, Blocks.air, 0, 3);
        world.setBlock(tnt_trap_0_posX + 8, tnt_trap_0_posY + 3, tnt_trap_0_posZ + 11, Blocks.air, 0, 3);
        world.setBlock(tnt_trap_0_posX + 9, tnt_trap_0_posY + 3, tnt_trap_0_posZ + 11, Blocks.air, 0, 3);
        world.setBlock(tnt_trap_0_posX + 10, tnt_trap_0_posY + 3, tnt_trap_0_posZ + 11, Blocks.air, 0, 3);
        world.setBlock(tnt_trap_0_posX + 11, tnt_trap_0_posY + 3, tnt_trap_0_posZ + 11, Blocks.air, 0, 3);
        world.setBlock(tnt_trap_0_posX + 0, tnt_trap_0_posY + 4, tnt_trap_0_posZ + 0, Blocks.air, 0, 3);
        world.setBlock(tnt_trap_0_posX + 1, tnt_trap_0_posY + 4, tnt_trap_0_posZ + 0, Blocks.air, 0, 3);
        world.setBlock(tnt_trap_0_posX + 2, tnt_trap_0_posY + 4, tnt_trap_0_posZ + 0, Blocks.air, 0, 3);
        world.setBlock(tnt_trap_0_posX + 3, tnt_trap_0_posY + 4, tnt_trap_0_posZ + 0, Blocks.air, 0, 3);
        world.setBlock(tnt_trap_0_posX + 4, tnt_trap_0_posY + 4, tnt_trap_0_posZ + 0, Blocks.air, 0, 3);
        world.setBlock(tnt_trap_0_posX + 5, tnt_trap_0_posY + 4, tnt_trap_0_posZ + 0, Blocks.air, 0, 3);
        world.setBlock(tnt_trap_0_posX + 6, tnt_trap_0_posY + 4, tnt_trap_0_posZ + 0, Blocks.air, 0, 3);
        world.setBlock(tnt_trap_0_posX + 7, tnt_trap_0_posY + 4, tnt_trap_0_posZ + 0, Blocks.air, 0, 3);
        world.setBlock(tnt_trap_0_posX + 8, tnt_trap_0_posY + 4, tnt_trap_0_posZ + 0, Blocks.air, 0, 3);
        world.setBlock(tnt_trap_0_posX + 9, tnt_trap_0_posY + 4, tnt_trap_0_posZ + 0, Blocks.air, 0, 3);
        world.setBlock(tnt_trap_0_posX + 10, tnt_trap_0_posY + 4, tnt_trap_0_posZ + 0, Blocks.air, 0, 3);
        world.setBlock(tnt_trap_0_posX + 11, tnt_trap_0_posY + 4, tnt_trap_0_posZ + 0, Blocks.air, 0, 3);
        world.setBlock(tnt_trap_0_posX + 0, tnt_trap_0_posY + 4, tnt_trap_0_posZ + 1, Blocks.air, 0, 3);
        world.setBlock(tnt_trap_0_posX + 1, tnt_trap_0_posY + 4, tnt_trap_0_posZ + 1, Blocks.redstone_block, 0, 3);
        world.setBlock(tnt_trap_0_posX + 2, tnt_trap_0_posY + 4, tnt_trap_0_posZ + 1, Blocks.redstone_block, 0, 3);
        world.setBlock(tnt_trap_0_posX + 3, tnt_trap_0_posY + 4, tnt_trap_0_posZ + 1, Blocks.redstone_block, 0, 3);
        world.setBlock(tnt_trap_0_posX + 4, tnt_trap_0_posY + 4, tnt_trap_0_posZ + 1, Blocks.redstone_block, 0, 3);
        world.setBlock(tnt_trap_0_posX + 5, tnt_trap_0_posY + 4, tnt_trap_0_posZ + 1, Blocks.redstone_block, 0, 3);
        world.setBlock(tnt_trap_0_posX + 6, tnt_trap_0_posY + 4, tnt_trap_0_posZ + 1, Blocks.redstone_block, 0, 3);
        world.setBlock(tnt_trap_0_posX + 7, tnt_trap_0_posY + 4, tnt_trap_0_posZ + 1, Blocks.redstone_block, 0, 3);
        world.setBlock(tnt_trap_0_posX + 8, tnt_trap_0_posY + 4, tnt_trap_0_posZ + 1, Blocks.redstone_block, 0, 3);
        world.setBlock(tnt_trap_0_posX + 9, tnt_trap_0_posY + 4, tnt_trap_0_posZ + 1, Blocks.redstone_block, 0, 3);
        world.setBlock(tnt_trap_0_posX + 10, tnt_trap_0_posY + 4, tnt_trap_0_posZ + 1, Blocks.redstone_block, 0, 3);
        world.setBlock(tnt_trap_0_posX + 11, tnt_trap_0_posY + 4, tnt_trap_0_posZ + 1, Blocks.air, 0, 3);
        world.setBlock(tnt_trap_0_posX + 0, tnt_trap_0_posY + 4, tnt_trap_0_posZ + 2, Blocks.air, 0, 3);
        world.setBlock(tnt_trap_0_posX + 1, tnt_trap_0_posY + 4, tnt_trap_0_posZ + 2, Blocks.redstone_block, 0, 3);
        world.setBlock(tnt_trap_0_posX + 2, tnt_trap_0_posY + 4, tnt_trap_0_posZ + 2, Blocks.tnt, 0, 3);
        world.setBlock(tnt_trap_0_posX + 3, tnt_trap_0_posY + 4, tnt_trap_0_posZ + 2, Blocks.tnt, 0, 3);
        world.setBlock(tnt_trap_0_posX + 4, tnt_trap_0_posY + 4, tnt_trap_0_posZ + 2, Blocks.tnt, 0, 3);
        world.setBlock(tnt_trap_0_posX + 5, tnt_trap_0_posY + 4, tnt_trap_0_posZ + 2, Blocks.tnt, 0, 3);
        world.setBlock(tnt_trap_0_posX + 6, tnt_trap_0_posY + 4, tnt_trap_0_posZ + 2, Blocks.tnt, 0, 3);
        world.setBlock(tnt_trap_0_posX + 7, tnt_trap_0_posY + 4, tnt_trap_0_posZ + 2, Blocks.tnt, 0, 3);
        world.setBlock(tnt_trap_0_posX + 8, tnt_trap_0_posY + 4, tnt_trap_0_posZ + 2, Blocks.tnt, 0, 3);
        world.setBlock(tnt_trap_0_posX + 9, tnt_trap_0_posY + 4, tnt_trap_0_posZ + 2, Blocks.tnt, 0, 3);
        world.setBlock(tnt_trap_0_posX + 10, tnt_trap_0_posY + 4, tnt_trap_0_posZ + 2, Blocks.redstone_block, 0, 3);
        world.setBlock(tnt_trap_0_posX + 11, tnt_trap_0_posY + 4, tnt_trap_0_posZ + 2, Blocks.air, 0, 3);
        world.setBlock(tnt_trap_0_posX + 0, tnt_trap_0_posY + 4, tnt_trap_0_posZ + 3, Blocks.air, 0, 3);
        world.setBlock(tnt_trap_0_posX + 1, tnt_trap_0_posY + 4, tnt_trap_0_posZ + 3, Blocks.redstone_block, 0, 3);
        world.setBlock(tnt_trap_0_posX + 2, tnt_trap_0_posY + 4, tnt_trap_0_posZ + 3, Blocks.tnt, 0, 3);
        world.setBlock(tnt_trap_0_posX + 3, tnt_trap_0_posY + 4, tnt_trap_0_posZ + 3, Blocks.diamond_block, 0, 3);
        world.setBlock(tnt_trap_0_posX + 4, tnt_trap_0_posY + 4, tnt_trap_0_posZ + 3, Blocks.diamond_block, 0, 3);
        world.setBlock(tnt_trap_0_posX + 5, tnt_trap_0_posY + 4, tnt_trap_0_posZ + 3, Blocks.diamond_block, 0, 3);
        world.setBlock(tnt_trap_0_posX + 6, tnt_trap_0_posY + 4, tnt_trap_0_posZ + 3, Blocks.diamond_block, 0, 3);
        world.setBlock(tnt_trap_0_posX + 7, tnt_trap_0_posY + 4, tnt_trap_0_posZ + 3, Blocks.diamond_block, 0, 3);
        world.setBlock(tnt_trap_0_posX + 8, tnt_trap_0_posY + 4, tnt_trap_0_posZ + 3, Blocks.diamond_block, 0, 3);
        world.setBlock(tnt_trap_0_posX + 9, tnt_trap_0_posY + 4, tnt_trap_0_posZ + 3, Blocks.tnt, 0, 3);
        world.setBlock(tnt_trap_0_posX + 10, tnt_trap_0_posY + 4, tnt_trap_0_posZ + 3, Blocks.redstone_block, 0, 3);
        world.setBlock(tnt_trap_0_posX + 11, tnt_trap_0_posY + 4, tnt_trap_0_posZ + 3, Blocks.air, 0, 3);
        world.setBlock(tnt_trap_0_posX + 0, tnt_trap_0_posY + 4, tnt_trap_0_posZ + 4, Blocks.air, 0, 3);
        world.setBlock(tnt_trap_0_posX + 1, tnt_trap_0_posY + 4, tnt_trap_0_posZ + 4, Blocks.redstone_block, 0, 3);
        world.setBlock(tnt_trap_0_posX + 2, tnt_trap_0_posY + 4, tnt_trap_0_posZ + 4, Blocks.tnt, 0, 3);
        world.setBlock(tnt_trap_0_posX + 3, tnt_trap_0_posY + 4, tnt_trap_0_posZ + 4, Blocks.diamond_block, 0, 3);
        world.setBlock(tnt_trap_0_posX + 4, tnt_trap_0_posY + 4, tnt_trap_0_posZ + 4, Blocks.air, 0, 3);
        world.setBlock(tnt_trap_0_posX + 5, tnt_trap_0_posY + 4, tnt_trap_0_posZ + 4, Blocks.air, 0, 3);
        world.setBlock(tnt_trap_0_posX + 6, tnt_trap_0_posY + 4, tnt_trap_0_posZ + 4, Blocks.air, 0, 3);
        world.setBlock(tnt_trap_0_posX + 7, tnt_trap_0_posY + 4, tnt_trap_0_posZ + 4, Blocks.air, 0, 3);
        world.setBlock(tnt_trap_0_posX + 8, tnt_trap_0_posY + 4, tnt_trap_0_posZ + 4, Blocks.diamond_block, 0, 3);
        world.setBlock(tnt_trap_0_posX + 9, tnt_trap_0_posY + 4, tnt_trap_0_posZ + 4, Blocks.tnt, 0, 3);
        world.setBlock(tnt_trap_0_posX + 10, tnt_trap_0_posY + 4, tnt_trap_0_posZ + 4, Blocks.redstone_block, 0, 3);
        world.setBlock(tnt_trap_0_posX + 11, tnt_trap_0_posY + 4, tnt_trap_0_posZ + 4, Blocks.air, 0, 3);
        world.setBlock(tnt_trap_0_posX + 0, tnt_trap_0_posY + 4, tnt_trap_0_posZ + 5, Blocks.air, 0, 3);
        world.setBlock(tnt_trap_0_posX + 1, tnt_trap_0_posY + 4, tnt_trap_0_posZ + 5, Blocks.redstone_block, 0, 3);
        world.setBlock(tnt_trap_0_posX + 2, tnt_trap_0_posY + 4, tnt_trap_0_posZ + 5, Blocks.tnt, 0, 3);
        world.setBlock(tnt_trap_0_posX + 3, tnt_trap_0_posY + 4, tnt_trap_0_posZ + 5, Blocks.diamond_block, 0, 3);
        world.setBlock(tnt_trap_0_posX + 4, tnt_trap_0_posY + 4, tnt_trap_0_posZ + 5, Blocks.air, 0, 3);
        world.setBlock(tnt_trap_0_posX + 5, tnt_trap_0_posY + 4, tnt_trap_0_posZ + 5, Blocks.air, 0, 3);
        world.setBlock(tnt_trap_0_posX + 6, tnt_trap_0_posY + 4, tnt_trap_0_posZ + 5, Blocks.air, 0, 3);
        world.setBlock(tnt_trap_0_posX + 7, tnt_trap_0_posY + 4, tnt_trap_0_posZ + 5, Blocks.air, 0, 3);
        world.setBlock(tnt_trap_0_posX + 8, tnt_trap_0_posY + 4, tnt_trap_0_posZ + 5, Blocks.diamond_block, 0, 3);
        world.setBlock(tnt_trap_0_posX + 9, tnt_trap_0_posY + 4, tnt_trap_0_posZ + 5, Blocks.tnt, 0, 3);
        world.setBlock(tnt_trap_0_posX + 10, tnt_trap_0_posY + 4, tnt_trap_0_posZ + 5, Blocks.redstone_block, 0, 3);
        world.setBlock(tnt_trap_0_posX + 11, tnt_trap_0_posY + 4, tnt_trap_0_posZ + 5, Blocks.air, 0, 3);
        world.setBlock(tnt_trap_0_posX + 0, tnt_trap_0_posY + 4, tnt_trap_0_posZ + 6, Blocks.air, 0, 3);
        world.setBlock(tnt_trap_0_posX + 1, tnt_trap_0_posY + 4, tnt_trap_0_posZ + 6, Blocks.redstone_block, 0, 3);
        world.setBlock(tnt_trap_0_posX + 2, tnt_trap_0_posY + 4, tnt_trap_0_posZ + 6, Blocks.tnt, 0, 3);
        world.setBlock(tnt_trap_0_posX + 3, tnt_trap_0_posY + 4, tnt_trap_0_posZ + 6, Blocks.diamond_block, 0, 3);
        world.setBlock(tnt_trap_0_posX + 4, tnt_trap_0_posY + 4, tnt_trap_0_posZ + 6, Blocks.air, 0, 3);
        world.setBlock(tnt_trap_0_posX + 5, tnt_trap_0_posY + 4, tnt_trap_0_posZ + 6, Blocks.air, 0, 3);
        world.setBlock(tnt_trap_0_posX + 6, tnt_trap_0_posY + 4, tnt_trap_0_posZ + 6, Blocks.air, 0, 3);
        world.setBlock(tnt_trap_0_posX + 7, tnt_trap_0_posY + 4, tnt_trap_0_posZ + 6, Blocks.air, 0, 3);
        world.setBlock(tnt_trap_0_posX + 8, tnt_trap_0_posY + 4, tnt_trap_0_posZ + 6, Blocks.diamond_block, 0, 3);
        world.setBlock(tnt_trap_0_posX + 9, tnt_trap_0_posY + 4, tnt_trap_0_posZ + 6, Blocks.tnt, 0, 3);
        world.setBlock(tnt_trap_0_posX + 10, tnt_trap_0_posY + 4, tnt_trap_0_posZ + 6, Blocks.redstone_block, 0, 3);
        world.setBlock(tnt_trap_0_posX + 11, tnt_trap_0_posY + 4, tnt_trap_0_posZ + 6, Blocks.air, 0, 3);
        world.setBlock(tnt_trap_0_posX + 0, tnt_trap_0_posY + 4, tnt_trap_0_posZ + 7, Blocks.air, 0, 3);
        world.setBlock(tnt_trap_0_posX + 1, tnt_trap_0_posY + 4, tnt_trap_0_posZ + 7, Blocks.redstone_block, 0, 3);
        world.setBlock(tnt_trap_0_posX + 2, tnt_trap_0_posY + 4, tnt_trap_0_posZ + 7, Blocks.tnt, 0, 3);
        world.setBlock(tnt_trap_0_posX + 3, tnt_trap_0_posY + 4, tnt_trap_0_posZ + 7, Blocks.diamond_block, 0, 3);
        world.setBlock(tnt_trap_0_posX + 4, tnt_trap_0_posY + 4, tnt_trap_0_posZ + 7, Blocks.air, 0, 3);
        world.setBlock(tnt_trap_0_posX + 5, tnt_trap_0_posY + 4, tnt_trap_0_posZ + 7, Blocks.air, 0, 3);
        world.setBlock(tnt_trap_0_posX + 6, tnt_trap_0_posY + 4, tnt_trap_0_posZ + 7, Blocks.air, 0, 3);
        world.setBlock(tnt_trap_0_posX + 7, tnt_trap_0_posY + 4, tnt_trap_0_posZ + 7, Blocks.air, 0, 3);
        world.setBlock(tnt_trap_0_posX + 8, tnt_trap_0_posY + 4, tnt_trap_0_posZ + 7, Blocks.diamond_block, 0, 3);
        world.setBlock(tnt_trap_0_posX + 9, tnt_trap_0_posY + 4, tnt_trap_0_posZ + 7, Blocks.tnt, 0, 3);
        world.setBlock(tnt_trap_0_posX + 10, tnt_trap_0_posY + 4, tnt_trap_0_posZ + 7, Blocks.redstone_block, 0, 3);
        world.setBlock(tnt_trap_0_posX + 11, tnt_trap_0_posY + 4, tnt_trap_0_posZ + 7, Blocks.air, 0, 3);
        world.setBlock(tnt_trap_0_posX + 0, tnt_trap_0_posY + 4, tnt_trap_0_posZ + 8, Blocks.air, 0, 3);
        world.setBlock(tnt_trap_0_posX + 1, tnt_trap_0_posY + 4, tnt_trap_0_posZ + 8, Blocks.redstone_block, 0, 3);
        world.setBlock(tnt_trap_0_posX + 2, tnt_trap_0_posY + 4, tnt_trap_0_posZ + 8, Blocks.tnt, 0, 3);
        world.setBlock(tnt_trap_0_posX + 3, tnt_trap_0_posY + 4, tnt_trap_0_posZ + 8, Blocks.diamond_block, 0, 3);
        world.setBlock(tnt_trap_0_posX + 4, tnt_trap_0_posY + 4, tnt_trap_0_posZ + 8, Blocks.diamond_block, 0, 3);
        world.setBlock(tnt_trap_0_posX + 5, tnt_trap_0_posY + 4, tnt_trap_0_posZ + 8, Blocks.diamond_block, 0, 3);
        world.setBlock(tnt_trap_0_posX + 6, tnt_trap_0_posY + 4, tnt_trap_0_posZ + 8, Blocks.diamond_block, 0, 3);
        world.setBlock(tnt_trap_0_posX + 7, tnt_trap_0_posY + 4, tnt_trap_0_posZ + 8, Blocks.diamond_block, 0, 3);
        world.setBlock(tnt_trap_0_posX + 8, tnt_trap_0_posY + 4, tnt_trap_0_posZ + 8, Blocks.diamond_block, 0, 3);
        world.setBlock(tnt_trap_0_posX + 9, tnt_trap_0_posY + 4, tnt_trap_0_posZ + 8, Blocks.tnt, 0, 3);
        world.setBlock(tnt_trap_0_posX + 10, tnt_trap_0_posY + 4, tnt_trap_0_posZ + 8, Blocks.redstone_block, 0, 3);
        world.setBlock(tnt_trap_0_posX + 11, tnt_trap_0_posY + 4, tnt_trap_0_posZ + 8, Blocks.air, 0, 3);
        world.setBlock(tnt_trap_0_posX + 0, tnt_trap_0_posY + 4, tnt_trap_0_posZ + 9, Blocks.air, 0, 3);
        world.setBlock(tnt_trap_0_posX + 1, tnt_trap_0_posY + 4, tnt_trap_0_posZ + 9, Blocks.redstone_block, 0, 3);
        world.setBlock(tnt_trap_0_posX + 2, tnt_trap_0_posY + 4, tnt_trap_0_posZ + 9, Blocks.tnt, 0, 3);
        world.setBlock(tnt_trap_0_posX + 3, tnt_trap_0_posY + 4, tnt_trap_0_posZ + 9, Blocks.tnt, 0, 3);
        world.setBlock(tnt_trap_0_posX + 4, tnt_trap_0_posY + 4, tnt_trap_0_posZ + 9, Blocks.tnt, 0, 3);
        world.setBlock(tnt_trap_0_posX + 5, tnt_trap_0_posY + 4, tnt_trap_0_posZ + 9, Blocks.tnt, 0, 3);
        world.setBlock(tnt_trap_0_posX + 6, tnt_trap_0_posY + 4, tnt_trap_0_posZ + 9, Blocks.tnt, 0, 3);
        world.setBlock(tnt_trap_0_posX + 7, tnt_trap_0_posY + 4, tnt_trap_0_posZ + 9, Blocks.tnt, 0, 3);
        world.setBlock(tnt_trap_0_posX + 8, tnt_trap_0_posY + 4, tnt_trap_0_posZ + 9, Blocks.tnt, 0, 3);
        world.setBlock(tnt_trap_0_posX + 9, tnt_trap_0_posY + 4, tnt_trap_0_posZ + 9, Blocks.tnt, 0, 3);
        world.setBlock(tnt_trap_0_posX + 10, tnt_trap_0_posY + 4, tnt_trap_0_posZ + 9, Blocks.redstone_block, 0, 3);
        world.setBlock(tnt_trap_0_posX + 11, tnt_trap_0_posY + 4, tnt_trap_0_posZ + 9, Blocks.air, 0, 3);
        world.setBlock(tnt_trap_0_posX + 0, tnt_trap_0_posY + 4, tnt_trap_0_posZ + 10, Blocks.air, 0, 3);
        world.setBlock(tnt_trap_0_posX + 1, tnt_trap_0_posY + 4, tnt_trap_0_posZ + 10, Blocks.redstone_block, 0, 3);
        world.setBlock(tnt_trap_0_posX + 2, tnt_trap_0_posY + 4, tnt_trap_0_posZ + 10, Blocks.redstone_block, 0, 3);
        world.setBlock(tnt_trap_0_posX + 3, tnt_trap_0_posY + 4, tnt_trap_0_posZ + 10, Blocks.redstone_block, 0, 3);
        world.setBlock(tnt_trap_0_posX + 4, tnt_trap_0_posY + 4, tnt_trap_0_posZ + 10, Blocks.redstone_block, 0, 3);
        world.setBlock(tnt_trap_0_posX + 5, tnt_trap_0_posY + 4, tnt_trap_0_posZ + 10, Blocks.redstone_block, 0, 3);
        world.setBlock(tnt_trap_0_posX + 6, tnt_trap_0_posY + 4, tnt_trap_0_posZ + 10, Blocks.redstone_block, 0, 3);
        world.setBlock(tnt_trap_0_posX + 7, tnt_trap_0_posY + 4, tnt_trap_0_posZ + 10, Blocks.redstone_block, 0, 3);
        world.setBlock(tnt_trap_0_posX + 8, tnt_trap_0_posY + 4, tnt_trap_0_posZ + 10, Blocks.redstone_block, 0, 3);
        world.setBlock(tnt_trap_0_posX + 9, tnt_trap_0_posY + 4, tnt_trap_0_posZ + 10, Blocks.redstone_block, 0, 3);
        world.setBlock(tnt_trap_0_posX + 10, tnt_trap_0_posY + 4, tnt_trap_0_posZ + 10, Blocks.redstone_block, 0, 3);
        world.setBlock(tnt_trap_0_posX + 11, tnt_trap_0_posY + 4, tnt_trap_0_posZ + 10, Blocks.air, 0, 3);
        world.setBlock(tnt_trap_0_posX + 0, tnt_trap_0_posY + 4, tnt_trap_0_posZ + 11, Blocks.air, 0, 3);
        world.setBlock(tnt_trap_0_posX + 1, tnt_trap_0_posY + 4, tnt_trap_0_posZ + 11, Blocks.air, 0, 3);
        world.setBlock(tnt_trap_0_posX + 2, tnt_trap_0_posY + 4, tnt_trap_0_posZ + 11, Blocks.air, 0, 3);
        world.setBlock(tnt_trap_0_posX + 3, tnt_trap_0_posY + 4, tnt_trap_0_posZ + 11, Blocks.air, 0, 3);
        world.setBlock(tnt_trap_0_posX + 4, tnt_trap_0_posY + 4, tnt_trap_0_posZ + 11, Blocks.air, 0, 3);
        world.setBlock(tnt_trap_0_posX + 5, tnt_trap_0_posY + 4, tnt_trap_0_posZ + 11, Blocks.air, 0, 3);
        world.setBlock(tnt_trap_0_posX + 6, tnt_trap_0_posY + 4, tnt_trap_0_posZ + 11, Blocks.air, 0, 3);
        world.setBlock(tnt_trap_0_posX + 7, tnt_trap_0_posY + 4, tnt_trap_0_posZ + 11, Blocks.air, 0, 3);
        world.setBlock(tnt_trap_0_posX + 8, tnt_trap_0_posY + 4, tnt_trap_0_posZ + 11, Blocks.air, 0, 3);
        world.setBlock(tnt_trap_0_posX + 9, tnt_trap_0_posY + 4, tnt_trap_0_posZ + 11, Blocks.air, 0, 3);
        world.setBlock(tnt_trap_0_posX + 10, tnt_trap_0_posY + 4, tnt_trap_0_posZ + 11, Blocks.air, 0, 3);
        world.setBlock(tnt_trap_0_posX + 11, tnt_trap_0_posY + 4, tnt_trap_0_posZ + 11, Blocks.air, 0, 3);
        world.setBlock(tnt_trap_0_posX + 0, tnt_trap_0_posY + 5, tnt_trap_0_posZ + 0, Blocks.air, 0, 3);
        world.setBlock(tnt_trap_0_posX + 1, tnt_trap_0_posY + 5, tnt_trap_0_posZ + 0, Blocks.air, 0, 3);
        world.setBlock(tnt_trap_0_posX + 2, tnt_trap_0_posY + 5, tnt_trap_0_posZ + 0, Blocks.air, 0, 3);
        world.setBlock(tnt_trap_0_posX + 3, tnt_trap_0_posY + 5, tnt_trap_0_posZ + 0, Blocks.air, 0, 3);
        world.setBlock(tnt_trap_0_posX + 4, tnt_trap_0_posY + 5, tnt_trap_0_posZ + 0, Blocks.air, 0, 3);
        world.setBlock(tnt_trap_0_posX + 5, tnt_trap_0_posY + 5, tnt_trap_0_posZ + 0, Blocks.air, 0, 3);
        world.setBlock(tnt_trap_0_posX + 6, tnt_trap_0_posY + 5, tnt_trap_0_posZ + 0, Blocks.air, 0, 3);
        world.setBlock(tnt_trap_0_posX + 7, tnt_trap_0_posY + 5, tnt_trap_0_posZ + 0, Blocks.air, 0, 3);
        world.setBlock(tnt_trap_0_posX + 8, tnt_trap_0_posY + 5, tnt_trap_0_posZ + 0, Blocks.air, 0, 3);
        world.setBlock(tnt_trap_0_posX + 9, tnt_trap_0_posY + 5, tnt_trap_0_posZ + 0, Blocks.air, 0, 3);
        world.setBlock(tnt_trap_0_posX + 10, tnt_trap_0_posY + 5, tnt_trap_0_posZ + 0, Blocks.air, 0, 3);
        world.setBlock(tnt_trap_0_posX + 11, tnt_trap_0_posY + 5, tnt_trap_0_posZ + 0, Blocks.air, 0, 3);
        world.setBlock(tnt_trap_0_posX + 0, tnt_trap_0_posY + 5, tnt_trap_0_posZ + 1, Blocks.air, 0, 3);
        world.setBlock(tnt_trap_0_posX + 1, tnt_trap_0_posY + 5, tnt_trap_0_posZ + 1, Blocks.redstone_block, 0, 3);
        world.setBlock(tnt_trap_0_posX + 2, tnt_trap_0_posY + 5, tnt_trap_0_posZ + 1, Blocks.redstone_block, 0, 3);
        world.setBlock(tnt_trap_0_posX + 3, tnt_trap_0_posY + 5, tnt_trap_0_posZ + 1, Blocks.redstone_block, 0, 3);
        world.setBlock(tnt_trap_0_posX + 4, tnt_trap_0_posY + 5, tnt_trap_0_posZ + 1, Blocks.redstone_block, 0, 3);
        world.setBlock(tnt_trap_0_posX + 5, tnt_trap_0_posY + 5, tnt_trap_0_posZ + 1, Blocks.redstone_block, 0, 3);
        world.setBlock(tnt_trap_0_posX + 6, tnt_trap_0_posY + 5, tnt_trap_0_posZ + 1, Blocks.redstone_block, 0, 3);
        world.setBlock(tnt_trap_0_posX + 7, tnt_trap_0_posY + 5, tnt_trap_0_posZ + 1, Blocks.redstone_block, 0, 3);
        world.setBlock(tnt_trap_0_posX + 8, tnt_trap_0_posY + 5, tnt_trap_0_posZ + 1, Blocks.redstone_block, 0, 3);
        world.setBlock(tnt_trap_0_posX + 9, tnt_trap_0_posY + 5, tnt_trap_0_posZ + 1, Blocks.redstone_block, 0, 3);
        world.setBlock(tnt_trap_0_posX + 10, tnt_trap_0_posY + 5, tnt_trap_0_posZ + 1, Blocks.redstone_block, 0, 3);
        world.setBlock(tnt_trap_0_posX + 11, tnt_trap_0_posY + 5, tnt_trap_0_posZ + 1, Blocks.air, 0, 3);
        world.setBlock(tnt_trap_0_posX + 0, tnt_trap_0_posY + 5, tnt_trap_0_posZ + 2, Blocks.air, 0, 3);
        world.setBlock(tnt_trap_0_posX + 1, tnt_trap_0_posY + 5, tnt_trap_0_posZ + 2, Blocks.redstone_block, 0, 3);
        world.setBlock(tnt_trap_0_posX + 2, tnt_trap_0_posY + 5, tnt_trap_0_posZ + 2, Blocks.tnt, 0, 3);
        world.setBlock(tnt_trap_0_posX + 3, tnt_trap_0_posY + 5, tnt_trap_0_posZ + 2, Blocks.tnt, 0, 3);
        world.setBlock(tnt_trap_0_posX + 4, tnt_trap_0_posY + 5, tnt_trap_0_posZ + 2, Blocks.tnt, 0, 3);
        world.setBlock(tnt_trap_0_posX + 5, tnt_trap_0_posY + 5, tnt_trap_0_posZ + 2, Blocks.tnt, 0, 3);
        world.setBlock(tnt_trap_0_posX + 6, tnt_trap_0_posY + 5, tnt_trap_0_posZ + 2, Blocks.tnt, 0, 3);
        world.setBlock(tnt_trap_0_posX + 7, tnt_trap_0_posY + 5, tnt_trap_0_posZ + 2, Blocks.tnt, 0, 3);
        world.setBlock(tnt_trap_0_posX + 8, tnt_trap_0_posY + 5, tnt_trap_0_posZ + 2, Blocks.tnt, 0, 3);
        world.setBlock(tnt_trap_0_posX + 9, tnt_trap_0_posY + 5, tnt_trap_0_posZ + 2, Blocks.tnt, 0, 3);
        world.setBlock(tnt_trap_0_posX + 10, tnt_trap_0_posY + 5, tnt_trap_0_posZ + 2, Blocks.redstone_block, 0, 3);
        world.setBlock(tnt_trap_0_posX + 11, tnt_trap_0_posY + 5, tnt_trap_0_posZ + 2, Blocks.air, 0, 3);
        world.setBlock(tnt_trap_0_posX + 0, tnt_trap_0_posY + 5, tnt_trap_0_posZ + 3, Blocks.air, 0, 3);
        world.setBlock(tnt_trap_0_posX + 1, tnt_trap_0_posY + 5, tnt_trap_0_posZ + 3, Blocks.redstone_block, 0, 3);
        world.setBlock(tnt_trap_0_posX + 2, tnt_trap_0_posY + 5, tnt_trap_0_posZ + 3, Blocks.tnt, 0, 3);
        world.setBlock(tnt_trap_0_posX + 3, tnt_trap_0_posY + 5, tnt_trap_0_posZ + 3, Blocks.diamond_block, 0, 3);
        world.setBlock(tnt_trap_0_posX + 4, tnt_trap_0_posY + 5, tnt_trap_0_posZ + 3, Blocks.diamond_block, 0, 3);
        world.setBlock(tnt_trap_0_posX + 5, tnt_trap_0_posY + 5, tnt_trap_0_posZ + 3, Blocks.diamond_block, 0, 3);
        world.setBlock(tnt_trap_0_posX + 6, tnt_trap_0_posY + 5, tnt_trap_0_posZ + 3, Blocks.diamond_block, 0, 3);
        world.setBlock(tnt_trap_0_posX + 7, tnt_trap_0_posY + 5, tnt_trap_0_posZ + 3, Blocks.diamond_block, 0, 3);
        world.setBlock(tnt_trap_0_posX + 8, tnt_trap_0_posY + 5, tnt_trap_0_posZ + 3, Blocks.diamond_block, 0, 3);
        world.setBlock(tnt_trap_0_posX + 9, tnt_trap_0_posY + 5, tnt_trap_0_posZ + 3, Blocks.tnt, 0, 3);
        world.setBlock(tnt_trap_0_posX + 10, tnt_trap_0_posY + 5, tnt_trap_0_posZ + 3, Blocks.redstone_block, 0, 3);
        world.setBlock(tnt_trap_0_posX + 11, tnt_trap_0_posY + 5, tnt_trap_0_posZ + 3, Blocks.air, 0, 3);
        world.setBlock(tnt_trap_0_posX + 0, tnt_trap_0_posY + 5, tnt_trap_0_posZ + 4, Blocks.air, 0, 3);
        world.setBlock(tnt_trap_0_posX + 1, tnt_trap_0_posY + 5, tnt_trap_0_posZ + 4, Blocks.redstone_block, 0, 3);
        world.setBlock(tnt_trap_0_posX + 2, tnt_trap_0_posY + 5, tnt_trap_0_posZ + 4, Blocks.tnt, 0, 3);
        world.setBlock(tnt_trap_0_posX + 3, tnt_trap_0_posY + 5, tnt_trap_0_posZ + 4, Blocks.diamond_block, 0, 3);
        world.setBlock(tnt_trap_0_posX + 4, tnt_trap_0_posY + 5, tnt_trap_0_posZ + 4, Blocks.air, 0, 3);
        world.setBlock(tnt_trap_0_posX + 5, tnt_trap_0_posY + 5, tnt_trap_0_posZ + 4, Blocks.air, 0, 3);
        world.setBlock(tnt_trap_0_posX + 6, tnt_trap_0_posY + 5, tnt_trap_0_posZ + 4, Blocks.air, 0, 3);
        world.setBlock(tnt_trap_0_posX + 7, tnt_trap_0_posY + 5, tnt_trap_0_posZ + 4, Blocks.air, 0, 3);
        world.setBlock(tnt_trap_0_posX + 8, tnt_trap_0_posY + 5, tnt_trap_0_posZ + 4, Blocks.diamond_block, 0, 3);
        world.setBlock(tnt_trap_0_posX + 9, tnt_trap_0_posY + 5, tnt_trap_0_posZ + 4, Blocks.tnt, 0, 3);
        world.setBlock(tnt_trap_0_posX + 10, tnt_trap_0_posY + 5, tnt_trap_0_posZ + 4, Blocks.redstone_block, 0, 3);
        world.setBlock(tnt_trap_0_posX + 11, tnt_trap_0_posY + 5, tnt_trap_0_posZ + 4, Blocks.air, 0, 3);
        world.setBlock(tnt_trap_0_posX + 0, tnt_trap_0_posY + 5, tnt_trap_0_posZ + 5, Blocks.air, 0, 3);
        world.setBlock(tnt_trap_0_posX + 1, tnt_trap_0_posY + 5, tnt_trap_0_posZ + 5, Blocks.redstone_block, 0, 3);
        world.setBlock(tnt_trap_0_posX + 2, tnt_trap_0_posY + 5, tnt_trap_0_posZ + 5, Blocks.tnt, 0, 3);
        world.setBlock(tnt_trap_0_posX + 3, tnt_trap_0_posY + 5, tnt_trap_0_posZ + 5, Blocks.diamond_block, 0, 3);
        world.setBlock(tnt_trap_0_posX + 4, tnt_trap_0_posY + 5, tnt_trap_0_posZ + 5, Blocks.air, 0, 3);
        world.setBlock(tnt_trap_0_posX + 5, tnt_trap_0_posY + 5, tnt_trap_0_posZ + 5, Blocks.air, 0, 3);
        world.setBlock(tnt_trap_0_posX + 6, tnt_trap_0_posY + 5, tnt_trap_0_posZ + 5, Blocks.air, 0, 3);
        world.setBlock(tnt_trap_0_posX + 7, tnt_trap_0_posY + 5, tnt_trap_0_posZ + 5, Blocks.air, 0, 3);
        world.setBlock(tnt_trap_0_posX + 8, tnt_trap_0_posY + 5, tnt_trap_0_posZ + 5, Blocks.diamond_block, 0, 3);
        world.setBlock(tnt_trap_0_posX + 9, tnt_trap_0_posY + 5, tnt_trap_0_posZ + 5, Blocks.tnt, 0, 3);
        world.setBlock(tnt_trap_0_posX + 10, tnt_trap_0_posY + 5, tnt_trap_0_posZ + 5, Blocks.redstone_block, 0, 3);
        world.setBlock(tnt_trap_0_posX + 11, tnt_trap_0_posY + 5, tnt_trap_0_posZ + 5, Blocks.air, 0, 3);
        world.setBlock(tnt_trap_0_posX + 0, tnt_trap_0_posY + 5, tnt_trap_0_posZ + 6, Blocks.air, 0, 3);
        world.setBlock(tnt_trap_0_posX + 1, tnt_trap_0_posY + 5, tnt_trap_0_posZ + 6, Blocks.redstone_block, 0, 3);
        world.setBlock(tnt_trap_0_posX + 2, tnt_trap_0_posY + 5, tnt_trap_0_posZ + 6, Blocks.tnt, 0, 3);
        world.setBlock(tnt_trap_0_posX + 3, tnt_trap_0_posY + 5, tnt_trap_0_posZ + 6, Blocks.diamond_block, 0, 3);
        world.setBlock(tnt_trap_0_posX + 4, tnt_trap_0_posY + 5, tnt_trap_0_posZ + 6, Blocks.air, 0, 3);
        world.setBlock(tnt_trap_0_posX + 5, tnt_trap_0_posY + 5, tnt_trap_0_posZ + 6, Blocks.air, 0, 3);
        world.setBlock(tnt_trap_0_posX + 6, tnt_trap_0_posY + 5, tnt_trap_0_posZ + 6, Blocks.air, 0, 3);
        world.setBlock(tnt_trap_0_posX + 7, tnt_trap_0_posY + 5, tnt_trap_0_posZ + 6, Blocks.air, 0, 3);
        world.setBlock(tnt_trap_0_posX + 8, tnt_trap_0_posY + 5, tnt_trap_0_posZ + 6, Blocks.diamond_block, 0, 3);
        world.setBlock(tnt_trap_0_posX + 9, tnt_trap_0_posY + 5, tnt_trap_0_posZ + 6, Blocks.tnt, 0, 3);
        world.setBlock(tnt_trap_0_posX + 10, tnt_trap_0_posY + 5, tnt_trap_0_posZ + 6, Blocks.redstone_block, 0, 3);
        world.setBlock(tnt_trap_0_posX + 11, tnt_trap_0_posY + 5, tnt_trap_0_posZ + 6, Blocks.air, 0, 3);
        world.setBlock(tnt_trap_0_posX + 0, tnt_trap_0_posY + 5, tnt_trap_0_posZ + 7, Blocks.air, 0, 3);
        world.setBlock(tnt_trap_0_posX + 1, tnt_trap_0_posY + 5, tnt_trap_0_posZ + 7, Blocks.redstone_block, 0, 3);
        world.setBlock(tnt_trap_0_posX + 2, tnt_trap_0_posY + 5, tnt_trap_0_posZ + 7, Blocks.tnt, 0, 3);
        world.setBlock(tnt_trap_0_posX + 3, tnt_trap_0_posY + 5, tnt_trap_0_posZ + 7, Blocks.diamond_block, 0, 3);
        world.setBlock(tnt_trap_0_posX + 4, tnt_trap_0_posY + 5, tnt_trap_0_posZ + 7, Blocks.air, 0, 3);
        world.setBlock(tnt_trap_0_posX + 5, tnt_trap_0_posY + 5, tnt_trap_0_posZ + 7, Blocks.air, 0, 3);
        world.setBlock(tnt_trap_0_posX + 6, tnt_trap_0_posY + 5, tnt_trap_0_posZ + 7, Blocks.air, 0, 3);
        world.setBlock(tnt_trap_0_posX + 7, tnt_trap_0_posY + 5, tnt_trap_0_posZ + 7, Blocks.air, 0, 3);
        world.setBlock(tnt_trap_0_posX + 8, tnt_trap_0_posY + 5, tnt_trap_0_posZ + 7, Blocks.diamond_block, 0, 3);
        world.setBlock(tnt_trap_0_posX + 9, tnt_trap_0_posY + 5, tnt_trap_0_posZ + 7, Blocks.tnt, 0, 3);
        world.setBlock(tnt_trap_0_posX + 10, tnt_trap_0_posY + 5, tnt_trap_0_posZ + 7, Blocks.redstone_block, 0, 3);
        world.setBlock(tnt_trap_0_posX + 11, tnt_trap_0_posY + 5, tnt_trap_0_posZ + 7, Blocks.air, 0, 3);
        world.setBlock(tnt_trap_0_posX + 0, tnt_trap_0_posY + 5, tnt_trap_0_posZ + 8, Blocks.air, 0, 3);
        world.setBlock(tnt_trap_0_posX + 1, tnt_trap_0_posY + 5, tnt_trap_0_posZ + 8, Blocks.redstone_block, 0, 3);
        world.setBlock(tnt_trap_0_posX + 2, tnt_trap_0_posY + 5, tnt_trap_0_posZ + 8, Blocks.tnt, 0, 3);
        world.setBlock(tnt_trap_0_posX + 3, tnt_trap_0_posY + 5, tnt_trap_0_posZ + 8, Blocks.diamond_block, 0, 3);
        world.setBlock(tnt_trap_0_posX + 4, tnt_trap_0_posY + 5, tnt_trap_0_posZ + 8, Blocks.diamond_block, 0, 3);
        world.setBlock(tnt_trap_0_posX + 5, tnt_trap_0_posY + 5, tnt_trap_0_posZ + 8, Blocks.diamond_block, 0, 3);
        world.setBlock(tnt_trap_0_posX + 6, tnt_trap_0_posY + 5, tnt_trap_0_posZ + 8, Blocks.diamond_block, 0, 3);
        world.setBlock(tnt_trap_0_posX + 7, tnt_trap_0_posY + 5, tnt_trap_0_posZ + 8, Blocks.diamond_block, 0, 3);
        world.setBlock(tnt_trap_0_posX + 8, tnt_trap_0_posY + 5, tnt_trap_0_posZ + 8, Blocks.diamond_block, 0, 3);
        world.setBlock(tnt_trap_0_posX + 9, tnt_trap_0_posY + 5, tnt_trap_0_posZ + 8, Blocks.tnt, 0, 3);
        world.setBlock(tnt_trap_0_posX + 10, tnt_trap_0_posY + 5, tnt_trap_0_posZ + 8, Blocks.redstone_block, 0, 3);
        world.setBlock(tnt_trap_0_posX + 11, tnt_trap_0_posY + 5, tnt_trap_0_posZ + 8, Blocks.air, 0, 3);
        world.setBlock(tnt_trap_0_posX + 0, tnt_trap_0_posY + 5, tnt_trap_0_posZ + 9, Blocks.air, 0, 3);
        world.setBlock(tnt_trap_0_posX + 1, tnt_trap_0_posY + 5, tnt_trap_0_posZ + 9, Blocks.redstone_block, 0, 3);
        world.setBlock(tnt_trap_0_posX + 2, tnt_trap_0_posY + 5, tnt_trap_0_posZ + 9, Blocks.tnt, 0, 3);
        world.setBlock(tnt_trap_0_posX + 3, tnt_trap_0_posY + 5, tnt_trap_0_posZ + 9, Blocks.tnt, 0, 3);
        world.setBlock(tnt_trap_0_posX + 4, tnt_trap_0_posY + 5, tnt_trap_0_posZ + 9, Blocks.tnt, 0, 3);
        world.setBlock(tnt_trap_0_posX + 5, tnt_trap_0_posY + 5, tnt_trap_0_posZ + 9, Blocks.tnt, 0, 3);
        world.setBlock(tnt_trap_0_posX + 6, tnt_trap_0_posY + 5, tnt_trap_0_posZ + 9, Blocks.tnt, 0, 3);
        world.setBlock(tnt_trap_0_posX + 7, tnt_trap_0_posY + 5, tnt_trap_0_posZ + 9, Blocks.tnt, 0, 3);
        world.setBlock(tnt_trap_0_posX + 8, tnt_trap_0_posY + 5, tnt_trap_0_posZ + 9, Blocks.tnt, 0, 3);
        world.setBlock(tnt_trap_0_posX + 9, tnt_trap_0_posY + 5, tnt_trap_0_posZ + 9, Blocks.tnt, 0, 3);
        world.setBlock(tnt_trap_0_posX + 10, tnt_trap_0_posY + 5, tnt_trap_0_posZ + 9, Blocks.redstone_block, 0, 3);
        world.setBlock(tnt_trap_0_posX + 11, tnt_trap_0_posY + 5, tnt_trap_0_posZ + 9, Blocks.air, 0, 3);
        world.setBlock(tnt_trap_0_posX + 0, tnt_trap_0_posY + 5, tnt_trap_0_posZ + 10, Blocks.air, 0, 3);
        world.setBlock(tnt_trap_0_posX + 1, tnt_trap_0_posY + 5, tnt_trap_0_posZ + 10, Blocks.redstone_block, 0, 3);
        world.setBlock(tnt_trap_0_posX + 2, tnt_trap_0_posY + 5, tnt_trap_0_posZ + 10, Blocks.redstone_block, 0, 3);
        world.setBlock(tnt_trap_0_posX + 3, tnt_trap_0_posY + 5, tnt_trap_0_posZ + 10, Blocks.redstone_block, 0, 3);
        world.setBlock(tnt_trap_0_posX + 4, tnt_trap_0_posY + 5, tnt_trap_0_posZ + 10, Blocks.redstone_block, 0, 3);
        world.setBlock(tnt_trap_0_posX + 5, tnt_trap_0_posY + 5, tnt_trap_0_posZ + 10, Blocks.redstone_block, 0, 3);
        world.setBlock(tnt_trap_0_posX + 6, tnt_trap_0_posY + 5, tnt_trap_0_posZ + 10, Blocks.redstone_block, 0, 3);
        world.setBlock(tnt_trap_0_posX + 7, tnt_trap_0_posY + 5, tnt_trap_0_posZ + 10, Blocks.redstone_block, 0, 3);
        world.setBlock(tnt_trap_0_posX + 8, tnt_trap_0_posY + 5, tnt_trap_0_posZ + 10, Blocks.redstone_block, 0, 3);
        world.setBlock(tnt_trap_0_posX + 9, tnt_trap_0_posY + 5, tnt_trap_0_posZ + 10, Blocks.redstone_block, 0, 3);
        world.setBlock(tnt_trap_0_posX + 10, tnt_trap_0_posY + 5, tnt_trap_0_posZ + 10, Blocks.redstone_block, 0, 3);
        world.setBlock(tnt_trap_0_posX + 11, tnt_trap_0_posY + 5, tnt_trap_0_posZ + 10, Blocks.air, 0, 3);
        world.setBlock(tnt_trap_0_posX + 0, tnt_trap_0_posY + 5, tnt_trap_0_posZ + 11, Blocks.air, 0, 3);
        world.setBlock(tnt_trap_0_posX + 1, tnt_trap_0_posY + 5, tnt_trap_0_posZ + 11, Blocks.air, 0, 3);
        world.setBlock(tnt_trap_0_posX + 2, tnt_trap_0_posY + 5, tnt_trap_0_posZ + 11, Blocks.air, 0, 3);
        world.setBlock(tnt_trap_0_posX + 3, tnt_trap_0_posY + 5, tnt_trap_0_posZ + 11, Blocks.air, 0, 3);
        world.setBlock(tnt_trap_0_posX + 4, tnt_trap_0_posY + 5, tnt_trap_0_posZ + 11, Blocks.air, 0, 3);
        world.setBlock(tnt_trap_0_posX + 5, tnt_trap_0_posY + 5, tnt_trap_0_posZ + 11, Blocks.air, 0, 3);
        world.setBlock(tnt_trap_0_posX + 6, tnt_trap_0_posY + 5, tnt_trap_0_posZ + 11, Blocks.air, 0, 3);
        world.setBlock(tnt_trap_0_posX + 7, tnt_trap_0_posY + 5, tnt_trap_0_posZ + 11, Blocks.air, 0, 3);
        world.setBlock(tnt_trap_0_posX + 8, tnt_trap_0_posY + 5, tnt_trap_0_posZ + 11, Blocks.air, 0, 3);
        world.setBlock(tnt_trap_0_posX + 9, tnt_trap_0_posY + 5, tnt_trap_0_posZ + 11, Blocks.air, 0, 3);
        world.setBlock(tnt_trap_0_posX + 10, tnt_trap_0_posY + 5, tnt_trap_0_posZ + 11, Blocks.air, 0, 3);
        world.setBlock(tnt_trap_0_posX + 11, tnt_trap_0_posY + 5, tnt_trap_0_posZ + 11, Blocks.air, 0, 3);
        world.setBlock(tnt_trap_0_posX + 0, tnt_trap_0_posY + 6, tnt_trap_0_posZ + 0, Blocks.air, 0, 3);
        world.setBlock(tnt_trap_0_posX + 1, tnt_trap_0_posY + 6, tnt_trap_0_posZ + 0, Blocks.air, 0, 3);
        world.setBlock(tnt_trap_0_posX + 2, tnt_trap_0_posY + 6, tnt_trap_0_posZ + 0, Blocks.air, 0, 3);
        world.setBlock(tnt_trap_0_posX + 3, tnt_trap_0_posY + 6, tnt_trap_0_posZ + 0, Blocks.air, 0, 3);
        world.setBlock(tnt_trap_0_posX + 4, tnt_trap_0_posY + 6, tnt_trap_0_posZ + 0, Blocks.air, 0, 3);
        world.setBlock(tnt_trap_0_posX + 5, tnt_trap_0_posY + 6, tnt_trap_0_posZ + 0, Blocks.air, 0, 3);
        world.setBlock(tnt_trap_0_posX + 6, tnt_trap_0_posY + 6, tnt_trap_0_posZ + 0, Blocks.air, 0, 3);
        world.setBlock(tnt_trap_0_posX + 7, tnt_trap_0_posY + 6, tnt_trap_0_posZ + 0, Blocks.air, 0, 3);
        world.setBlock(tnt_trap_0_posX + 8, tnt_trap_0_posY + 6, tnt_trap_0_posZ + 0, Blocks.air, 0, 3);
        world.setBlock(tnt_trap_0_posX + 9, tnt_trap_0_posY + 6, tnt_trap_0_posZ + 0, Blocks.air, 0, 3);
        world.setBlock(tnt_trap_0_posX + 10, tnt_trap_0_posY + 6, tnt_trap_0_posZ + 0, Blocks.air, 0, 3);
        world.setBlock(tnt_trap_0_posX + 11, tnt_trap_0_posY + 6, tnt_trap_0_posZ + 0, Blocks.air, 0, 3);
        world.setBlock(tnt_trap_0_posX + 0, tnt_trap_0_posY + 6, tnt_trap_0_posZ + 1, Blocks.air, 0, 3);
        world.setBlock(tnt_trap_0_posX + 1, tnt_trap_0_posY + 6, tnt_trap_0_posZ + 1, Blocks.redstone_block, 0, 3);
        world.setBlock(tnt_trap_0_posX + 2, tnt_trap_0_posY + 6, tnt_trap_0_posZ + 1, Blocks.redstone_block, 0, 3);
        world.setBlock(tnt_trap_0_posX + 3, tnt_trap_0_posY + 6, tnt_trap_0_posZ + 1, Blocks.redstone_block, 0, 3);
        world.setBlock(tnt_trap_0_posX + 4, tnt_trap_0_posY + 6, tnt_trap_0_posZ + 1, Blocks.redstone_block, 0, 3);
        world.setBlock(tnt_trap_0_posX + 5, tnt_trap_0_posY + 6, tnt_trap_0_posZ + 1, Blocks.redstone_block, 0, 3);
        world.setBlock(tnt_trap_0_posX + 6, tnt_trap_0_posY + 6, tnt_trap_0_posZ + 1, Blocks.redstone_block, 0, 3);
        world.setBlock(tnt_trap_0_posX + 7, tnt_trap_0_posY + 6, tnt_trap_0_posZ + 1, Blocks.redstone_block, 0, 3);
        world.setBlock(tnt_trap_0_posX + 8, tnt_trap_0_posY + 6, tnt_trap_0_posZ + 1, Blocks.redstone_block, 0, 3);
        world.setBlock(tnt_trap_0_posX + 9, tnt_trap_0_posY + 6, tnt_trap_0_posZ + 1, Blocks.redstone_block, 0, 3);
        world.setBlock(tnt_trap_0_posX + 10, tnt_trap_0_posY + 6, tnt_trap_0_posZ + 1, Blocks.redstone_block, 0, 3);
        world.setBlock(tnt_trap_0_posX + 11, tnt_trap_0_posY + 6, tnt_trap_0_posZ + 1, Blocks.air, 0, 3);
        world.setBlock(tnt_trap_0_posX + 0, tnt_trap_0_posY + 6, tnt_trap_0_posZ + 2, Blocks.air, 0, 3);
        world.setBlock(tnt_trap_0_posX + 1, tnt_trap_0_posY + 6, tnt_trap_0_posZ + 2, Blocks.redstone_block, 0, 3);
        world.setBlock(tnt_trap_0_posX + 2, tnt_trap_0_posY + 6, tnt_trap_0_posZ + 2, Blocks.tnt, 0, 3);
        world.setBlock(tnt_trap_0_posX + 3, tnt_trap_0_posY + 6, tnt_trap_0_posZ + 2, Blocks.tnt, 0, 3);
        world.setBlock(tnt_trap_0_posX + 4, tnt_trap_0_posY + 6, tnt_trap_0_posZ + 2, Blocks.tnt, 0, 3);
        world.setBlock(tnt_trap_0_posX + 5, tnt_trap_0_posY + 6, tnt_trap_0_posZ + 2, Blocks.tnt, 0, 3);
        world.setBlock(tnt_trap_0_posX + 6, tnt_trap_0_posY + 6, tnt_trap_0_posZ + 2, Blocks.tnt, 0, 3);
        world.setBlock(tnt_trap_0_posX + 7, tnt_trap_0_posY + 6, tnt_trap_0_posZ + 2, Blocks.tnt, 0, 3);
        world.setBlock(tnt_trap_0_posX + 8, tnt_trap_0_posY + 6, tnt_trap_0_posZ + 2, Blocks.tnt, 0, 3);
        world.setBlock(tnt_trap_0_posX + 9, tnt_trap_0_posY + 6, tnt_trap_0_posZ + 2, Blocks.tnt, 0, 3);
        world.setBlock(tnt_trap_0_posX + 10, tnt_trap_0_posY + 6, tnt_trap_0_posZ + 2, Blocks.redstone_block, 0, 3);
        world.setBlock(tnt_trap_0_posX + 11, tnt_trap_0_posY + 6, tnt_trap_0_posZ + 2, Blocks.air, 0, 3);
        world.setBlock(tnt_trap_0_posX + 0, tnt_trap_0_posY + 6, tnt_trap_0_posZ + 3, Blocks.air, 0, 3);
        world.setBlock(tnt_trap_0_posX + 1, tnt_trap_0_posY + 6, tnt_trap_0_posZ + 3, Blocks.redstone_block, 0, 3);
        world.setBlock(tnt_trap_0_posX + 2, tnt_trap_0_posY + 6, tnt_trap_0_posZ + 3, Blocks.tnt, 0, 3);
        world.setBlock(tnt_trap_0_posX + 3, tnt_trap_0_posY + 6, tnt_trap_0_posZ + 3, Blocks.diamond_block, 0, 3);
        world.setBlock(tnt_trap_0_posX + 4, tnt_trap_0_posY + 6, tnt_trap_0_posZ + 3, Blocks.diamond_block, 0, 3);
        world.setBlock(tnt_trap_0_posX + 5, tnt_trap_0_posY + 6, tnt_trap_0_posZ + 3, Blocks.diamond_block, 0, 3);
        world.setBlock(tnt_trap_0_posX + 6, tnt_trap_0_posY + 6, tnt_trap_0_posZ + 3, Blocks.diamond_block, 0, 3);
        world.setBlock(tnt_trap_0_posX + 7, tnt_trap_0_posY + 6, tnt_trap_0_posZ + 3, Blocks.diamond_block, 0, 3);
        world.setBlock(tnt_trap_0_posX + 8, tnt_trap_0_posY + 6, tnt_trap_0_posZ + 3, Blocks.diamond_block, 0, 3);
        world.setBlock(tnt_trap_0_posX + 9, tnt_trap_0_posY + 6, tnt_trap_0_posZ + 3, Blocks.tnt, 0, 3);
        world.setBlock(tnt_trap_0_posX + 10, tnt_trap_0_posY + 6, tnt_trap_0_posZ + 3, Blocks.redstone_block, 0, 3);
        world.setBlock(tnt_trap_0_posX + 11, tnt_trap_0_posY + 6, tnt_trap_0_posZ + 3, Blocks.air, 0, 3);
